<sdf version='1.5'>
  <model name='robotiq_hand'>
    <link name='EE_LINK'>
      <pose>0 0 0 0 -0 0</pose>
      <inertial>
        <pose>0 0 0 0 -0 0</pose>
        <mass>1.3</mass>
        <inertia>
          <ixx>0.0035</ixx>
          <ixy>0</ixy>
          <ixz>0</ixz>
          <iyy>0.0035</iyy>
          <iyz>-1.29247e-26</iyz>
          <izz>0.0035</izz>
        </inertia>
      </inertial>
      <collision name='EE_LINK_collision'>
        <pose>0 0 0 1.5708 -0 0</pose>
        <geometry>
          <box>
            <size>0.1 0.1 0.1</size>
          </box>
        </geometry>
      </collision>
      <visual name='EE_LINK_visual'>
        <pose>0 0 0 1.5708 -0 0</pose>
        <geometry>
          <mesh>
            <scale>1 1 1</scale>
            <uri>model://robotiq_s_model_visualization/meshes/s-model_articulated/visual/palm.STL</uri>
          </mesh>
        </geometry>
      </visual>
      <gravity>1</gravity>
      <velocity_decay/>
      <self_collide>0</self_collide>
    </link>
    <link name='l_finger_1_link_0'>
      <pose>-0.0455 -0.036 0.0214 1.5616 -1.57 -3.1324</pose>
      <inertial>
        <pose>-0.01 0 0 0 -0 0</pose>
        <mass>0.1</mass>
        <inertia>
          <ixx>1.8e-05</ixx>
          <ixy>0</ixy>
          <ixz>0</ixz>
          <iyy>2.5e-05</iyy>
          <iyz>0</iyz>
          <izz>2.5e-05</izz>
        </inertia>
      </inertial>
      <collision name='l_finger_1_link_0_collision'>
        <pose>0 0 0 -3.14159 5.35898e-08 1.5708</pose>
        <geometry>
          <mesh>
            <scale>1 1 1</scale>
            <uri>model://robotiq_s_model_visualization/meshes/s-model_articulated/collision/link_0.STL</uri>
          </mesh>
        </geometry>
        <surface>
          <contact>
            <ode/>
          </contact>
          <friction>
            <ode>
              <mu>1.1</mu>
              <mu2>1.1</mu2>
            </ode>
          </friction>
        </surface>
      </collision>
      <visual name='l_finger_1_link_0_visual'>
        <pose>0.02 0 0 0 -0 0</pose>
        <geometry>
          <mesh>
            <scale>1 1 1</scale>
            <uri>model://robotiq_s_model_visualization/meshes/s-model_articulated/visual/link_0.STL</uri>
          </mesh>
        </geometry>
      </visual>
      <gravity>1</gravity>
      <velocity_decay/>
      <self_collide>0</self_collide>
    </link>
    <joint name='l_palm_finger_1_joint' type='revolute'>
      <child>l_finger_1_link_0</child>
      <parent>EE_LINK</parent>
      <axis>
        <xyz>1 2.13376e-11 0.000796327</xyz>
        <limit>
          <lower>-0.2967</lower>
          <upper>0.2967</upper>
          <effort>60</effort>
          <velocity>-1</velocity>
        </limit>
        <dynamics>
          <damping>1</damping>
          <friction>0</friction>
          <spring_reference>0</spring_reference>
          <spring_stiffness>0</spring_stiffness>
        </dynamics>
        <use_parent_model_frame>1</use_parent_model_frame>
      </axis>
      <physics>
        <ode>
          <implicit_spring_damper>1</implicit_spring_damper>
          <cfm_damping>1</cfm_damping>
          <limit>
            <cfm>0</cfm>
            <erp>0.2</erp>
          </limit>
        </ode>
      </physics>
    </joint>
    <link name='l_finger_1_link_1'>
      <pose>-0.0455 -0.036 0.0214 1.57079 0.5206 3.14159</pose>
      <inertial>
        <pose>0.00053 0.03218 0 0 -0 1.5708</pose>
        <mass>0.047</mass>
        <inertia>
          <ixx>4.99332e-06</ixx>
          <ixy>9.1312e-07</ixy>
          <ixz>-1.2e-09</ixz>
          <iyy>6.43453e-05</iyy>
          <iyz>-7e-11</iyz>
          <izz>6.06192e-05</izz>
        </inertia>
      </inertial>
      <collision name='l_finger_1_link_1_collision'>
        <pose>0 0.05717 0 0 -0 1.5708</pose>
        <geometry>
          <mesh>
            <scale>1 1 1</scale>
            <uri>model://robotiq_s_model_visualization/meshes/s-model_articulated/collision/link_1.STL</uri>
          </mesh>
        </geometry>
        <surface>
          <contact>
            <ode/>
          </contact>
          <friction>
            <ode>
              <mu>1.1</mu>
              <mu2>1.1</mu2>
            </ode>
          </friction>
        </surface>
      </collision>
      <visual name='l_finger_1_link_1_visual'>
        <pose>0 0.05717 0 0 -0 1.5708</pose>
        <geometry>
          <mesh>
            <scale>1 1 1</scale>
            <uri>model://robotiq_s_model_visualization/meshes/s-model_articulated/visual/link_1.STL</uri>
          </mesh>
        </geometry>
      </visual>
      <gravity>1</gravity>
      <velocity_decay/>
      <self_collide>0</self_collide>
    </link>
    <joint name='l_finger_1_joint_1' type='revolute'>
      <child>l_finger_1_link_1</child>
      <parent>l_finger_1_link_0</parent>
      <axis>
        <xyz>-5.85014e-09 1 7.31961e-06</xyz>
        <limit>
          <lower>0</lower>
          <upper>1.2217</upper>
          <effort>60</effort>
          <velocity>-1</velocity>
        </limit>
        <dynamics>
          <damping>1</damping>
          <friction>0</friction>
          <spring_reference>0</spring_reference>
          <spring_stiffness>0</spring_stiffness>
        </dynamics>
        <use_parent_model_frame>1</use_parent_model_frame>
      </axis>
      <physics>
        <ode>
          <implicit_spring_damper>1</implicit_spring_damper>
          <cfm_damping>1</cfm_damping>
          <limit>
            <cfm>0</cfm>
            <erp>0.2</erp>
          </limit>
        </ode>
      </physics>
    </joint>
    <link name='l_finger_1_link_2'>
      <pose>-0.0739265 -0.0360004 0.0709788 1.57079 0.5206 3.14159</pose>
      <inertial>
        <pose>0.00048 0.02167 0.00018 0 -0 1.5708</pose>
        <mass>0.03284</mass>
        <inertia>
          <ixx>3.48008e-06</ixx>
          <ixy>3.194e-07</ixy>
          <ixz>1.3041e-07</ixz>
          <iyy>2.24812e-05</iyy>
          <iyz>2.91e-09</iyz>
          <izz>1.98635e-05</izz>
        </inertia>
      </inertial>
      <collision name='l_finger_1_link_2_collision'>
        <pose>0 0.0381 0.0075 0 -0 1.5708</pose>
        <geometry>
          <mesh>
            <scale>1 1 1</scale>
            <uri>model://robotiq_s_model_visualization/meshes/s-model_articulated/collision/link_2.STL</uri>
          </mesh>
        </geometry>
        <surface>
          <contact>
            <ode/>
          </contact>
          <friction>
            <ode>
              <mu>1.1</mu>
              <mu2>1.1</mu2>
            </ode>
          </friction>
        </surface>
      </collision>
      <visual name='l_finger_1_link_2_visual'>
        <pose>0 0.0381 0.0075 0 -0 1.5708</pose>
        <geometry>
          <mesh>
            <scale>1 1 1</scale>
            <uri>model://robotiq_s_model_visualization/meshes/s-model_articulated/visual/link_2.STL</uri>
          </mesh>
        </geometry>
      </visual>
      <gravity>1</gravity>
      <velocity_decay/>
      <self_collide>0</self_collide>
    </link>
    <joint name='l_finger_1_joint_2' type='revolute'>
      <child>l_finger_1_link_2</child>
      <parent>l_finger_1_link_1</parent>
      <axis>
        <xyz>-5.85014e-09 1 7.31961e-06</xyz>
        <limit>
          <lower>0</lower>
          <upper>1.5708</upper>
          <effort>60</effort>
          <velocity>-1</velocity>
        </limit>
        <dynamics>
          <damping>1</damping>
          <friction>0</friction>
          <spring_reference>0</spring_reference>
          <spring_stiffness>0</spring_stiffness>
        </dynamics>
        <use_parent_model_frame>1</use_parent_model_frame>
      </axis>
      <physics>
        <ode>
          <implicit_spring_damper>1</implicit_spring_damper>
          <cfm_damping>1</cfm_damping>
          <limit>
            <cfm>0</cfm>
            <erp>0.2</erp>
          </limit>
        </ode>
      </physics>
    </joint>
    <link name='l_finger_1_link_3'>
      <pose>-0.0933251 -0.0360006 0.104812 1.5616 -1.57 -3.1324</pose>
      <inertial>
        <pose>0.01626 0.00049 0.0002 0 -0 0</pose>
        <mass>0.03354</mass>
        <inertia>
          <ixx>3.05151e-06</ixx>
          <ixy>8.9792e-07</ixy>
          <ixz>2.49e-09</ixz>
          <iyy>1.42798e-05</iyy>
          <iyz>-1.191e-08</iyz>
          <izz>1.26413e-05</izz>
        </inertia>
      </inertial>
      <collision name='l_finger_1_link_3_collision'>
        <pose>0 0 0 0 -0 0</pose>
        <geometry>
          <mesh>
            <scale>1 1 1</scale>
            <uri>model://robotiq_s_model_visualization/meshes/s-model_articulated/collision/link_3.STL</uri>
          </mesh>
        </geometry>
        <surface>
          <contact>
            <ode>
              <kp>10000</kp>
              <kd>1</kd>
            </ode>
          </contact>
          <friction>
            <ode>
              <mu>1000</mu>
              <mu2>1000</mu2>
            </ode>
          </friction>
        </surface>
      </collision>
      <visual name='l_finger_1_link_3_visual'>
        <pose>0 0 0 0 -0 0</pose>
        <geometry>
          <mesh>
            <scale>1 1 1</scale>
            <uri>model://robotiq_s_model_visualization/meshes/s-model_articulated/visual/link_3.STL</uri>
          </mesh>
        </geometry>
      </visual>
      <gravity>1</gravity>
      <velocity_decay/>
      <self_collide>0</self_collide>
    </link>
    <joint name='l_finger_1_joint_3' type='revolute'>
      <child>l_finger_1_link_3</child>
      <parent>l_finger_1_link_2</parent>
      <axis>
        <xyz>-5.85014e-09 1 7.31961e-06</xyz>
        <limit>
          <lower>-0.6632</lower>
          <upper>1.0471</upper>
          <effort>60</effort>
          <velocity>-1</velocity>
        </limit>
        <dynamics>
          <damping>1</damping>
          <friction>0</friction>
          <spring_reference>0</spring_reference>
          <spring_stiffness>0</spring_stiffness>
        </dynamics>
        <use_parent_model_frame>1</use_parent_model_frame>
      </axis>
      <physics>
        <ode>
          <implicit_spring_damper>1</implicit_spring_damper>
          <cfm_damping>1</cfm_damping>
          <limit>
            <cfm>0</cfm>
            <erp>0.2</erp>
          </limit>
        </ode>
      </physics>
    </joint>
    <link name='l_finger_1_link_paradistal_hinge'>
      <pose>-0.0933251 -0.0460006 0.104812 1.57079 0.5206 3.14159</pose>
      <inertial>
        <pose>0.00548 0 0 0 -0 0</pose>
        <mass>0.00158</mass>
        <inertia>
          <ixx>1.907e-08</ixx>
          <ixy>0</ixy>
          <ixz>0</ixz>
          <iyy>1.097e-07</iyy>
          <iyz>0</iyz>
          <izz>1.261e-07</izz>
        </inertia>
      </inertial>
      <collision name='l_finger_1_link_paradistal_hinge_collision'>
        <pose>0 0 0 0 -0 0</pose>
        <geometry>
          <box>
            <size>0.02 0.02 0.002</size>
          </box>
        </geometry>
        <surface>
          <contact>
            <ode/>
          </contact>
          <friction>
            <ode>
              <mu>1.1</mu>
              <mu2>1.1</mu2>
            </ode>
          </friction>
        </surface>
      </collision>
      <visual name='l_finger_1_link_paradistal_hinge_visual'>
        <pose>0 0 0 0 -0 0</pose>
        <geometry>
          <box>
            <size>0.02 0.02 0.002</size>
          </box>
        </geometry>
      </visual>
      <gravity>1</gravity>
      <velocity_decay/>
      <self_collide>0</self_collide>
    </link>
    <joint name='l_finger_1_joint_paradistal_hinge' type='revolute'>
      <child>l_finger_1_link_paradistal_hinge</child>
      <parent>l_finger_1_link_2</parent>
      <axis>
        <xyz>-5.85014e-09 1 7.31961e-06</xyz>
        <limit>
          <lower>-3.1416</lower>
          <upper>3.1416</upper>
          <effort>100</effort>
          <velocity>100</velocity>
        </limit>
        <dynamics>
          <spring_reference>0</spring_reference>
          <spring_stiffness>0</spring_stiffness>
        </dynamics>
        <use_parent_model_frame>1</use_parent_model_frame>
      </axis>
      <physics>
        <ode>
          <implicit_spring_damper>1</implicit_spring_damper>
          <cfm_damping>1</cfm_damping>
          <limit>
            <cfm>0</cfm>
            <erp>0.2</erp>
          </limit>
        </ode>
      </physics>
    </joint>
    <link name='l_finger_1_link_median_actuating_hinge'>
      <pose>-0.0739265 -0.0260004 0.0709789 1.57078 0.8906 3.14158</pose>
      <inertial>
        <pose>0.0092 0.00514 0 0 -0 0</pose>
        <mass>0.00359</mass>
        <inertia>
          <ixx>2.4735e-07</ixx>
          <ixy>2.3619e-07</ixy>
          <ixz>0</ixz>
          <iyy>4.7681e-07</iyy>
          <iyz>0</iyz>
          <izz>7.1813e-07</izz>
        </inertia>
      </inertial>
      <collision name='l_finger_1_link_median_actuating_hinge_collision'>
        <pose>0 0 0 0 -0 0</pose>
        <geometry>
          <box>
            <size>0.02 0.02 0.002</size>
          </box>
        </geometry>
        <surface>
          <contact>
            <ode/>
          </contact>
          <friction>
            <ode>
              <mu>1.1</mu>
              <mu2>1.1</mu2>
            </ode>
          </friction>
        </surface>
      </collision>
      <visual name='l_finger_1_link_median_actuating_hinge_visual'>
        <pose>0 0 0 0 -0 0</pose>
        <geometry>
          <box>
            <size>0.02 0.02 0.002</size>
          </box>
        </geometry>
      </visual>
      <gravity>1</gravity>
      <velocity_decay/>
      <self_collide>0</self_collide>
    </link>
    <joint name='l_finger_1_joint_median_actuating_hinge' type='revolute'>
      <child>l_finger_1_link_median_actuating_hinge</child>
      <parent>l_finger_1_link_1</parent>
      <axis>
        <xyz>-5.85014e-09 1 7.31961e-06</xyz>
        <limit>
          <lower>-3.1416</lower>
          <upper>3.1416</upper>
          <effort>100</effort>
          <velocity>100</velocity>
        </limit>
        <dynamics>
          <spring_reference>0</spring_reference>
          <spring_stiffness>0</spring_stiffness>
        </dynamics>
        <use_parent_model_frame>1</use_parent_model_frame>
      </axis>
      <physics>
        <ode>
          <implicit_spring_damper>1</implicit_spring_damper>
          <cfm_damping>1</cfm_damping>
          <limit>
            <cfm>0</cfm>
            <erp>0.2</erp>
          </limit>
        </ode>
      </physics>
    </joint>
    <link name='l_finger_1_link_median_bar'>
      <pose>-0.095933 -0.0260003 0.0678802 1.57074 -1.4309 -3.14154</pose>
      <inertial>
        <pose>0.01905 -0.00107 0 0 -0 0</pose>
        <mass>0.00538</mass>
        <inertia>
          <ixx>6.639e-08</ixx>
          <ixy>-1.0996e-07</ixy>
          <ixz>9.4e-10</ixz>
          <iyy>3.05318e-06</iyy>
          <iyz>0</iyz>
          <izz>3.04657e-06</izz>
        </inertia>
      </inertial>
      <collision name='l_finger_1_link_median_bar_collision'>
        <pose>0.01905 0 0 0 -0 0</pose>
        <geometry>
          <box>
            <size>0.0381 0.0075 0.002</size>
          </box>
        </geometry>
        <surface>
          <contact>
            <ode/>
          </contact>
          <friction>
            <ode>
              <mu>1.1</mu>
              <mu2>1.1</mu2>
            </ode>
          </friction>
        </surface>
      </collision>
      <visual name='l_finger_1_link_median_bar_visual'>
        <pose>0.01905 0 0 0 -0 0</pose>
        <geometry>
          <box>
            <size>0.0381 0.0075 0.002</size>
          </box>
        </geometry>
      </visual>
      <gravity>1</gravity>
      <velocity_decay/>
      <self_collide>0</self_collide>
    </link>
    <joint name='l_finger_1_joint_median_actuating_hinge_median_bar' type='revolute'>
      <child>l_finger_1_link_median_bar</child>
      <parent>l_finger_1_link_median_actuating_hinge</parent>
      <axis>
        <xyz>-5.85014e-09 1 7.31961e-06</xyz>
        <limit>
          <lower>-3.1416</lower>
          <upper>3.1416</upper>
          <effort>100</effort>
          <velocity>100</velocity>
        </limit>
        <dynamics>
          <spring_reference>0</spring_reference>
          <spring_stiffness>0</spring_stiffness>
        </dynamics>
        <use_parent_model_frame>1</use_parent_model_frame>
      </axis>
      <physics>
        <ode>
          <implicit_spring_damper>1</implicit_spring_damper>
          <cfm_damping>1</cfm_damping>
          <limit>
            <cfm>0</cfm>
            <erp>0.2</erp>
          </limit>
        </ode>
      </physics>
    </joint>
    <link name='l_finger_1_link_paramedian_hinge'>
      <pose>-0.0739265 -0.0460004 0.0709787 1.57079 0.5206 3.14159</pose>
      <inertial>
        <pose>-0.01025 0.00046 0 0 -0 0</pose>
        <mass>0.00276</mass>
        <inertia>
          <ixx>4.213e-08</ixx>
          <ixy>-1.491e-08</ixy>
          <ixz>0</ixz>
          <iyy>5.0258e-07</iyy>
          <iyz>0</iyz>
          <izz>5.4007e-07</izz>
        </inertia>
      </inertial>
      <collision name='l_finger_1_link_paramedian_hinge_collision'>
        <pose>0 0 0 0 -0 0</pose>
        <geometry>
          <box>
            <size>0.02 0.02 0.002</size>
          </box>
        </geometry>
        <surface>
          <contact>
            <ode/>
          </contact>
          <friction>
            <ode>
              <mu>1.1</mu>
              <mu2>1.1</mu2>
            </ode>
          </friction>
        </surface>
      </collision>
      <visual name='l_finger_1_link_paramedian_hinge_visual'>
        <pose>0 0 0 0 -0 0</pose>
        <geometry>
          <box>
            <size>0.02 0.02 0.002</size>
          </box>
        </geometry>
      </visual>
      <gravity>1</gravity>
      <velocity_decay/>
      <self_collide>0</self_collide>
    </link>
    <joint name='l_finger_1_joint_paramedian_hinge' type='revolute'>
      <child>l_finger_1_link_paramedian_hinge</child>
      <parent>l_finger_1_link_1</parent>
      <axis>
        <xyz>-5.85014e-09 1 7.31961e-06</xyz>
        <limit>
          <lower>-3.1416</lower>
          <upper>3.1416</upper>
          <effort>100</effort>
          <velocity>100</velocity>
        </limit>
        <dynamics>
          <spring_reference>0</spring_reference>
          <spring_stiffness>0</spring_stiffness>
        </dynamics>
        <use_parent_model_frame>1</use_parent_model_frame>
      </axis>
      <physics>
        <ode>
          <implicit_spring_damper>1</implicit_spring_damper>
          <cfm_damping>1</cfm_damping>
          <limit>
            <cfm>0</cfm>
            <erp>0.2</erp>
          </limit>
        </ode>
      </physics>
    </joint>
    <link name='l_finger_1_link_median_bar_underactuated'>
      <pose>-0.0862074 -0.0460003 0.0677298 1.57078 -1.0502 -3.14158</pose>
      <inertial>
        <pose>0.01905 -0.00107 0 0 -0 0</pose>
        <mass>0.00538</mass>
        <inertia>
          <ixx>6.639e-08</ixx>
          <ixy>-1.0996e-07</ixy>
          <ixz>-9.4e-10</ixz>
          <iyy>3.05318e-06</iyy>
          <iyz>0</iyz>
          <izz>3.04657e-06</izz>
        </inertia>
      </inertial>
      <collision name='l_finger_1_link_median_bar_underactuated_collision'>
        <pose>0.01905 0 0 0 -0 0</pose>
        <geometry>
          <box>
            <size>0.0381 0.0075 0.002</size>
          </box>
        </geometry>
        <surface>
          <contact>
            <ode/>
          </contact>
          <friction>
            <ode>
              <mu>1.1</mu>
              <mu2>1.1</mu2>
            </ode>
          </friction>
        </surface>
      </collision>
      <visual name='l_finger_1_link_median_bar_underactuated_visual'>
        <pose>0.01905 0 0 0 -0 0</pose>
        <geometry>
          <box>
            <size>0.0381 0.0075 0.002</size>
          </box>
        </geometry>
      </visual>
      <gravity>1</gravity>
      <velocity_decay/>
      <self_collide>0</self_collide>
    </link>
    <joint name='l_finger_1_joint_paramedian_hinge_median_bar_underactuated' type='revolute'>
      <child>l_finger_1_link_median_bar_underactuated</child>
      <parent>l_finger_1_link_paramedian_hinge</parent>
      <axis>
        <xyz>-5.85014e-09 1 7.31961e-06</xyz>
        <limit>
          <lower>-3.1416</lower>
          <upper>3.1416</upper>
          <effort>100</effort>
          <velocity>100</velocity>
        </limit>
        <dynamics>
          <spring_reference>0</spring_reference>
          <spring_stiffness>0</spring_stiffness>
        </dynamics>
        <use_parent_model_frame>1</use_parent_model_frame>
      </axis>
      <physics>
        <ode>
          <implicit_spring_damper>1</implicit_spring_damper>
          <cfm_damping>1</cfm_damping>
          <limit>
            <cfm>0</cfm>
            <erp>0.2</erp>
          </limit>
        </ode>
      </physics>
    </joint>
    <link name='l_finger_1_link_paraproximal_actuating_hinge'>
      <pose>-0.0455 -0.046 0.0213999 1.57079 0.5206 3.14159</pose>
      <inertial>
        <pose>0.0064 0 0 0 -0 0</pose>
        <mass>0.00362</mass>
        <inertia>
          <ixx>1.2043e-07</ixx>
          <ixy>0</ixy>
          <ixz>0</ixz>
          <iyy>5.3588e-07</iyy>
          <iyz>0</iyz>
          <izz>6.5322e-07</izz>
        </inertia>
      </inertial>
      <collision name='l_finger_1_link_paraproximal_actuating_hinge_collision'>
        <pose>0.01143 0 0 0 -0 0</pose>
        <geometry>
          <box>
            <size>0.02286 0.0075 0.002</size>
          </box>
        </geometry>
        <surface>
          <contact>
            <ode/>
          </contact>
          <friction>
            <ode>
              <mu>1.1</mu>
              <mu2>1.1</mu2>
            </ode>
          </friction>
        </surface>
      </collision>
      <visual name='l_finger_1_link_paraproximal_actuating_hinge_visual'>
        <pose>0.01143 0 0 0 -0 0</pose>
        <geometry>
          <box>
            <size>0.02286 0.0075 0.002</size>
          </box>
        </geometry>
      </visual>
      <gravity>1</gravity>
      <velocity_decay/>
      <self_collide>0</self_collide>
    </link>
    <joint name='l_finger_1_joint_paraproximal_actuating_hinge' type='revolute'>
      <child>l_finger_1_link_paraproximal_actuating_hinge</child>
      <parent>l_finger_1_link_0</parent>
      <axis>
        <xyz>-5.85014e-09 1 7.31961e-06</xyz>
        <limit>
          <lower>-3.1416</lower>
          <upper>3.1416</upper>
          <effort>100</effort>
          <velocity>100</velocity>
        </limit>
        <dynamics>
          <spring_reference>0</spring_reference>
          <spring_stiffness>0</spring_stiffness>
        </dynamics>
        <use_parent_model_frame>1</use_parent_model_frame>
      </axis>
      <physics>
        <ode>
          <implicit_spring_damper>1</implicit_spring_damper>
          <cfm_damping>1</cfm_damping>
          <limit>
            <cfm>0</cfm>
            <erp>0.2</erp>
          </limit>
        </ode>
      </physics>
    </joint>
    <link name='l_finger_1_link_paraproximal_bar'>
      <pose>-0.0653315 -0.0459999 0.0100293 1.57078 -1.0494 -3.14158</pose>
      <inertial>
        <pose>0.02858 -0.00129 0 0 -0 0</pose>
        <mass>0.00732</mass>
        <inertia>
          <ixx>9.065e-08</ixx>
          <ixy>-2.7047e-07</ixy>
          <ixz>1.42e-09</ixz>
          <iyy>8.78034e-06</iyy>
          <iyz>0</iyz>
          <izz>8.77558e-06</izz>
        </inertia>
      </inertial>
      <collision name='l_finger_1_link_paraproximal_bar_collision'>
        <pose>0.02885 0 0 0 -0 0</pose>
        <geometry>
          <box>
            <size>0.0577 0.0075 0.002</size>
          </box>
        </geometry>
        <surface>
          <contact>
            <ode/>
          </contact>
          <friction>
            <ode>
              <mu>1.1</mu>
              <mu2>1.1</mu2>
            </ode>
          </friction>
        </surface>
      </collision>
      <visual name='l_finger_1_link_paraproximal_bar_visual'>
        <pose>0.02885 0 0 0 -0 0</pose>
        <geometry>
          <box>
            <size>0.0577 0.0075 0.002</size>
          </box>
        </geometry>
      </visual>
      <gravity>1</gravity>
      <velocity_decay/>
      <self_collide>0</self_collide>
    </link>
    <joint name='l_finger_1_joint_paraproximal_bar' type='revolute'>
      <child>l_finger_1_link_paraproximal_bar</child>
      <parent>l_finger_1_link_paraproximal_actuating_hinge</parent>
      <axis>
        <xyz>-5.85014e-09 1 7.31961e-06</xyz>
        <limit>
          <lower>-3.1416</lower>
          <upper>3.1416</upper>
          <effort>100</effort>
          <velocity>100</velocity>
        </limit>
        <dynamics>
          <spring_reference>0</spring_reference>
          <spring_stiffness>0</spring_stiffness>
        </dynamics>
        <use_parent_model_frame>1</use_parent_model_frame>
      </axis>
      <physics>
        <ode>
          <implicit_spring_damper>1</implicit_spring_damper>
          <cfm_damping>1</cfm_damping>
          <limit>
            <cfm>0</cfm>
            <erp>0.2</erp>
          </limit>
        </ode>
      </physics>
    </joint>
    <link name='l_finger_1_link_proximal_actuating_hinge'>
      <pose>-0.0455 -0.026 0.0214001 1.57079 0.5206 3.14159</pose>
      <inertial>
        <pose>0.0012 -0.00162 -0.00161 0 -0 0</pose>
        <mass>0.02647</mass>
        <inertia>
          <ixx>1.56447e-06</ixx>
          <ixy>2.36226e-07</ixy>
          <ixz>-1.4862e-07</ixz>
          <iyy>2.21068e-06</iyy>
          <iyz>-1.4369e-07</iyz>
          <izz>3.23175e-06</izz>
        </inertia>
      </inertial>
      <collision name='l_finger_1_link_proximal_actuating_hinge_collision'>
        <pose>0.01429 0 0 0 -0 0</pose>
        <geometry>
          <box>
            <size>0.02858 0.0075 0.002</size>
          </box>
        </geometry>
        <surface>
          <contact>
            <ode/>
          </contact>
          <friction>
            <ode>
              <mu>1.1</mu>
              <mu2>1.1</mu2>
            </ode>
          </friction>
        </surface>
      </collision>
      <visual name='l_finger_1_link_proximal_actuating_hinge_visual'>
        <pose>0.01429 0 0 0 -0 0</pose>
        <geometry>
          <box>
            <size>0.02858 0.0075 0.002</size>
          </box>
        </geometry>
      </visual>
      <gravity>1</gravity>
      <velocity_decay/>
      <self_collide>0</self_collide>
    </link>
    <joint name='l_finger_1_joint_proximal_actuating_hinge' type='revolute'>
      <child>l_finger_1_link_proximal_actuating_hinge</child>
      <parent>l_finger_1_link_0</parent>
      <axis>
        <xyz>-5.85014e-09 1 7.31961e-06</xyz>
        <limit>
          <lower>-3.1416</lower>
          <upper>3.1416</upper>
          <effort>100</effort>
          <velocity>100</velocity>
        </limit>
        <dynamics>
          <spring_reference>0</spring_reference>
          <spring_stiffness>0</spring_stiffness>
        </dynamics>
        <use_parent_model_frame>1</use_parent_model_frame>
      </axis>
      <physics>
        <ode>
          <implicit_spring_damper>1</implicit_spring_damper>
          <cfm_damping>1</cfm_damping>
          <limit>
            <cfm>0</cfm>
            <erp>0.2</erp>
          </limit>
        </ode>
      </physics>
    </joint>
    <link name='l_finger_1_link_proximal_actuating_bar'>
      <pose>-0.0702937 -0.0259999 0.00718436 1.57076 -1.341 -3.14156</pose>
      <inertial>
        <pose>0.02699 -0.00122 0 0 -0 0</pose>
        <mass>0.00659</mass>
        <inertia>
          <ixx>8.348e-08</ixx>
          <ixy>-2.179e-07</ixy>
          <ixz>1.34e-09</ixz>
          <iyy>7.19076e-06</iyy>
          <iyz>0</iyz>
          <izz>7.18272e-06</izz>
        </inertia>
      </inertial>
      <collision name='l_finger_1_link_proximal_actuating_bar_collision'>
        <pose>0.026789 0 0 0 -0 0</pose>
        <geometry>
          <box>
            <size>0.05398 0.0075 0.002</size>
          </box>
        </geometry>
        <surface>
          <contact>
            <ode/>
          </contact>
          <friction>
            <ode>
              <mu>1.1</mu>
              <mu2>1.1</mu2>
            </ode>
          </friction>
        </surface>
      </collision>
      <visual name='l_finger_1_link_proximal_actuating_bar_visual'>
        <pose>0.026789 0 0 0 -0 0</pose>
        <geometry>
          <box>
            <size>0.05398 0.0075 0.002</size>
          </box>
        </geometry>
      </visual>
      <gravity>1</gravity>
      <velocity_decay/>
      <self_collide>0</self_collide>
    </link>
    <joint name='l_finger_1_joint_proximal_actuating_bar' type='revolute'>
      <child>l_finger_1_link_proximal_actuating_bar</child>
      <parent>l_finger_1_link_proximal_actuating_hinge</parent>
      <axis>
        <xyz>-5.85014e-09 1 7.31961e-06</xyz>
        <limit>
          <lower>-3.1416</lower>
          <upper>3.1416</upper>
          <effort>100</effort>
          <velocity>100</velocity>
        </limit>
        <dynamics>
          <spring_reference>0</spring_reference>
          <spring_stiffness>0</spring_stiffness>
        </dynamics>
        <use_parent_model_frame>1</use_parent_model_frame>
      </axis>
      <physics>
        <ode>
          <implicit_spring_damper>1</implicit_spring_damper>
          <cfm_damping>1</cfm_damping>
          <limit>
            <cfm>0</cfm>
            <erp>0.2</erp>
          </limit>
        </ode>
      </physics>
    </joint>
    <link name='l_finger_2_link_0'>
      <pose>-0.0455 0.036 0.0214 1.5616 -1.57 -3.1324</pose>
      <inertial>
        <pose>-0.01 0 0 0 -0 0</pose>
        <mass>0.1</mass>
        <inertia>
          <ixx>1.8e-05</ixx>
          <ixy>0</ixy>
          <ixz>0</ixz>
          <iyy>2.5e-05</iyy>
          <iyz>0</iyz>
          <izz>2.5e-05</izz>
        </inertia>
      </inertial>
      <collision name='l_finger_2_link_0_collision'>
        <pose>0 0 0 -3.14159 5.35898e-08 1.5708</pose>
        <geometry>
          <mesh>
            <scale>1 1 1</scale>
            <uri>model://robotiq_s_model_visualization/meshes/s-model_articulated/collision/link_0.STL</uri>
          </mesh>
        </geometry>
        <surface>
          <contact>
            <ode/>
          </contact>
          <friction>
            <ode>
              <mu>1.1</mu>
              <mu2>1.1</mu2>
            </ode>
          </friction>
        </surface>
      </collision>
      <visual name='l_finger_2_link_0_visual'>
        <pose>0.02 0 0 0 -0 0</pose>
        <geometry>
          <mesh>
            <scale>1 1 1</scale>
            <uri>model://robotiq_s_model_visualization/meshes/s-model_articulated/visual/link_0.STL</uri>
          </mesh>
        </geometry>
      </visual>
      <gravity>1</gravity>
      <velocity_decay/>
      <self_collide>0</self_collide>
    </link>
    <joint name='l_palm_finger_2_joint' type='revolute'>
      <child>l_finger_2_link_0</child>
      <parent>EE_LINK</parent>
      <axis>
        <xyz>1 2.13376e-11 0.000796327</xyz>
        <limit>
          <lower>-0.2967</lower>
          <upper>0.2967</upper>
          <effort>60</effort>
          <velocity>-1</velocity>
        </limit>
        <dynamics>
          <damping>1</damping>
          <friction>0</friction>
          <spring_reference>0</spring_reference>
          <spring_stiffness>0</spring_stiffness>
        </dynamics>
        <use_parent_model_frame>1</use_parent_model_frame>
      </axis>
      <physics>
        <ode>
          <implicit_spring_damper>1</implicit_spring_damper>
          <cfm_damping>1</cfm_damping>
          <limit>
            <cfm>0</cfm>
            <erp>0.2</erp>
          </limit>
        </ode>
      </physics>
    </joint>
    <link name='l_finger_2_link_1'>
      <pose>-0.0455 0.036 0.0214 1.57079 0.5206 3.14159</pose>
      <inertial>
        <pose>0.00053 0.03218 0 0 -0 1.5708</pose>
        <mass>0.047</mass>
        <inertia>
          <ixx>4.99332e-06</ixx>
          <ixy>9.1312e-07</ixy>
          <ixz>-1.2e-09</ixz>
          <iyy>6.43453e-05</iyy>
          <iyz>-7e-11</iyz>
          <izz>6.06192e-05</izz>
        </inertia>
      </inertial>
      <collision name='l_finger_2_link_1_collision'>
        <pose>0 0.05717 0 0 -0 1.5708</pose>
        <geometry>
          <mesh>
            <scale>1 1 1</scale>
            <uri>model://robotiq_s_model_visualization/meshes/s-model_articulated/collision/link_1.STL</uri>
          </mesh>
        </geometry>
        <surface>
          <contact>
            <ode/>
          </contact>
          <friction>
            <ode>
              <mu>1.1</mu>
              <mu2>1.1</mu2>
            </ode>
          </friction>
        </surface>
      </collision>
      <visual name='l_finger_2_link_1_visual'>
        <pose>0 0.05717 0 0 -0 1.5708</pose>
        <geometry>
          <mesh>
            <scale>1 1 1</scale>
            <uri>model://robotiq_s_model_visualization/meshes/s-model_articulated/visual/link_1.STL</uri>
          </mesh>
        </geometry>
      </visual>
      <gravity>1</gravity>
      <velocity_decay/>
      <self_collide>0</self_collide>
    </link>
    <joint name='l_finger_2_joint_1' type='revolute'>
      <child>l_finger_2_link_1</child>
      <parent>l_finger_2_link_0</parent>
      <axis>
        <xyz>-5.85014e-09 1 7.31961e-06</xyz>
        <limit>
          <lower>0</lower>
          <upper>1.2217</upper>
          <effort>60</effort>
          <velocity>-1</velocity>
        </limit>
        <dynamics>
          <damping>1</damping>
          <friction>0</friction>
          <spring_reference>0</spring_reference>
          <spring_stiffness>0</spring_stiffness>
        </dynamics>
        <use_parent_model_frame>1</use_parent_model_frame>
      </axis>
      <physics>
        <ode>
          <implicit_spring_damper>1</implicit_spring_damper>
          <cfm_damping>1</cfm_damping>
          <limit>
            <cfm>0</cfm>
            <erp>0.2</erp>
          </limit>
        </ode>
      </physics>
    </joint>
    <link name='l_finger_2_link_2'>
      <pose>-0.0739265 0.0359996 0.0709788 1.57079 0.5206 3.14159</pose>
      <inertial>
        <pose>0.00048 0.02167 0.00018 0 -0 1.5708</pose>
        <mass>0.03284</mass>
        <inertia>
          <ixx>3.48008e-06</ixx>
          <ixy>3.194e-07</ixy>
          <ixz>1.3041e-07</ixz>
          <iyy>2.24812e-05</iyy>
          <iyz>2.91e-09</iyz>
          <izz>1.98635e-05</izz>
        </inertia>
      </inertial>
      <collision name='l_finger_2_link_2_collision'>
        <pose>0 0.0381 0.0075 0 -0 1.5708</pose>
        <geometry>
          <mesh>
            <scale>1 1 1</scale>
            <uri>model://robotiq_s_model_visualization/meshes/s-model_articulated/collision/link_2.STL</uri>
          </mesh>
        </geometry>
        <surface>
          <contact>
            <ode/>
          </contact>
          <friction>
            <ode>
              <mu>1.1</mu>
              <mu2>1.1</mu2>
            </ode>
          </friction>
        </surface>
      </collision>
      <visual name='l_finger_2_link_2_visual'>
        <pose>0 0.0381 0.0075 0 -0 1.5708</pose>
        <geometry>
          <mesh>
            <scale>1 1 1</scale>
            <uri>model://robotiq_s_model_visualization/meshes/s-model_articulated/visual/link_2.STL</uri>
          </mesh>
        </geometry>
      </visual>
      <gravity>1</gravity>
      <velocity_decay/>
      <self_collide>0</self_collide>
    </link>
    <joint name='l_finger_2_joint_2' type='revolute'>
      <child>l_finger_2_link_2</child>
      <parent>l_finger_2_link_1</parent>
      <axis>
        <xyz>-5.85014e-09 1 7.31961e-06</xyz>
        <limit>
          <lower>0</lower>
          <upper>1.5708</upper>
          <effort>60</effort>
          <velocity>-1</velocity>
        </limit>
        <dynamics>
          <damping>1</damping>
          <friction>0</friction>
          <spring_reference>0</spring_reference>
          <spring_stiffness>0</spring_stiffness>
        </dynamics>
        <use_parent_model_frame>1</use_parent_model_frame>
      </axis>
      <physics>
        <ode>
          <implicit_spring_damper>1</implicit_spring_damper>
          <cfm_damping>1</cfm_damping>
          <limit>
            <cfm>0</cfm>
            <erp>0.2</erp>
          </limit>
        </ode>
      </physics>
    </joint>
    <link name='l_finger_2_link_3'>
      <pose>-0.0933251 0.0359994 0.104812 1.5616 -1.57 -3.1324</pose>
      <inertial>
        <pose>0.01626 0.00049 0.0002 0 -0 0</pose>
        <mass>0.03354</mass>
        <inertia>
          <ixx>3.05151e-06</ixx>
          <ixy>8.9792e-07</ixy>
          <ixz>2.49e-09</ixz>
          <iyy>1.42798e-05</iyy>
          <iyz>-1.191e-08</iyz>
          <izz>1.26413e-05</izz>
        </inertia>
      </inertial>
      <collision name='l_finger_2_link_3_collision'>
        <pose>0 0 0 0 -0 0</pose>
        <geometry>
          <mesh>
            <scale>1 1 1</scale>
            <uri>model://robotiq_s_model_visualization/meshes/s-model_articulated/collision/link_3.STL</uri>
          </mesh>
        </geometry>
        <surface>
          <contact>
            <ode>
              <kp>10000</kp>
              <kd>1</kd>
            </ode>
          </contact>
          <friction>
            <ode>
              <mu>1000</mu>
              <mu2>1000</mu2>
            </ode>
          </friction>
        </surface>
      </collision>
      <visual name='l_finger_2_link_3_visual'>
        <pose>0 0 0 0 -0 0</pose>
        <geometry>
          <mesh>
            <scale>1 1 1</scale>
            <uri>model://robotiq_s_model_visualization/meshes/s-model_articulated/visual/link_3.STL</uri>
          </mesh>
        </geometry>
      </visual>
      <gravity>1</gravity>
      <velocity_decay/>
      <self_collide>0</self_collide>
    </link>
    <joint name='l_finger_2_joint_3' type='revolute'>
      <child>l_finger_2_link_3</child>
      <parent>l_finger_2_link_2</parent>
      <axis>
        <xyz>-5.85014e-09 1 7.31961e-06</xyz>
        <limit>
          <lower>-0.6632</lower>
          <upper>1.0471</upper>
          <effort>60</effort>
          <velocity>-1</velocity>
        </limit>
        <dynamics>
          <damping>1</damping>
          <friction>0</friction>
          <spring_reference>0</spring_reference>
          <spring_stiffness>0</spring_stiffness>
        </dynamics>
        <use_parent_model_frame>1</use_parent_model_frame>
      </axis>
      <physics>
        <ode>
          <implicit_spring_damper>1</implicit_spring_damper>
          <cfm_damping>1</cfm_damping>
          <limit>
            <cfm>0</cfm>
            <erp>0.2</erp>
          </limit>
        </ode>
      </physics>
    </joint>
    <link name='l_finger_2_link_paradistal_hinge'>
      <pose>-0.0933251 0.0259994 0.104812 1.57079 0.5206 3.14159</pose>
      <inertial>
        <pose>0.00548 0 0 0 -0 0</pose>
        <mass>0.00158</mass>
        <inertia>
          <ixx>1.907e-08</ixx>
          <ixy>0</ixy>
          <ixz>0</ixz>
          <iyy>1.097e-07</iyy>
          <iyz>0</iyz>
          <izz>1.261e-07</izz>
        </inertia>
      </inertial>
      <collision name='l_finger_2_link_paradistal_hinge_collision'>
        <pose>0 0 0 0 -0 0</pose>
        <geometry>
          <box>
            <size>0.02 0.02 0.002</size>
          </box>
        </geometry>
        <surface>
          <contact>
            <ode/>
          </contact>
          <friction>
            <ode>
              <mu>1.1</mu>
              <mu2>1.1</mu2>
            </ode>
          </friction>
        </surface>
      </collision>
      <visual name='l_finger_2_link_paradistal_hinge_visual'>
        <pose>0 0 0 0 -0 0</pose>
        <geometry>
          <box>
            <size>0.02 0.02 0.002</size>
          </box>
        </geometry>
      </visual>
      <gravity>1</gravity>
      <velocity_decay/>
      <self_collide>0</self_collide>
    </link>
    <joint name='l_finger_2_joint_paradistal_hinge' type='revolute'>
      <child>l_finger_2_link_paradistal_hinge</child>
      <parent>l_finger_2_link_2</parent>
      <axis>
        <xyz>-5.85014e-09 1 7.31961e-06</xyz>
        <limit>
          <lower>-3.1416</lower>
          <upper>3.1416</upper>
          <effort>100</effort>
          <velocity>100</velocity>
        </limit>
        <dynamics>
          <spring_reference>0</spring_reference>
          <spring_stiffness>0</spring_stiffness>
        </dynamics>
        <use_parent_model_frame>1</use_parent_model_frame>
      </axis>
      <physics>
        <ode>
          <implicit_spring_damper>1</implicit_spring_damper>
          <cfm_damping>1</cfm_damping>
          <limit>
            <cfm>0</cfm>
            <erp>0.2</erp>
          </limit>
        </ode>
      </physics>
    </joint>
    <link name='l_finger_2_link_median_actuating_hinge'>
      <pose>-0.0739265 0.0459996 0.0709789 1.57078 0.8906 3.14158</pose>
      <inertial>
        <pose>0.0092 0.00514 0 0 -0 0</pose>
        <mass>0.00359</mass>
        <inertia>
          <ixx>2.4735e-07</ixx>
          <ixy>2.3619e-07</ixy>
          <ixz>0</ixz>
          <iyy>4.7681e-07</iyy>
          <iyz>0</iyz>
          <izz>7.1813e-07</izz>
        </inertia>
      </inertial>
      <collision name='l_finger_2_link_median_actuating_hinge_collision'>
        <pose>0 0 0 0 -0 0</pose>
        <geometry>
          <box>
            <size>0.02 0.02 0.002</size>
          </box>
        </geometry>
        <surface>
          <contact>
            <ode/>
          </contact>
          <friction>
            <ode>
              <mu>1.1</mu>
              <mu2>1.1</mu2>
            </ode>
          </friction>
        </surface>
      </collision>
      <visual name='l_finger_2_link_median_actuating_hinge_visual'>
        <pose>0 0 0 0 -0 0</pose>
        <geometry>
          <box>
            <size>0.02 0.02 0.002</size>
          </box>
        </geometry>
      </visual>
      <gravity>1</gravity>
      <velocity_decay/>
      <self_collide>0</self_collide>
    </link>
    <joint name='l_finger_2_joint_median_actuating_hinge' type='revolute'>
      <child>l_finger_2_link_median_actuating_hinge</child>
      <parent>l_finger_2_link_1</parent>
      <axis>
        <xyz>-5.85014e-09 1 7.31961e-06</xyz>
        <limit>
          <lower>-3.1416</lower>
          <upper>3.1416</upper>
          <effort>100</effort>
          <velocity>100</velocity>
        </limit>
        <dynamics>
          <spring_reference>0</spring_reference>
          <spring_stiffness>0</spring_stiffness>
        </dynamics>
        <use_parent_model_frame>1</use_parent_model_frame>
      </axis>
      <physics>
        <ode>
          <implicit_spring_damper>1</implicit_spring_damper>
          <cfm_damping>1</cfm_damping>
          <limit>
            <cfm>0</cfm>
            <erp>0.2</erp>
          </limit>
        </ode>
      </physics>
    </joint>
    <link name='l_finger_2_link_median_bar'>
      <pose>-0.095933 0.0459997 0.0678802 1.57074 -1.4309 -3.14154</pose>
      <inertial>
        <pose>0.01905 -0.00107 0 0 -0 0</pose>
        <mass>0.00538</mass>
        <inertia>
          <ixx>6.639e-08</ixx>
          <ixy>-1.0996e-07</ixy>
          <ixz>9.4e-10</ixz>
          <iyy>3.05318e-06</iyy>
          <iyz>0</iyz>
          <izz>3.04657e-06</izz>
        </inertia>
      </inertial>
      <collision name='l_finger_2_link_median_bar_collision'>
        <pose>0.01905 0 0 0 -0 0</pose>
        <geometry>
          <box>
            <size>0.0381 0.0075 0.002</size>
          </box>
        </geometry>
        <surface>
          <contact>
            <ode/>
          </contact>
          <friction>
            <ode>
              <mu>1.1</mu>
              <mu2>1.1</mu2>
            </ode>
          </friction>
        </surface>
      </collision>
      <visual name='l_finger_2_link_median_bar_visual'>
        <pose>0.01905 0 0 0 -0 0</pose>
        <geometry>
          <box>
            <size>0.0381 0.0075 0.002</size>
          </box>
        </geometry>
      </visual>
      <gravity>1</gravity>
      <velocity_decay/>
      <self_collide>0</self_collide>
    </link>
    <joint name='l_finger_2_joint_median_actuating_hinge_median_bar' type='revolute'>
      <child>l_finger_2_link_median_bar</child>
      <parent>l_finger_2_link_median_actuating_hinge</parent>
      <axis>
        <xyz>-5.85014e-09 1 7.31961e-06</xyz>
        <limit>
          <lower>-3.1416</lower>
          <upper>3.1416</upper>
          <effort>100</effort>
          <velocity>100</velocity>
        </limit>
        <dynamics>
          <spring_reference>0</spring_reference>
          <spring_stiffness>0</spring_stiffness>
        </dynamics>
        <use_parent_model_frame>1</use_parent_model_frame>
      </axis>
      <physics>
        <ode>
          <implicit_spring_damper>1</implicit_spring_damper>
          <cfm_damping>1</cfm_damping>
          <limit>
            <cfm>0</cfm>
            <erp>0.2</erp>
          </limit>
        </ode>
      </physics>
    </joint>
    <link name='l_finger_2_link_paramedian_hinge'>
      <pose>-0.0739265 0.0259996 0.0709787 1.57079 0.5206 3.14159</pose>
      <inertial>
        <pose>-0.01025 0.00046 0 0 -0 0</pose>
        <mass>0.00276</mass>
        <inertia>
          <ixx>4.213e-08</ixx>
          <ixy>-1.491e-08</ixy>
          <ixz>0</ixz>
          <iyy>5.0258e-07</iyy>
          <iyz>0</iyz>
          <izz>5.4007e-07</izz>
        </inertia>
      </inertial>
      <collision name='l_finger_2_link_paramedian_hinge_collision'>
        <pose>0 0 0 0 -0 0</pose>
        <geometry>
          <box>
            <size>0.02 0.02 0.002</size>
          </box>
        </geometry>
        <surface>
          <contact>
            <ode/>
          </contact>
          <friction>
            <ode>
              <mu>1.1</mu>
              <mu2>1.1</mu2>
            </ode>
          </friction>
        </surface>
      </collision>
      <visual name='l_finger_2_link_paramedian_hinge_visual'>
        <pose>0 0 0 0 -0 0</pose>
        <geometry>
          <box>
            <size>0.02 0.02 0.002</size>
          </box>
        </geometry>
      </visual>
      <gravity>1</gravity>
      <velocity_decay/>
      <self_collide>0</self_collide>
    </link>
    <joint name='l_finger_2_joint_paramedian_hinge' type='revolute'>
      <child>l_finger_2_link_paramedian_hinge</child>
      <parent>l_finger_2_link_1</parent>
      <axis>
        <xyz>-5.85014e-09 1 7.31961e-06</xyz>
        <limit>
          <lower>-3.1416</lower>
          <upper>3.1416</upper>
          <effort>100</effort>
          <velocity>100</velocity>
        </limit>
        <dynamics>
          <spring_reference>0</spring_reference>
          <spring_stiffness>0</spring_stiffness>
        </dynamics>
        <use_parent_model_frame>1</use_parent_model_frame>
      </axis>
      <physics>
        <ode>
          <implicit_spring_damper>1</implicit_spring_damper>
          <cfm_damping>1</cfm_damping>
          <limit>
            <cfm>0</cfm>
            <erp>0.2</erp>
          </limit>
        </ode>
      </physics>
    </joint>
    <link name='l_finger_2_link_median_bar_underactuated'>
      <pose>-0.0862074 0.0259997 0.0677298 1.57078 -1.0502 -3.14158</pose>
      <inertial>
        <pose>0.01905 -0.00107 0 0 -0 0</pose>
        <mass>0.00538</mass>
        <inertia>
          <ixx>6.639e-08</ixx>
          <ixy>-1.0996e-07</ixy>
          <ixz>-9.4e-10</ixz>
          <iyy>3.05318e-06</iyy>
          <iyz>0</iyz>
          <izz>3.04657e-06</izz>
        </inertia>
      </inertial>
      <collision name='l_finger_2_link_median_bar_underactuated_collision'>
        <pose>0.01905 0 0 0 -0 0</pose>
        <geometry>
          <box>
            <size>0.0381 0.0075 0.002</size>
          </box>
        </geometry>
        <surface>
          <contact>
            <ode/>
          </contact>
          <friction>
            <ode>
              <mu>1.1</mu>
              <mu2>1.1</mu2>
            </ode>
          </friction>
        </surface>
      </collision>
      <visual name='l_finger_2_link_median_bar_underactuated_visual'>
        <pose>0.01905 0 0 0 -0 0</pose>
        <geometry>
          <box>
            <size>0.0381 0.0075 0.002</size>
          </box>
        </geometry>
      </visual>
      <gravity>1</gravity>
      <velocity_decay/>
      <self_collide>0</self_collide>
    </link>
    <joint name='l_finger_2_joint_paramedian_hinge_median_bar_underactuated' type='revolute'>
      <child>l_finger_2_link_median_bar_underactuated</child>
      <parent>l_finger_2_link_paramedian_hinge</parent>
      <axis>
        <xyz>-5.85014e-09 1 7.31961e-06</xyz>
        <limit>
          <lower>-3.1416</lower>
          <upper>3.1416</upper>
          <effort>100</effort>
          <velocity>100</velocity>
        </limit>
        <dynamics>
          <spring_reference>0</spring_reference>
          <spring_stiffness>0</spring_stiffness>
        </dynamics>
        <use_parent_model_frame>1</use_parent_model_frame>
      </axis>
      <physics>
        <ode>
          <implicit_spring_damper>1</implicit_spring_damper>
          <cfm_damping>1</cfm_damping>
          <limit>
            <cfm>0</cfm>
            <erp>0.2</erp>
          </limit>
        </ode>
      </physics>
    </joint>
    <link name='l_finger_2_link_paraproximal_actuating_hinge'>
      <pose>-0.0455 0.026 0.0213999 1.57079 0.5206 3.14159</pose>
      <inertial>
        <pose>0.0064 0 0 0 -0 0</pose>
        <mass>0.00362</mass>
        <inertia>
          <ixx>1.2043e-07</ixx>
          <ixy>0</ixy>
          <ixz>0</ixz>
          <iyy>5.3588e-07</iyy>
          <iyz>0</iyz>
          <izz>6.5322e-07</izz>
        </inertia>
      </inertial>
      <collision name='l_finger_2_link_paraproximal_actuating_hinge_collision'>
        <pose>0.01143 0 0 0 -0 0</pose>
        <geometry>
          <box>
            <size>0.02286 0.0075 0.002</size>
          </box>
        </geometry>
        <surface>
          <contact>
            <ode/>
          </contact>
          <friction>
            <ode>
              <mu>1.1</mu>
              <mu2>1.1</mu2>
            </ode>
          </friction>
        </surface>
      </collision>
      <visual name='l_finger_2_link_paraproximal_actuating_hinge_visual'>
        <pose>0.01143 0 0 0 -0 0</pose>
        <geometry>
          <box>
            <size>0.02286 0.0075 0.002</size>
          </box>
        </geometry>
      </visual>
      <gravity>1</gravity>
      <velocity_decay/>
      <self_collide>0</self_collide>
    </link>
    <joint name='l_finger_2_joint_paraproximal_actuating_hinge' type='revolute'>
      <child>l_finger_2_link_paraproximal_actuating_hinge</child>
      <parent>l_finger_2_link_0</parent>
      <axis>
        <xyz>-5.85014e-09 1 7.31961e-06</xyz>
        <limit>
          <lower>-3.1416</lower>
          <upper>3.1416</upper>
          <effort>100</effort>
          <velocity>100</velocity>
        </limit>
        <dynamics>
          <spring_reference>0</spring_reference>
          <spring_stiffness>0</spring_stiffness>
        </dynamics>
        <use_parent_model_frame>1</use_parent_model_frame>
      </axis>
      <physics>
        <ode>
          <implicit_spring_damper>1</implicit_spring_damper>
          <cfm_damping>1</cfm_damping>
          <limit>
            <cfm>0</cfm>
            <erp>0.2</erp>
          </limit>
        </ode>
      </physics>
    </joint>
    <link name='l_finger_2_link_paraproximal_bar'>
      <pose>-0.0653315 0.0260001 0.0100293 1.57078 -1.0494 -3.14158</pose>
      <inertial>
        <pose>0.02858 -0.00129 0 0 -0 0</pose>
        <mass>0.00732</mass>
        <inertia>
          <ixx>9.065e-08</ixx>
          <ixy>-2.7047e-07</ixy>
          <ixz>1.42e-09</ixz>
          <iyy>8.78034e-06</iyy>
          <iyz>0</iyz>
          <izz>8.77558e-06</izz>
        </inertia>
      </inertial>
      <collision name='l_finger_2_link_paraproximal_bar_collision'>
        <pose>0.02885 0 0 0 -0 0</pose>
        <geometry>
          <box>
            <size>0.0577 0.0075 0.002</size>
          </box>
        </geometry>
        <surface>
          <contact>
            <ode/>
          </contact>
          <friction>
            <ode>
              <mu>1.1</mu>
              <mu2>1.1</mu2>
            </ode>
          </friction>
        </surface>
      </collision>
      <visual name='l_finger_2_link_paraproximal_bar_visual'>
        <pose>0.02885 0 0 0 -0 0</pose>
        <geometry>
          <box>
            <size>0.0577 0.0075 0.002</size>
          </box>
        </geometry>
      </visual>
      <gravity>1</gravity>
      <velocity_decay/>
      <self_collide>0</self_collide>
    </link>
    <joint name='l_finger_2_joint_paraproximal_bar' type='revolute'>
      <child>l_finger_2_link_paraproximal_bar</child>
      <parent>l_finger_2_link_paraproximal_actuating_hinge</parent>
      <axis>
        <xyz>-5.85014e-09 1 7.31961e-06</xyz>
        <limit>
          <lower>-3.1416</lower>
          <upper>3.1416</upper>
          <effort>100</effort>
          <velocity>100</velocity>
        </limit>
        <dynamics>
          <spring_reference>0</spring_reference>
          <spring_stiffness>0</spring_stiffness>
        </dynamics>
        <use_parent_model_frame>1</use_parent_model_frame>
      </axis>
      <physics>
        <ode>
          <implicit_spring_damper>1</implicit_spring_damper>
          <cfm_damping>1</cfm_damping>
          <limit>
            <cfm>0</cfm>
            <erp>0.2</erp>
          </limit>
        </ode>
      </physics>
    </joint>
    <link name='l_finger_2_link_proximal_actuating_hinge'>
      <pose>-0.0455 0.046 0.0214001 1.57079 0.5206 3.14159</pose>
      <inertial>
        <pose>0.0012 -0.00162 -0.00161 0 -0 0</pose>
        <mass>0.02647</mass>
        <inertia>
          <ixx>1.56447e-06</ixx>
          <ixy>2.36226e-07</ixy>
          <ixz>-1.4862e-07</ixz>
          <iyy>2.21068e-06</iyy>
          <iyz>-1.4369e-07</iyz>
          <izz>3.23175e-06</izz>
        </inertia>
      </inertial>
      <collision name='l_finger_2_link_proximal_actuating_hinge_collision'>
        <pose>0.01429 0 0 0 -0 0</pose>
        <geometry>
          <box>
            <size>0.02858 0.0075 0.002</size>
          </box>
        </geometry>
        <surface>
          <contact>
            <ode/>
          </contact>
          <friction>
            <ode>
              <mu>1.1</mu>
              <mu2>1.1</mu2>
            </ode>
          </friction>
        </surface>
      </collision>
      <visual name='l_finger_2_link_proximal_actuating_hinge_visual'>
        <pose>0.01429 0 0 0 -0 0</pose>
        <geometry>
          <box>
            <size>0.02858 0.0075 0.002</size>
          </box>
        </geometry>
      </visual>
      <gravity>1</gravity>
      <velocity_decay/>
      <self_collide>0</self_collide>
    </link>
    <joint name='l_finger_2_joint_proximal_actuating_hinge' type='revolute'>
      <child>l_finger_2_link_proximal_actuating_hinge</child>
      <parent>l_finger_2_link_0</parent>
      <axis>
        <xyz>-5.85014e-09 1 7.31961e-06</xyz>
        <limit>
          <lower>-3.1416</lower>
          <upper>3.1416</upper>
          <effort>100</effort>
          <velocity>100</velocity>
        </limit>
        <dynamics>
          <spring_reference>0</spring_reference>
          <spring_stiffness>0</spring_stiffness>
        </dynamics>
        <use_parent_model_frame>1</use_parent_model_frame>
      </axis>
      <physics>
        <ode>
          <implicit_spring_damper>1</implicit_spring_damper>
          <cfm_damping>1</cfm_damping>
          <limit>
            <cfm>0</cfm>
            <erp>0.2</erp>
          </limit>
        </ode>
      </physics>
    </joint>
    <link name='l_finger_2_link_proximal_actuating_bar'>
      <pose>-0.0702937 0.0460001 0.00718436 1.57076 -1.341 -3.14156</pose>
      <inertial>
        <pose>0.02699 -0.00122 0 0 -0 0</pose>
        <mass>0.00659</mass>
        <inertia>
          <ixx>8.348e-08</ixx>
          <ixy>-2.179e-07</ixy>
          <ixz>1.34e-09</ixz>
          <iyy>7.19076e-06</iyy>
          <iyz>0</iyz>
          <izz>7.18272e-06</izz>
        </inertia>
      </inertial>
      <collision name='l_finger_2_link_proximal_actuating_bar_collision'>
        <pose>0.026789 0 0 0 -0 0</pose>
        <geometry>
          <box>
            <size>0.05398 0.0075 0.002</size>
          </box>
        </geometry>
        <surface>
          <contact>
            <ode/>
          </contact>
          <friction>
            <ode>
              <mu>1.1</mu>
              <mu2>1.1</mu2>
            </ode>
          </friction>
        </surface>
      </collision>
      <visual name='l_finger_2_link_proximal_actuating_bar_visual'>
        <pose>0.026789 0 0 0 -0 0</pose>
        <geometry>
          <box>
            <size>0.05398 0.0075 0.002</size>
          </box>
        </geometry>
      </visual>
      <gravity>1</gravity>
      <velocity_decay/>
      <self_collide>0</self_collide>
    </link>
    <joint name='l_finger_2_joint_proximal_actuating_bar' type='revolute'>
      <child>l_finger_2_link_proximal_actuating_bar</child>
      <parent>l_finger_2_link_proximal_actuating_hinge</parent>
      <axis>
        <xyz>-5.85014e-09 1 7.31961e-06</xyz>
        <limit>
          <lower>-3.1416</lower>
          <upper>3.1416</upper>
          <effort>100</effort>
          <velocity>100</velocity>
        </limit>
        <dynamics>
          <spring_reference>0</spring_reference>
          <spring_stiffness>0</spring_stiffness>
        </dynamics>
        <use_parent_model_frame>1</use_parent_model_frame>
      </axis>
      <physics>
        <ode>
          <implicit_spring_damper>1</implicit_spring_damper>
          <cfm_damping>1</cfm_damping>
          <limit>
            <cfm>0</cfm>
            <erp>0.2</erp>
          </limit>
        </ode>
      </physics>
    </joint>
    <link name='l_finger_middle_link_0'>
      <pose>0.0455 5.73411e-10 0.0214 1.57076 -1.57 3.36481e-05</pose>
      <inertial>
        <pose>-0.01 0 0 0 -0 0</pose>
        <mass>0.1</mass>
        <inertia>
          <ixx>1.8e-05</ixx>
          <ixy>0</ixy>
          <ixz>0</ixz>
          <iyy>2.5e-05</iyy>
          <iyz>0</iyz>
          <izz>2.5e-05</izz>
        </inertia>
      </inertial>
      <collision name='l_finger_middle_link_0_collision'>
        <pose>0 0 0 -3.14159 5.35898e-08 1.5708</pose>
        <geometry>
          <mesh>
            <scale>1 1 1</scale>
            <uri>model://robotiq_s_model_visualization/meshes/s-model_articulated/collision/link_0.STL</uri>
          </mesh>
        </geometry>
        <surface>
          <contact>
            <ode/>
          </contact>
          <friction>
            <ode>
              <mu>1.1</mu>
              <mu2>1.1</mu2>
            </ode>
          </friction>
        </surface>
      </collision>
      <visual name='l_finger_middle_link_0_visual'>
        <pose>0.02 0 0 0 -0 0</pose>
        <geometry>
          <mesh>
            <scale>1 1 1</scale>
            <uri>model://robotiq_s_model_visualization/meshes/s-model_articulated/visual/link_0.STL</uri>
          </mesh>
        </geometry>
      </visual>
      <gravity>1</gravity>
      <velocity_decay/>
      <self_collide>0</self_collide>
    </link>
    <joint name='l_palm_finger_middle_joint' type='revolute'>
      <child>l_finger_middle_link_0</child>
      <parent>EE_LINK</parent>
      <axis>
        <xyz>-1 2.13375e-11 0.000796327</xyz>
        <limit>
          <lower>0</lower>
          <upper>0</upper>
          <effort>60</effort>
          <velocity>-1</velocity>
        </limit>
        <dynamics>
          <damping>1</damping>
          <friction>0</friction>
          <spring_reference>0</spring_reference>
          <spring_stiffness>0</spring_stiffness>
        </dynamics>
        <use_parent_model_frame>1</use_parent_model_frame>
      </axis>
      <physics>
        <ode>
          <implicit_spring_damper>1</implicit_spring_damper>
          <cfm_damping>1</cfm_damping>
          <limit>
            <cfm>0</cfm>
            <erp>0.2</erp>
          </limit>
        </ode>
      </physics>
    </joint>
    <link name='l_finger_middle_link_1'>
      <pose>0.0455 5.73411e-10 0.0214 1.5708 0.5206 -1.53631e-08</pose>
      <inertial>
        <pose>0.00053 0.03218 0 0 -0 1.5708</pose>
        <mass>0.047</mass>
        <inertia>
          <ixx>4.99332e-06</ixx>
          <ixy>9.1312e-07</ixy>
          <ixz>-1.2e-09</ixz>
          <iyy>6.43453e-05</iyy>
          <iyz>-7e-11</iyz>
          <izz>6.06192e-05</izz>
        </inertia>
      </inertial>
      <collision name='l_finger_middle_link_1_collision'>
        <pose>0 0.05717 0 0 -0 1.5708</pose>
        <geometry>
          <mesh>
            <scale>1 1 1</scale>
            <uri>model://robotiq_s_model_visualization/meshes/s-model_articulated/collision/link_1.STL</uri>
          </mesh>
        </geometry>
        <surface>
          <contact>
            <ode/>
          </contact>
          <friction>
            <ode>
              <mu>1.1</mu>
              <mu2>1.1</mu2>
            </ode>
          </friction>
        </surface>
      </collision>
      <visual name='l_finger_middle_link_1_visual'>
        <pose>0 0.05717 0 0 -0 1.5708</pose>
        <geometry>
          <mesh>
            <scale>1 1 1</scale>
            <uri>model://robotiq_s_model_visualization/meshes/s-model_articulated/visual/link_1.STL</uri>
          </mesh>
        </geometry>
      </visual>
      <gravity>1</gravity>
      <velocity_decay/>
      <self_collide>0</self_collide>
    </link>
    <joint name='l_finger_middle_joint_1' type='revolute'>
      <child>l_finger_middle_link_1</child>
      <parent>l_finger_middle_link_0</parent>
      <axis>
        <xyz>1.38778e-17 -1 2.67949e-08</xyz>
        <limit>
          <lower>0</lower>
          <upper>1.2217</upper>
          <effort>60</effort>
          <velocity>-1</velocity>
        </limit>
        <dynamics>
          <damping>1</damping>
          <friction>0</friction>
          <spring_reference>0</spring_reference>
          <spring_stiffness>0</spring_stiffness>
        </dynamics>
        <use_parent_model_frame>1</use_parent_model_frame>
      </axis>
      <physics>
        <ode>
          <implicit_spring_damper>1</implicit_spring_damper>
          <cfm_damping>1</cfm_damping>
          <limit>
            <cfm>0</cfm>
            <erp>0.2</erp>
          </limit>
        </ode>
      </physics>
    </joint>
    <link name='l_finger_middle_link_2'>
      <pose>0.0739265 1.90187e-09 0.0709788 1.5708 0.5206 -1.53631e-08</pose>
      <inertial>
        <pose>0.00048 0.02167 0.00018 0 -0 1.5708</pose>
        <mass>0.03284</mass>
        <inertia>
          <ixx>3.48008e-06</ixx>
          <ixy>3.194e-07</ixy>
          <ixz>1.3041e-07</ixz>
          <iyy>2.24812e-05</iyy>
          <iyz>2.91e-09</iyz>
          <izz>1.98635e-05</izz>
        </inertia>
      </inertial>
      <collision name='l_finger_middle_link_2_collision'>
        <pose>0 0.0381 0.0075 0 -0 1.5708</pose>
        <geometry>
          <mesh>
            <scale>1 1 1</scale>
            <uri>model://robotiq_s_model_visualization/meshes/s-model_articulated/collision/link_2.STL</uri>
          </mesh>
        </geometry>
        <surface>
          <contact>
            <ode/>
          </contact>
          <friction>
            <ode>
              <mu>1.1</mu>
              <mu2>1.1</mu2>
            </ode>
          </friction>
        </surface>
      </collision>
      <visual name='l_finger_middle_link_2_visual'>
        <pose>0 0.0381 0.0075 0 -0 1.5708</pose>
        <geometry>
          <mesh>
            <scale>1 1 1</scale>
            <uri>model://robotiq_s_model_visualization/meshes/s-model_articulated/visual/link_2.STL</uri>
          </mesh>
        </geometry>
      </visual>
      <gravity>1</gravity>
      <velocity_decay/>
      <self_collide>0</self_collide>
    </link>
    <joint name='l_finger_middle_joint_2' type='revolute'>
      <child>l_finger_middle_link_2</child>
      <parent>l_finger_middle_link_1</parent>
      <axis>
        <xyz>1.38778e-17 -1 2.67949e-08</xyz>
        <limit>
          <lower>0</lower>
          <upper>1.5708</upper>
          <effort>60</effort>
          <velocity>-1</velocity>
        </limit>
        <dynamics>
          <damping>1</damping>
          <friction>0</friction>
          <spring_reference>0</spring_reference>
          <spring_stiffness>0</spring_stiffness>
        </dynamics>
        <use_parent_model_frame>1</use_parent_model_frame>
      </axis>
      <physics>
        <ode>
          <implicit_spring_damper>1</implicit_spring_damper>
          <cfm_damping>1</cfm_damping>
          <limit>
            <cfm>0</cfm>
            <erp>0.2</erp>
          </limit>
        </ode>
      </physics>
    </joint>
    <link name='l_finger_middle_link_3'>
      <pose>0.0933251 2.80843e-09 0.104812 1.57076 -1.57 3.36481e-05</pose>
      <inertial>
        <pose>0.01626 0.00049 0.0002 0 -0 0</pose>
        <mass>0.03354</mass>
        <inertia>
          <ixx>3.05151e-06</ixx>
          <ixy>8.9792e-07</ixy>
          <ixz>2.49e-09</ixz>
          <iyy>1.42798e-05</iyy>
          <iyz>-1.191e-08</iyz>
          <izz>1.26413e-05</izz>
        </inertia>
      </inertial>
      <collision name='l_finger_middle_link_3_collision'>
        <pose>0 0 0 0 -0 0</pose>
        <geometry>
          <mesh>
            <scale>1 1 1</scale>
            <uri>model://robotiq_s_model_visualization/meshes/s-model_articulated/collision/link_3.STL</uri>
          </mesh>
        </geometry>
        <surface>
          <contact>
            <ode>
              <kp>10000</kp>
              <kd>1</kd>
            </ode>
          </contact>
          <friction>
            <ode>
              <mu>1000</mu>
              <mu2>1000</mu2>
            </ode>
          </friction>
        </surface>
      </collision>
      <visual name='l_finger_middle_link_3_visual'>
        <pose>0 0 0 0 -0 0</pose>
        <geometry>
          <mesh>
            <scale>1 1 1</scale>
            <uri>model://robotiq_s_model_visualization/meshes/s-model_articulated/visual/link_3.STL</uri>
          </mesh>
        </geometry>
      </visual>
      <gravity>1</gravity>
      <velocity_decay/>
      <self_collide>0</self_collide>
    </link>
    <joint name='l_finger_middle_joint_3' type='revolute'>
      <child>l_finger_middle_link_3</child>
      <parent>l_finger_middle_link_2</parent>
      <axis>
        <xyz>1.66533e-16 -1 2.67949e-08</xyz>
        <limit>
          <lower>-0.6632</lower>
          <upper>1.0471</upper>
          <effort>60</effort>
          <velocity>-1</velocity>
        </limit>
        <dynamics>
          <damping>1</damping>
          <friction>0</friction>
          <spring_reference>0</spring_reference>
          <spring_stiffness>0</spring_stiffness>
        </dynamics>
        <use_parent_model_frame>1</use_parent_model_frame>
      </axis>
      <physics>
        <ode>
          <implicit_spring_damper>1</implicit_spring_damper>
          <cfm_damping>1</cfm_damping>
          <limit>
            <cfm>0</cfm>
            <erp>0.2</erp>
          </limit>
        </ode>
      </physics>
    </joint>
    <link name='l_finger_middle_link_paradistal_hinge'>
      <pose>0.0933251 0.01 0.104812 1.5708 0.5206 -1.53631e-08</pose>
      <inertial>
        <pose>0.00548 0 0 0 -0 0</pose>
        <mass>0.00158</mass>
        <inertia>
          <ixx>1.907e-08</ixx>
          <ixy>0</ixy>
          <ixz>0</ixz>
          <iyy>1.097e-07</iyy>
          <iyz>0</iyz>
          <izz>1.261e-07</izz>
        </inertia>
      </inertial>
      <collision name='l_finger_middle_link_paradistal_hinge_collision'>
        <pose>0 0 0 0 -0 0</pose>
        <geometry>
          <box>
            <size>0.02 0.02 0.002</size>
          </box>
        </geometry>
        <surface>
          <contact>
            <ode/>
          </contact>
          <friction>
            <ode>
              <mu>1.1</mu>
              <mu2>1.1</mu2>
            </ode>
          </friction>
        </surface>
      </collision>
      <visual name='l_finger_middle_link_paradistal_hinge_visual'>
        <pose>0 0 0 0 -0 0</pose>
        <geometry>
          <box>
            <size>0.02 0.02 0.002</size>
          </box>
        </geometry>
      </visual>
      <gravity>1</gravity>
      <velocity_decay/>
      <self_collide>0</self_collide>
    </link>
    <joint name='l_finger_middle_joint_paradistal_hinge' type='revolute'>
      <child>l_finger_middle_link_paradistal_hinge</child>
      <parent>l_finger_middle_link_2</parent>
      <axis>
        <xyz>1.38778e-17 -1 2.67949e-08</xyz>
        <limit>
          <lower>-3.1416</lower>
          <upper>3.1416</upper>
          <effort>100</effort>
          <velocity>100</velocity>
        </limit>
        <dynamics>
          <spring_reference>0</spring_reference>
          <spring_stiffness>0</spring_stiffness>
        </dynamics>
        <use_parent_model_frame>1</use_parent_model_frame>
      </axis>
      <physics>
        <ode>
          <implicit_spring_damper>1</implicit_spring_damper>
          <cfm_damping>1</cfm_damping>
          <limit>
            <cfm>0</cfm>
            <erp>0.2</erp>
          </limit>
        </ode>
      </physics>
    </joint>
    <link name='l_finger_middle_link_median_actuating_hinge'>
      <pose>0.0739265 -0.01 0.0709788 1.5708 0.8906 -3.31216e-08</pose>
      <inertial>
        <pose>0.0092 0.00514 0 0 -0 0</pose>
        <mass>0.00359</mass>
        <inertia>
          <ixx>2.4735e-07</ixx>
          <ixy>2.3619e-07</ixy>
          <ixz>0</ixz>
          <iyy>4.7681e-07</iyy>
          <iyz>0</iyz>
          <izz>7.1813e-07</izz>
        </inertia>
      </inertial>
      <collision name='l_finger_middle_link_median_actuating_hinge_collision'>
        <pose>0 0 0 0 -0 0</pose>
        <geometry>
          <box>
            <size>0.02 0.02 0.002</size>
          </box>
        </geometry>
        <surface>
          <contact>
            <ode/>
          </contact>
          <friction>
            <ode>
              <mu>1.1</mu>
              <mu2>1.1</mu2>
            </ode>
          </friction>
        </surface>
      </collision>
      <visual name='l_finger_middle_link_median_actuating_hinge_visual'>
        <pose>0 0 0 0 -0 0</pose>
        <geometry>
          <box>
            <size>0.02 0.02 0.002</size>
          </box>
        </geometry>
      </visual>
      <gravity>1</gravity>
      <velocity_decay/>
      <self_collide>0</self_collide>
    </link>
    <joint name='l_finger_middle_joint_median_actuating_hinge' type='revolute'>
      <child>l_finger_middle_link_median_actuating_hinge</child>
      <parent>l_finger_middle_link_1</parent>
      <axis>
        <xyz>8.32667e-17 -1 2.67949e-08</xyz>
        <limit>
          <lower>-3.1416</lower>
          <upper>3.1416</upper>
          <effort>100</effort>
          <velocity>100</velocity>
        </limit>
        <dynamics>
          <spring_reference>0</spring_reference>
          <spring_stiffness>0</spring_stiffness>
        </dynamics>
        <use_parent_model_frame>1</use_parent_model_frame>
      </axis>
      <physics>
        <ode>
          <implicit_spring_damper>1</implicit_spring_damper>
          <cfm_damping>1</cfm_damping>
          <limit>
            <cfm>0</cfm>
            <erp>0.2</erp>
          </limit>
        </ode>
      </physics>
    </joint>
    <link name='l_finger_middle_link_median_bar'>
      <pose>0.095933 -0.01 0.0678801 1.5708 -1.4309 1.90283e-07</pose>
      <inertial>
        <pose>0.01905 -0.00107 0 0 -0 0</pose>
        <mass>0.00538</mass>
        <inertia>
          <ixx>6.639e-08</ixx>
          <ixy>-1.0996e-07</ixy>
          <ixz>9.4e-10</ixz>
          <iyy>3.05318e-06</iyy>
          <iyz>0</iyz>
          <izz>3.04657e-06</izz>
        </inertia>
      </inertial>
      <collision name='l_finger_middle_link_median_bar_collision'>
        <pose>0.01905 0 0 0 -0 0</pose>
        <geometry>
          <box>
            <size>0.0381 0.0075 0.002</size>
          </box>
        </geometry>
        <surface>
          <contact>
            <ode/>
          </contact>
          <friction>
            <ode>
              <mu>1.1</mu>
              <mu2>1.1</mu2>
            </ode>
          </friction>
        </surface>
      </collision>
      <visual name='l_finger_middle_link_median_bar_visual'>
        <pose>0.01905 0 0 0 -0 0</pose>
        <geometry>
          <box>
            <size>0.0381 0.0075 0.002</size>
          </box>
        </geometry>
      </visual>
      <gravity>1</gravity>
      <velocity_decay/>
      <self_collide>0</self_collide>
    </link>
    <joint name='l_finger_middle_joint_median_actuating_hinge_median_bar' type='revolute'>
      <child>l_finger_middle_link_median_bar</child>
      <parent>l_finger_middle_link_median_actuating_hinge</parent>
      <axis>
        <xyz>8.32667e-17 -1 2.67949e-08</xyz>
        <limit>
          <lower>-3.1416</lower>
          <upper>3.1416</upper>
          <effort>100</effort>
          <velocity>100</velocity>
        </limit>
        <dynamics>
          <spring_reference>0</spring_reference>
          <spring_stiffness>0</spring_stiffness>
        </dynamics>
        <use_parent_model_frame>1</use_parent_model_frame>
      </axis>
      <physics>
        <ode>
          <implicit_spring_damper>1</implicit_spring_damper>
          <cfm_damping>1</cfm_damping>
          <limit>
            <cfm>0</cfm>
            <erp>0.2</erp>
          </limit>
        </ode>
      </physics>
    </joint>
    <link name='l_finger_middle_link_paramedian_hinge'>
      <pose>0.0739265 0.01 0.0709788 1.5708 0.5206 -1.53631e-08</pose>
      <inertial>
        <pose>-0.01025 0.00046 0 0 -0 0</pose>
        <mass>0.00276</mass>
        <inertia>
          <ixx>4.213e-08</ixx>
          <ixy>-1.491e-08</ixy>
          <ixz>0</ixz>
          <iyy>5.0258e-07</iyy>
          <iyz>0</iyz>
          <izz>5.4007e-07</izz>
        </inertia>
      </inertial>
      <collision name='l_finger_middle_link_paramedian_hinge_collision'>
        <pose>0 0 0 0 -0 0</pose>
        <geometry>
          <box>
            <size>0.02 0.02 0.002</size>
          </box>
        </geometry>
        <surface>
          <contact>
            <ode/>
          </contact>
          <friction>
            <ode>
              <mu>1.1</mu>
              <mu2>1.1</mu2>
            </ode>
          </friction>
        </surface>
      </collision>
      <visual name='l_finger_middle_link_paramedian_hinge_visual'>
        <pose>0 0 0 0 -0 0</pose>
        <geometry>
          <box>
            <size>0.02 0.02 0.002</size>
          </box>
        </geometry>
      </visual>
      <gravity>1</gravity>
      <velocity_decay/>
      <self_collide>0</self_collide>
    </link>
    <joint name='l_finger_middle_joint_paramedian_hinge' type='revolute'>
      <child>l_finger_middle_link_paramedian_hinge</child>
      <parent>l_finger_middle_link_1</parent>
      <axis>
        <xyz>1.38778e-17 -1 2.67949e-08</xyz>
        <limit>
          <lower>-3.1416</lower>
          <upper>3.1416</upper>
          <effort>100</effort>
          <velocity>100</velocity>
        </limit>
        <dynamics>
          <spring_reference>0</spring_reference>
          <spring_stiffness>0</spring_stiffness>
        </dynamics>
        <use_parent_model_frame>1</use_parent_model_frame>
      </axis>
      <physics>
        <ode>
          <implicit_spring_damper>1</implicit_spring_damper>
          <cfm_damping>1</cfm_damping>
          <limit>
            <cfm>0</cfm>
            <erp>0.2</erp>
          </limit>
        </ode>
      </physics>
    </joint>
    <link name='l_finger_middle_link_median_bar_underactuated'>
      <pose>0.0862074 0.01 0.0677299 1.5708 -1.0502 4.67336e-08</pose>
      <inertial>
        <pose>0.01905 -0.00107 0 0 -0 0</pose>
        <mass>0.00538</mass>
        <inertia>
          <ixx>6.639e-08</ixx>
          <ixy>-1.0996e-07</ixy>
          <ixz>-9.4e-10</ixz>
          <iyy>3.05318e-06</iyy>
          <iyz>0</iyz>
          <izz>3.04657e-06</izz>
        </inertia>
      </inertial>
      <collision name='l_finger_middle_link_median_bar_underactuated_collision'>
        <pose>0.01905 0 0 0 -0 0</pose>
        <geometry>
          <box>
            <size>0.0381 0.0075 0.002</size>
          </box>
        </geometry>
        <surface>
          <contact>
            <ode/>
          </contact>
          <friction>
            <ode>
              <mu>1.1</mu>
              <mu2>1.1</mu2>
            </ode>
          </friction>
        </surface>
      </collision>
      <visual name='l_finger_middle_link_median_bar_underactuated_visual'>
        <pose>0.01905 0 0 0 -0 0</pose>
        <geometry>
          <box>
            <size>0.0381 0.0075 0.002</size>
          </box>
        </geometry>
      </visual>
      <gravity>1</gravity>
      <velocity_decay/>
      <self_collide>0</self_collide>
    </link>
    <joint name='l_finger_middle_joint_paramedian_hinge_median_bar_underactuated' type='revolute'>
      <child>l_finger_middle_link_median_bar_underactuated</child>
      <parent>l_finger_middle_link_paramedian_hinge</parent>
      <axis>
        <xyz>0 -1 2.67949e-08</xyz>
        <limit>
          <lower>-3.1416</lower>
          <upper>3.1416</upper>
          <effort>100</effort>
          <velocity>100</velocity>
        </limit>
        <dynamics>
          <spring_reference>0</spring_reference>
          <spring_stiffness>0</spring_stiffness>
        </dynamics>
        <use_parent_model_frame>1</use_parent_model_frame>
      </axis>
      <physics>
        <ode>
          <implicit_spring_damper>1</implicit_spring_damper>
          <cfm_damping>1</cfm_damping>
          <limit>
            <cfm>0</cfm>
            <erp>0.2</erp>
          </limit>
        </ode>
      </physics>
    </joint>
    <link name='l_finger_middle_link_paraproximal_actuating_hinge'>
      <pose>0.0455 0.01 0.0214 1.5708 0.5206 -1.53631e-08</pose>
      <inertial>
        <pose>0.0064 0 0 0 -0 0</pose>
        <mass>0.00362</mass>
        <inertia>
          <ixx>1.2043e-07</ixx>
          <ixy>0</ixy>
          <ixz>0</ixz>
          <iyy>5.3588e-07</iyy>
          <iyz>0</iyz>
          <izz>6.5322e-07</izz>
        </inertia>
      </inertial>
      <collision name='l_finger_middle_link_paraproximal_actuating_hinge_collision'>
        <pose>0.01143 0 0 0 -0 0</pose>
        <geometry>
          <box>
            <size>0.02286 0.0075 0.002</size>
          </box>
        </geometry>
        <surface>
          <contact>
            <ode/>
          </contact>
          <friction>
            <ode>
              <mu>1.1</mu>
              <mu2>1.1</mu2>
            </ode>
          </friction>
        </surface>
      </collision>
      <visual name='l_finger_middle_link_paraproximal_actuating_hinge_visual'>
        <pose>0.01143 0 0 0 -0 0</pose>
        <geometry>
          <box>
            <size>0.02286 0.0075 0.002</size>
          </box>
        </geometry>
      </visual>
      <gravity>1</gravity>
      <velocity_decay/>
      <self_collide>0</self_collide>
    </link>
    <joint name='l_finger_middle_joint_paraproximal_actuating_hinge' type='revolute'>
      <child>l_finger_middle_link_paraproximal_actuating_hinge</child>
      <parent>l_finger_middle_link_0</parent>
      <axis>
        <xyz>1.38778e-17 -1 2.67949e-08</xyz>
        <limit>
          <lower>-3.1416</lower>
          <upper>3.1416</upper>
          <effort>100</effort>
          <velocity>100</velocity>
        </limit>
        <dynamics>
          <spring_reference>0</spring_reference>
          <spring_stiffness>0</spring_stiffness>
        </dynamics>
        <use_parent_model_frame>1</use_parent_model_frame>
      </axis>
      <physics>
        <ode>
          <implicit_spring_damper>1</implicit_spring_damper>
          <cfm_damping>1</cfm_damping>
          <limit>
            <cfm>0</cfm>
            <erp>0.2</erp>
          </limit>
        </ode>
      </physics>
    </joint>
    <link name='l_finger_middle_link_paraproximal_bar'>
      <pose>0.0653315 0.01 0.0100294 1.5708 -1.0494 4.66471e-08</pose>
      <inertial>
        <pose>0.02858 -0.00129 0 0 -0 0</pose>
        <mass>0.00732</mass>
        <inertia>
          <ixx>9.065e-08</ixx>
          <ixy>-2.7047e-07</ixy>
          <ixz>1.42e-09</ixz>
          <iyy>8.78034e-06</iyy>
          <iyz>0</iyz>
          <izz>8.77558e-06</izz>
        </inertia>
      </inertial>
      <collision name='l_finger_middle_link_paraproximal_bar_collision'>
        <pose>0.02885 0 0 0 -0 0</pose>
        <geometry>
          <box>
            <size>0.0577 0.0075 0.002</size>
          </box>
        </geometry>
        <surface>
          <contact>
            <ode/>
          </contact>
          <friction>
            <ode>
              <mu>1.1</mu>
              <mu2>1.1</mu2>
            </ode>
          </friction>
        </surface>
      </collision>
      <visual name='l_finger_middle_link_paraproximal_bar_visual'>
        <pose>0.02885 0 0 0 -0 0</pose>
        <geometry>
          <box>
            <size>0.0577 0.0075 0.002</size>
          </box>
        </geometry>
      </visual>
      <gravity>1</gravity>
      <velocity_decay/>
      <self_collide>0</self_collide>
    </link>
    <joint name='l_finger_middle_joint_paraproximal_bar' type='revolute'>
      <child>l_finger_middle_link_paraproximal_bar</child>
      <parent>l_finger_middle_link_paraproximal_actuating_hinge</parent>
      <axis>
        <xyz>0 -1 2.67949e-08</xyz>
        <limit>
          <lower>-3.1416</lower>
          <upper>3.1416</upper>
          <effort>100</effort>
          <velocity>100</velocity>
        </limit>
        <dynamics>
          <spring_reference>0</spring_reference>
          <spring_stiffness>0</spring_stiffness>
        </dynamics>
        <use_parent_model_frame>1</use_parent_model_frame>
      </axis>
      <physics>
        <ode>
          <implicit_spring_damper>1</implicit_spring_damper>
          <cfm_damping>1</cfm_damping>
          <limit>
            <cfm>0</cfm>
            <erp>0.2</erp>
          </limit>
        </ode>
      </physics>
    </joint>
    <link name='l_finger_middle_link_proximal_actuating_hinge'>
      <pose>0.0455 -0.01 0.0214 1.5708 0.5206 -1.53631e-08</pose>
      <inertial>
        <pose>0.0012 -0.00162 -0.00161 0 -0 0</pose>
        <mass>0.02647</mass>
        <inertia>
          <ixx>1.56447e-06</ixx>
          <ixy>2.36226e-07</ixy>
          <ixz>-1.4862e-07</ixz>
          <iyy>2.21068e-06</iyy>
          <iyz>-1.4369e-07</iyz>
          <izz>3.23175e-06</izz>
        </inertia>
      </inertial>
      <collision name='l_finger_middle_link_proximal_actuating_hinge_collision'>
        <pose>0.01429 0 0 0 -0 0</pose>
        <geometry>
          <box>
            <size>0.02858 0.0075 0.002</size>
          </box>
        </geometry>
        <surface>
          <contact>
            <ode/>
          </contact>
          <friction>
            <ode>
              <mu>1.1</mu>
              <mu2>1.1</mu2>
            </ode>
          </friction>
        </surface>
      </collision>
      <visual name='l_finger_middle_link_proximal_actuating_hinge_visual'>
        <pose>0.01429 0 0 0 -0 0</pose>
        <geometry>
          <box>
            <size>0.02858 0.0075 0.002</size>
          </box>
        </geometry>
      </visual>
      <gravity>1</gravity>
      <velocity_decay/>
      <self_collide>0</self_collide>
    </link>
    <joint name='l_finger_middle_joint_proximal_actuating_hinge' type='revolute'>
      <child>l_finger_middle_link_proximal_actuating_hinge</child>
      <parent>l_finger_middle_link_0</parent>
      <axis>
        <xyz>1.38778e-17 -1 2.67949e-08</xyz>
        <limit>
          <lower>-3.1416</lower>
          <upper>3.1416</upper>
          <effort>100</effort>
          <velocity>100</velocity>
        </limit>
        <dynamics>
          <spring_reference>0</spring_reference>
          <spring_stiffness>0</spring_stiffness>
        </dynamics>
        <use_parent_model_frame>1</use_parent_model_frame>
      </axis>
      <physics>
        <ode>
          <implicit_spring_damper>1</implicit_spring_damper>
          <cfm_damping>1</cfm_damping>
          <limit>
            <cfm>0</cfm>
            <erp>0.2</erp>
          </limit>
        </ode>
      </physics>
    </joint>
    <link name='l_finger_middle_link_proximal_actuating_bar'>
      <pose>0.0702937 -0.01 0.00718429 1.5708 -1.341 1.14543e-07</pose>
      <inertial>
        <pose>0.02699 -0.00122 0 0 -0 0</pose>
        <mass>0.00659</mass>
        <inertia>
          <ixx>8.348e-08</ixx>
          <ixy>-2.179e-07</ixy>
          <ixz>1.34e-09</ixz>
          <iyy>7.19076e-06</iyy>
          <iyz>0</iyz>
          <izz>7.18272e-06</izz>
        </inertia>
      </inertial>
      <collision name='l_finger_middle_link_proximal_actuating_bar_collision'>
        <pose>0.026789 0 0 0 -0 0</pose>
        <geometry>
          <box>
            <size>0.05398 0.0075 0.002</size>
          </box>
        </geometry>
        <surface>
          <contact>
            <ode/>
          </contact>
          <friction>
            <ode>
              <mu>1.1</mu>
              <mu2>1.1</mu2>
            </ode>
          </friction>
        </surface>
      </collision>
      <visual name='l_finger_middle_link_proximal_actuating_bar_visual'>
        <pose>0.026789 0 0 0 -0 0</pose>
        <geometry>
          <box>
            <size>0.05398 0.0075 0.002</size>
          </box>
        </geometry>
      </visual>
      <gravity>1</gravity>
      <velocity_decay/>
      <self_collide>0</self_collide>
    </link>
    <joint name='l_finger_middle_joint_proximal_actuating_bar' type='revolute'>
      <child>l_finger_middle_link_proximal_actuating_bar</child>
      <parent>l_finger_middle_link_proximal_actuating_hinge</parent>
      <axis>
        <xyz>1.11022e-16 -1 2.67949e-08</xyz>
        <limit>
          <lower>-3.1416</lower>
          <upper>3.1416</upper>
          <effort>100</effort>
          <velocity>100</velocity>
        </limit>
        <dynamics>
          <spring_reference>0</spring_reference>
          <spring_stiffness>0</spring_stiffness>
        </dynamics>
        <use_parent_model_frame>1</use_parent_model_frame>
      </axis>
      <physics>
        <ode>
          <implicit_spring_damper>1</implicit_spring_damper>
          <cfm_damping>1</cfm_damping>
          <limit>
            <cfm>0</cfm>
            <erp>0.2</erp>
          </limit>
        </ode>
      </physics>
    </joint>
    <joint name='l_finger_1_link_proximal_actuating_bar_median_actuating_hinge_couple' type='revolute'>
      <parent>l_finger_1_link_median_actuating_hinge</parent>
      <child>l_finger_1_link_proximal_actuating_bar</child>
      <pose>0.05398 0 0 0 -0 0</pose>
      <axis>
        <dynamics>
          <damping>0</damping>
          <friction>0</friction>
          <spring_reference>0</spring_reference>
          <spring_stiffness>0</spring_stiffness>
        </dynamics>
        <xyz>0 0 1</xyz>
        <use_parent_model_frame>1</use_parent_model_frame>
        <limit>
          <lower>-1e+16</lower>
          <upper>1e+16</upper>
        </limit>
      </axis>
    </joint>
    <joint name='l_finger_1_link_median_bar_link_3_couple' type='revolute'>
      <parent>l_finger_1_link_3</parent>
      <child>l_finger_1_link_median_bar</child>
      <pose>0.0381 0 0 0 -0 0</pose>
      <axis>
        <dynamics>
          <damping>0</damping>
          <friction>0</friction>
          <spring_reference>0</spring_reference>
          <spring_stiffness>0</spring_stiffness>
        </dynamics>
        <xyz>0 0 1</xyz>
        <use_parent_model_frame>1</use_parent_model_frame>
        <limit>
          <lower>-1e+16</lower>
          <upper>1e+16</upper>
        </limit>
      </axis>
    </joint>
    <joint name='l_finger_1_link_paramedian_bar_paradistal_hinge_couple' type='revolute'>
      <parent>l_finger_1_link_paradistal_hinge</parent>
      <child>l_finger_1_link_median_bar_underactuated</child>
      <pose>0.0381 0 0 0 -0 0</pose>
      <axis>
        <dynamics>
          <damping>0</damping>
          <friction>0</friction>
          <spring_reference>0</spring_reference>
          <spring_stiffness>0</spring_stiffness>
        </dynamics>
        <xyz>0 0 1</xyz>
        <use_parent_model_frame>1</use_parent_model_frame>
        <limit>
          <lower>-1e+16</lower>
          <upper>1e+16</upper>
        </limit>
      </axis>
    </joint>
    <joint name='l_finger_1_link_paradistal_hinge_link_3_couple' type='revolute'>
      <parent>l_finger_1_link_paradistal_hinge</parent>
      <child>l_finger_1_link_3</child>
      <pose>0.0381 0 0 0 -0 0</pose>
      <axis>
        <dynamics>
          <damping>0</damping>
          <friction>0</friction>
          <spring_reference>0</spring_reference>
          <spring_stiffness>0</spring_stiffness>
        </dynamics>
        <xyz>0 0 1</xyz>
        <use_parent_model_frame>1</use_parent_model_frame>
        <limit>
          <lower>-1e+16</lower>
          <upper>1e+16</upper>
        </limit>
      </axis>
    </joint>
    <joint name='l_finger_1_link_paraproximal_bar_paramedian_hinge_couple' type='revolute'>
      <parent>l_finger_1_link_paramedian_hinge</parent>
      <child>l_finger_1_link_paraproximal_bar</child>
      <pose>0.0577 0 0 0 -0 0</pose>
      <axis>
        <dynamics>
          <damping>0</damping>
          <friction>0</friction>
          <spring_reference>0</spring_reference>
          <spring_stiffness>0</spring_stiffness>
        </dynamics>
        <xyz>0 0 1</xyz>
        <use_parent_model_frame>1</use_parent_model_frame>
        <limit>
          <lower>-1e+16</lower>
          <upper>1e+16</upper>
        </limit>
      </axis>
    </joint>
    <joint name='l_finger_2_link_proximal_actuating_bar_median_actuating_hinge_couple' type='revolute'>
      <parent>l_finger_2_link_median_actuating_hinge</parent>
      <child>l_finger_2_link_proximal_actuating_bar</child>
      <pose>0.05398 0 0 0 -0 0</pose>
      <axis>
        <dynamics>
          <damping>0</damping>
          <friction>0</friction>
          <spring_reference>0</spring_reference>
          <spring_stiffness>0</spring_stiffness>
        </dynamics>
        <xyz>0 0 1</xyz>
        <use_parent_model_frame>1</use_parent_model_frame>
        <limit>
          <lower>-1e+16</lower>
          <upper>1e+16</upper>
        </limit>
      </axis>
    </joint>
    <joint name='l_finger_2_link_median_bar_link_3_couple' type='revolute'>
      <parent>l_finger_2_link_3</parent>
      <child>l_finger_2_link_median_bar</child>
      <pose>0.0381 0 0 0 -0 0</pose>
      <axis>
        <dynamics>
          <damping>0</damping>
          <friction>0</friction>
          <spring_reference>0</spring_reference>
          <spring_stiffness>0</spring_stiffness>
        </dynamics>
        <xyz>0 0 1</xyz>
        <use_parent_model_frame>1</use_parent_model_frame>
        <limit>
          <lower>-1e+16</lower>
          <upper>1e+16</upper>
        </limit>
      </axis>
    </joint>
    <joint name='l_finger_2_link_paramedian_bar_paradistal_hinge_couple' type='revolute'>
      <parent>l_finger_2_link_paradistal_hinge</parent>
      <child>l_finger_2_link_median_bar_underactuated</child>
      <pose>0.0381 0 0 0 -0 0</pose>
      <axis>
        <dynamics>
          <damping>0</damping>
          <friction>0</friction>
          <spring_reference>0</spring_reference>
          <spring_stiffness>0</spring_stiffness>
        </dynamics>
        <xyz>0 0 1</xyz>
        <use_parent_model_frame>1</use_parent_model_frame>
        <limit>
          <lower>-1e+16</lower>
          <upper>1e+16</upper>
        </limit>
      </axis>
    </joint>
    <joint name='l_finger_2_link_paradistal_hinge_link_3_couple' type='revolute'>
      <parent>l_finger_2_link_paradistal_hinge</parent>
      <child>l_finger_2_link_3</child>
      <pose>0.0381 0 0 0 -0 0</pose>
      <axis>
        <dynamics>
          <damping>0</damping>
          <friction>0</friction>
          <spring_reference>0</spring_reference>
          <spring_stiffness>0</spring_stiffness>
        </dynamics>
        <xyz>0 0 1</xyz>
        <use_parent_model_frame>1</use_parent_model_frame>
        <limit>
          <lower>-1e+16</lower>
          <upper>1e+16</upper>
        </limit>
      </axis>
    </joint>
    <joint name='l_finger_2_link_paraproximal_bar_paramedian_hinge_couple' type='revolute'>
      <parent>l_finger_2_link_paramedian_hinge</parent>
      <child>l_finger_2_link_paraproximal_bar</child>
      <pose>0.0577 0 0 0 -0 0</pose>
      <axis>
        <dynamics>
          <damping>0</damping>
          <friction>0</friction>
          <spring_reference>0</spring_reference>
          <spring_stiffness>0</spring_stiffness>
        </dynamics>
        <xyz>0 0 1</xyz>
        <use_parent_model_frame>1</use_parent_model_frame>
        <limit>
          <lower>-1e+16</lower>
          <upper>1e+16</upper>
        </limit>
      </axis>
    </joint>
    <joint name='l_finger_middle_link_proximal_actuating_bar_median_actuating_hinge_couple' type='revolute'>
      <parent>l_finger_middle_link_median_actuating_hinge</parent>
      <child>l_finger_middle_link_proximal_actuating_bar</child>
      <pose>0.05398 0 0 0 -0 0</pose>
      <axis>
        <dynamics>
          <damping>0</damping>
          <friction>0</friction>
          <spring_reference>0</spring_reference>
          <spring_stiffness>0</spring_stiffness>
        </dynamics>
        <xyz>0 0 1</xyz>
        <use_parent_model_frame>1</use_parent_model_frame>
        <limit>
          <lower>-1e+16</lower>
          <upper>1e+16</upper>
        </limit>
      </axis>
    </joint>
    <joint name='l_finger_middle_link_median_bar_link_3_couple' type='revolute'>
      <parent>l_finger_middle_link_3</parent>
      <child>l_finger_middle_link_median_bar</child>
      <pose>0.0381 0 0 0 -0 0</pose>
      <axis>
        <dynamics>
          <damping>0</damping>
          <friction>0</friction>
          <spring_reference>0</spring_reference>
          <spring_stiffness>0</spring_stiffness>
        </dynamics>
        <xyz>0 0 1</xyz>
        <use_parent_model_frame>1</use_parent_model_frame>
        <limit>
          <lower>-1e+16</lower>
          <upper>1e+16</upper>
        </limit>
      </axis>
    </joint>
    <joint name='l_finger_middle_link_paramedian_bar_paradistal_hinge_couple' type='revolute'>
      <parent>l_finger_middle_link_paradistal_hinge</parent>
      <child>l_finger_middle_link_median_bar_underactuated</child>
      <pose>0.0381 0 0 0 -0 0</pose>
      <axis>
        <dynamics>
          <damping>0</damping>
          <friction>0</friction>
          <spring_reference>0</spring_reference>
          <spring_stiffness>0</spring_stiffness>
        </dynamics>
        <xyz>0 0 1</xyz>
        <use_parent_model_frame>1</use_parent_model_frame>
        <limit>
          <lower>-1e+16</lower>
          <upper>1e+16</upper>
        </limit>
      </axis>
    </joint>
    <joint name='l_finger_middle_link_paradistal_hinge_link_3_couple' type='revolute'>
      <parent>l_finger_middle_link_paradistal_hinge</parent>
      <child>l_finger_middle_link_3</child>
      <pose>0.0381 0 0 0 -0 0</pose>
      <axis>
        <dynamics>
          <damping>0</damping>
          <friction>0</friction>
          <spring_reference>0</spring_reference>
          <spring_stiffness>0</spring_stiffness>
        </dynamics>
        <xyz>0 0 1</xyz>
        <use_parent_model_frame>1</use_parent_model_frame>
        <limit>
          <lower>-1e+16</lower>
          <upper>1e+16</upper>
        </limit>
      </axis>
    </joint>
    <static>0</static>
    <joint name='l_finger_middle_link_paraproximal_bar_paramedian_hinge_couple' type='revolute'>
      <parent>l_finger_middle_link_paramedian_hinge</parent>
      <child>l_finger_middle_link_paraproximal_bar</child>
      <pose>0.0577 0 0 0 -0 0</pose>
      <axis>
        <dynamics>
          <damping>0</damping>
          <friction>0</friction>
          <spring_reference>0</spring_reference>
          <spring_stiffness>0</spring_stiffness>
        </dynamics>
        <xyz>0 0 1</xyz>
        <use_parent_model_frame>1</use_parent_model_frame>
        <limit>
          <lower>-1e+16</lower>
          <upper>1e+16</upper>
        </limit>
      </axis>
    </joint>
  </model>
</sdf>
