<sdf version='1.5'>
  <model name='full_lwr'>
    <link name='lwr_base_link'>
      <pose>0 0 0 0 -0 0</pose>
      <inertial>
        <pose>0 0 0.055 0 -0 0</pose>
        <mass>2</mass>
        <inertia>
          <ixx>0.00381667</ixx>
          <ixy>0</ixy>
          <ixz>0</ixz>
          <iyy>0.0036</iyy>
          <iyz>0</iyz>
          <izz>0.00381667</izz>
        </inertia>
      </inertial>
      <collision name='lwr_base_link_collision'>
        <pose>0 0 0.055 0 -0 -3.14159</pose>
        <geometry>
          <cylinder>
            <length>0.11</length>
            <radius>0.07</radius>
          </cylinder>
        </geometry>
        <surface>
          <contact>
            <ode/>
          </contact>
          <friction>
            <ode/>
          </friction>
        </surface>
      </collision>
      <visual name='lwr_base_link_visual'>
        <pose>0 0 0 0 -0 -3.14159</pose>
        <geometry>
          <mesh>
            <scale>1 1 1</scale>
            <uri>model://lwr_description/meshes/base.STL</uri>
          </mesh>
        </geometry>
        <material>
          <script>
            <name>Gazebo/Orange</name>
            <uri>__default__</uri>
          </script>
        </material>
      </visual>
      <gravity>1</gravity>
      <velocity_decay/>
      <self_collide>0</self_collide>
      <gravity>1</gravity>
    </link>
    <joint name='world_lwr_base_joint' type='revolute'>
      <child>lwr_base_link</child>
      <parent>world</parent>
      <axis>
        <limit>
          <lower>0</lower>
          <upper>0</upper>
        </limit>
        <dynamics>
          <damping>0</damping>
          <friction>0</friction>
          <spring_reference>0</spring_reference>
          <spring_stiffness>0</spring_stiffness>
        </dynamics>
        <use_parent_model_frame>1</use_parent_model_frame>
        <xyz>0 0 1</xyz>
      </axis>
    </joint>
    <link name='lwr_1_link'>
      <pose>0 0 0.11 0 -0 0</pose>
      <inertial>
        <pose>0 -0.06 0.13 0 -0 0</pose>
        <mass>2</mass>
        <inertia>
          <ixx>0.0136667</ixx>
          <ixy>0</ixy>
          <ixz>0</ixz>
          <iyy>0.003</iyy>
          <iyz>0</iyz>
          <izz>0.0118667</izz>
        </inertia>
      </inertial>
      <collision name='lwr_1_link_collision'>
        <pose>0 0 0 0 -0 0</pose>
        <geometry>
          <sphere>
            <radius>0.07</radius>
          </sphere>
        </geometry>
        <surface>
          <contact>
            <ode/>
          </contact>
          <friction>
            <ode/>
          </friction>
        </surface>
      </collision>
      <collision name='lwr_1_link_collision_lwr_1_link_1'>
        <pose>0 0.06 0.2 0 -0 0</pose>
        <geometry>
          <sphere>
            <radius>0.07</radius>
          </sphere>
        </geometry>
        <surface>
          <contact>
            <ode/>
          </contact>
          <friction>
            <ode/>
          </friction>
        </surface>
      </collision>
      <collision name='lwr_1_link_collision_lwr_1_link_2'>
        <pose>0 0.03 0.1 -0.291 0 0</pose>
        <geometry>
          <cylinder>
            <length>0.208</length>
            <radius>0.07</radius>
          </cylinder>
        </geometry>
        <surface>
          <contact>
            <ode/>
          </contact>
          <friction>
            <ode/>
          </friction>
        </surface>
      </collision>
      <visual name='lwr_1_link_visual'>
        <pose>0 0 -0.008 0 -0 -3.14159</pose>
        <geometry>
          <mesh>
            <scale>1 1 1</scale>
            <uri>model://lwr_description/meshes/link_1.STL</uri>
          </mesh>
        </geometry>
        <material>
          <script>
            <name>Gazebo/Orange</name>
            <uri>__default__</uri>
          </script>
        </material>
      </visual>
      <gravity>1</gravity>
      <velocity_decay/>
      <self_collide>0</self_collide>
      <gravity>1</gravity>
    </link>
    <joint name='lwr_0_joint' type='revolute'>
      <child>lwr_1_link</child>
      <parent>lwr_base_link</parent>
      <axis>
        <xyz>0 0 1</xyz>
        <limit>
          <lower>-2.96706</lower>
          <upper>2.96706</upper>
          <effort>176</effort>
          <velocity>1.91986</velocity>
        </limit>
        <dynamics>
          <damping>1</damping>
          <friction>10</friction>
          <spring_reference>0</spring_reference>
          <spring_stiffness>0</spring_stiffness>
        </dynamics>
        <use_parent_model_frame>1</use_parent_model_frame>
      </axis>
    </joint>
    <link name='lwr_2_link'>
      <pose>0 0 0.3105 0 -0 0</pose>
      <inertial>
        <pose>0 0.06 0.07 0 -0 0</pose>
        <mass>2</mass>
        <inertia>
          <ixx>0.0136667</ixx>
          <ixy>0</ixy>
          <ixz>0</ixz>
          <iyy>0.003</iyy>
          <iyz>0</iyz>
          <izz>0.0118667</izz>
        </inertia>
      </inertial>
      <collision name='lwr_2_link_collision'>
        <pose>0 0 0.2 0 -0 0</pose>
        <geometry>
          <sphere>
            <radius>0.07</radius>
          </sphere>
        </geometry>
        <surface>
          <contact>
            <ode/>
          </contact>
          <friction>
            <ode/>
          </friction>
        </surface>
      </collision>
      <collision name='lwr_2_link_collision_lwr_2_link_1'>
        <pose>0 -0.06 0 0 -0 0</pose>
        <geometry>
          <sphere>
            <radius>0.07</radius>
          </sphere>
        </geometry>
        <surface>
          <contact>
            <ode/>
          </contact>
          <friction>
            <ode/>
          </friction>
        </surface>
      </collision>
      <collision name='lwr_2_link_collision_lwr_2_link_2'>
        <pose>0 -0.03 0.1 -0.291 0 0</pose>
        <geometry>
          <cylinder>
            <length>0.208</length>
            <radius>0.07</radius>
          </cylinder>
        </geometry>
        <surface>
          <contact>
            <ode/>
          </contact>
          <friction>
            <ode/>
          </friction>
        </surface>
      </collision>
      <visual name='lwr_2_link_visual'>
        <pose>0 0 0 0 -0 -3.14159</pose>
        <geometry>
          <mesh>
            <scale>1 1 1</scale>
            <uri>model://lwr_description/meshes/link_2.STL</uri>
          </mesh>
        </geometry>
        <material>
          <script>
            <name>Gazebo/Orange</name>
            <uri>__default__</uri>
          </script>
        </material>
      </visual>
      <gravity>1</gravity>
      <velocity_decay/>
      <self_collide>0</self_collide>
      <gravity>1</gravity>
    </link>
    <joint name='lwr_1_joint' type='revolute'>
      <child>lwr_2_link</child>
      <parent>lwr_1_link</parent>
      <axis>
        <xyz>0 -1 0</xyz>
        <limit>
          <lower>-2.0944</lower>
          <upper>2.0944</upper>
          <effort>176</effort>
          <velocity>1.91986</velocity>
        </limit>
        <dynamics>
          <damping>1</damping>
          <friction>10</friction>
          <spring_reference>0</spring_reference>
          <spring_stiffness>0</spring_stiffness>
        </dynamics>
        <use_parent_model_frame>1</use_parent_model_frame>
      </axis>
    </joint>
    <link name='lwr_3_link'>
      <pose>0 0 0.5105 0 -0 0</pose>
      <inertial>
        <pose>0 0.06 0.13 0 -0 0</pose>
        <mass>2</mass>
        <inertia>
          <ixx>0.0136667</ixx>
          <ixy>0</ixy>
          <ixz>0</ixz>
          <iyy>0.003</iyy>
          <iyz>0</iyz>
          <izz>0.0118667</izz>
        </inertia>
      </inertial>
      <collision name='lwr_3_link_collision'>
        <pose>0 0 0 0 -0 0</pose>
        <geometry>
          <sphere>
            <radius>0.07</radius>
          </sphere>
        </geometry>
        <surface>
          <contact>
            <ode/>
          </contact>
          <friction>
            <ode/>
          </friction>
        </surface>
      </collision>
      <collision name='lwr_3_link_collision_lwr_3_link_1'>
        <pose>0 -0.06 0.2 0 -0 0</pose>
        <geometry>
          <sphere>
            <radius>0.07</radius>
          </sphere>
        </geometry>
        <surface>
          <contact>
            <ode/>
          </contact>
          <friction>
            <ode/>
          </friction>
        </surface>
      </collision>
      <collision name='lwr_3_link_collision_lwr_3_link_2'>
        <pose>0 -0.03 0.1 0.291 -0 0</pose>
        <geometry>
          <cylinder>
            <length>0.208</length>
            <radius>0.07</radius>
          </cylinder>
        </geometry>
        <surface>
          <contact>
            <ode/>
          </contact>
          <friction>
            <ode/>
          </friction>
        </surface>
      </collision>
      <visual name='lwr_3_link_visual'>
        <pose>0 0 -0.008 0 -0 -3.14159</pose>
        <geometry>
          <mesh>
            <scale>1 1 1</scale>
            <uri>model://lwr_description/meshes/link_3.STL</uri>
          </mesh>
        </geometry>
        <material>
          <script>
            <name>Gazebo/Orange</name>
            <uri>__default__</uri>
          </script>
        </material>
      </visual>
      <gravity>1</gravity>
      <velocity_decay/>
      <self_collide>0</self_collide>
      <gravity>1</gravity>
    </link>
    <joint name='lwr_2_joint' type='revolute'>
      <child>lwr_3_link</child>
      <parent>lwr_2_link</parent>
      <axis>
        <xyz>0 0 1</xyz>
        <limit>
          <lower>-2.96706</lower>
          <upper>2.96706</upper>
          <effort>100</effort>
          <velocity>2.23402</velocity>
        </limit>
        <dynamics>
          <damping>1</damping>
          <friction>10</friction>
          <spring_reference>0</spring_reference>
          <spring_stiffness>0</spring_stiffness>
        </dynamics>
        <use_parent_model_frame>1</use_parent_model_frame>
      </axis>
    </joint>
    <link name='lwr_4_link'>
      <pose>0 0 0.7105 0 -0 0</pose>
      <inertial>
        <pose>0 -0.06 0.07 0 -0 0</pose>
        <mass>2</mass>
        <inertia>
          <ixx>0.0136667</ixx>
          <ixy>0</ixy>
          <ixz>0</ixz>
          <iyy>0.003</iyy>
          <iyz>0</iyz>
          <izz>0.0118667</izz>
        </inertia>
      </inertial>
      <collision name='lwr_4_link_collision'>
        <pose>0 0 0.2 0 -0 0</pose>
        <geometry>
          <sphere>
            <radius>0.07</radius>
          </sphere>
        </geometry>
        <surface>
          <contact>
            <ode/>
          </contact>
          <friction>
            <ode/>
          </friction>
        </surface>
      </collision>
      <collision name='lwr_4_link_collision_lwr_4_link_1'>
        <pose>0 0.06 0 0 -0 0</pose>
        <geometry>
          <sphere>
            <radius>0.07</radius>
          </sphere>
        </geometry>
        <surface>
          <contact>
            <ode/>
          </contact>
          <friction>
            <ode/>
          </friction>
        </surface>
      </collision>
      <collision name='lwr_4_link_collision_lwr_4_link_2'>
        <pose>0 0.03 0.1 0.291 -0 0</pose>
        <geometry>
          <cylinder>
            <length>0.208</length>
            <radius>0.07</radius>
          </cylinder>
        </geometry>
        <surface>
          <contact>
            <ode/>
          </contact>
          <friction>
            <ode/>
          </friction>
        </surface>
      </collision>
      <visual name='lwr_4_link_visual'>
        <pose>0 0 0 0 -0 -3.14159</pose>
        <geometry>
          <mesh>
            <scale>1 1 1</scale>
            <uri>model://lwr_description/meshes/link_4.STL</uri>
          </mesh>
        </geometry>
        <material>
          <script>
            <name>Gazebo/Orange</name>
            <uri>__default__</uri>
          </script>
        </material>
      </visual>
      <gravity>1</gravity>
      <velocity_decay/>
      <self_collide>0</self_collide>
      <gravity>1</gravity>
    </link>
    <joint name='lwr_3_joint' type='revolute'>
      <child>lwr_4_link</child>
      <parent>lwr_3_link</parent>
      <axis>
        <xyz>0 1 0</xyz>
        <limit>
          <lower>-2.0944</lower>
          <upper>2.0944</upper>
          <effort>100</effort>
          <velocity>2.23402</velocity>
        </limit>
        <dynamics>
          <damping>1</damping>
          <friction>10</friction>
          <spring_reference>0</spring_reference>
          <spring_stiffness>0</spring_stiffness>
        </dynamics>
        <use_parent_model_frame>1</use_parent_model_frame>
      </axis>
    </joint>
    <link name='lwr_5_link'>
      <pose>0 0 0.9105 0 -0 0</pose>
      <inertial>
        <pose>0 0 0.124 0 -0 0</pose>
        <mass>2</mass>
        <inertia>
          <ixx>0.0126507</ixx>
          <ixy>0</ixy>
          <ixz>0</ixz>
          <iyy>0.003</iyy>
          <iyz>0</iyz>
          <izz>0.0108507</izz>
        </inertia>
      </inertial>
      <collision name='lwr_5_link_collision'>
        <pose>0 0 0 0 -0 0</pose>
        <geometry>
          <sphere>
            <radius>0.07</radius>
          </sphere>
        </geometry>
        <surface>
          <contact>
            <ode/>
          </contact>
          <friction>
            <ode/>
          </friction>
        </surface>
      </collision>
      <collision name='lwr_5_link_collision_lwr_5_link_1'>
        <pose>0 0.04 0.19 0 -0 0</pose>
        <geometry>
          <sphere>
            <radius>0.07</radius>
          </sphere>
        </geometry>
        <surface>
          <contact>
            <ode/>
          </contact>
          <friction>
            <ode/>
          </friction>
        </surface>
      </collision>
      <collision name='lwr_5_link_collision_lwr_5_link_2'>
        <pose>0 0.02 0.095 -0.207 0 0</pose>
        <geometry>
          <cylinder>
            <length>0.198</length>
            <radius>0.07</radius>
          </cylinder>
        </geometry>
        <surface>
          <contact>
            <ode/>
          </contact>
          <friction>
            <ode/>
          </friction>
        </surface>
      </collision>
      <visual name='lwr_5_link_visual'>
        <pose>0 0 -0.008 0 -0 -3.14159</pose>
        <geometry>
          <mesh>
            <scale>1 1 1</scale>
            <uri>model://lwr_description/meshes/link_5.STL</uri>
          </mesh>
        </geometry>
        <material>
          <script>
            <name>Gazebo/Orange</name>
            <uri>__default__</uri>
          </script>
        </material>
      </visual>
      <gravity>1</gravity>
      <velocity_decay/>
      <self_collide>0</self_collide>
      <gravity>1</gravity>
    </link>
    <joint name='lwr_4_joint' type='revolute'>
      <child>lwr_5_link</child>
      <parent>lwr_4_link</parent>
      <axis>
        <xyz>0 0 1</xyz>
        <limit>
          <lower>-2.96706</lower>
          <upper>2.96706</upper>
          <effort>100</effort>
          <velocity>3.56047</velocity>
        </limit>
        <dynamics>
          <damping>1</damping>
          <friction>10</friction>
          <spring_reference>0</spring_reference>
          <spring_stiffness>0</spring_stiffness>
        </dynamics>
        <use_parent_model_frame>1</use_parent_model_frame>
      </axis>
    </joint>
    <link name='lwr_6_link'>
      <pose>0 0 1.1005 0 -0 0</pose>
      <inertial>
        <pose>0 0 0.0625 0 -0 0</pose>
        <mass>0.2</mass>
        <inertia>
          <ixx>0.000520833</ixx>
          <ixy>0</ixy>
          <ixz>0</ixz>
          <iyy>0.000520833</iyy>
          <iyz>0</iyz>
          <izz>0.000520833</izz>
        </inertia>
      </inertial>
      <collision name='lwr_6_link_collision'>
        <pose>0 0 0 0 -0 -3.14159</pose>
        <geometry>
          <mesh>
            <scale>1 1 1</scale>
            <uri>model://lwr_description/meshes/convex/arm_wrist_convex.stl</uri>
          </mesh>
        </geometry>
        <surface>
          <contact>
            <ode/>
          </contact>
          <friction>
            <ode/>
          </friction>
        </surface>
      </collision>
      <visual name='lwr_6_link_visual'>
        <pose>0 0 0 0 -0 -3.14159</pose>
        <geometry>
          <mesh>
            <scale>1 1 1</scale>
            <uri>model://lwr_description/meshes/link_6.STL</uri>
          </mesh>
        </geometry>
        <material>
          <script>
            <name>Gazebo/Orange</name>
            <uri>__default__</uri>
          </script>
        </material>
      </visual>
      <gravity>1</gravity>
      <velocity_decay/>
      <self_collide>0</self_collide>
      <gravity>1</gravity>
    </link>
    <joint name='lwr_5_joint' type='revolute'>
      <child>lwr_6_link</child>
      <parent>lwr_5_link</parent>
      <axis>
        <xyz>0 -1 0</xyz>
        <limit>
          <lower>-2.0944</lower>
          <upper>2.0944</upper>
          <effort>38</effort>
          <velocity>3.21141</velocity>
        </limit>
        <dynamics>
          <damping>1</damping>
          <friction>10</friction>
          <spring_reference>0</spring_reference>
          <spring_stiffness>0</spring_stiffness>
        </dynamics>
        <use_parent_model_frame>1</use_parent_model_frame>
      </axis>
    </joint>
    <link name='lwr_7_link'>
      <pose>0 0 1.1785 0 -0 0</pose>
      <inertial>
        <pose>0 0 0.0385667 0 -0 0</pose>
        <mass>1.5</mass>
        <inertia>
          <ixx>0.0371766</ixx>
          <ixy>0</ixy>
          <ixz>0</ixz>
          <iyy>0.0371766</iyy>
          <iyz>-1.29247e-26</iyz>
          <izz>0.0368333</izz>
        </inertia>
      </inertial>
      <collision name='lwr_7_link_collision'>
        <pose>0 0 0 0 -0 -3.14159</pose>
        <geometry>
          <cylinder>
            <length>0.05</length>
            <radius>0.04</radius>
          </cylinder>
        </geometry>
        <surface>
          <contact>
            <ode/>
          </contact>
          <friction>
            <ode/>
          </friction>
        </surface>
      </collision>
      <collision name='lwr_7_link_collision_lwr_7_link_1'>
        <pose>0 0 0.0445 1.5708 -0 0</pose>
        <geometry>
          <box>
            <size>0.1 0.1 0.1</size>
          </box>
        </geometry>
        <surface>
          <contact>
            <ode/>
          </contact>
          <friction>
            <ode/>
          </friction>
        </surface>
      </collision>
      <visual name='lwr_7_link_visual'>
        <pose>0 0 0 0 -0 -3.14159</pose>
        <geometry>
          <mesh>
            <scale>1 1 1</scale>
            <uri>model://lwr_description/meshes/link_7.STL</uri>
          </mesh>
        </geometry>
        <material>
          <script>
            <name>Gazebo/Grey</name>
            <uri>__default__</uri>
          </script>
        </material>
      </visual>
      <visual name='lwr_7_link_visual_lwr_7_link_1'>
        <pose>0 0 0.0445 1.5708 -0 0</pose>
        <geometry>
          <mesh>
            <scale>1 1 1</scale>
            <uri>model://robotiq_s_model_visualization/meshes/s-model_articulated/visual/palm.STL</uri>
          </mesh>
        </geometry>
        <material>
          <script>
            <name>Gazebo/Grey</name>
            <uri>__default__</uri>
          </script>
        </material>
      </visual>
      <velocity_decay/>
      <gravity>1</gravity>
      <gravity>1</gravity>
      <velocity_decay/>
      <self_collide>0</self_collide>
    </link>
    <joint name='lwr_6_joint' type='revolute'>
      <child>lwr_7_link</child>
      <parent>lwr_6_link</parent>
      <axis>
        <xyz>0 0 1</xyz>
        <limit>
          <lower>-2.96706</lower>
          <upper>2.96706</upper>
          <effort>38</effort>
          <velocity>3.21141</velocity>
        </limit>
        <dynamics>
          <damping>1</damping>
          <friction>10</friction>
          <spring_reference>0</spring_reference>
          <spring_stiffness>0</spring_stiffness>
        </dynamics>
        <use_parent_model_frame>1</use_parent_model_frame>
      </axis>
    </joint>
    <link name='l_finger_1_link_0'>
      <pose>-0.0455 -0.036 1.2444 1.5616 -1.57 -3.1324</pose>
      <inertial>
        <pose>-0.01 0 0 0 -0 0</pose>
        <mass>0.1</mass>
        <inertia>
          <ixx>1.8e-05</ixx>
          <ixy>0</ixy>
          <ixz>0</ixz>
          <iyy>2.5e-05</iyy>
          <iyz>0</iyz>
          <izz>2.5e-05</izz>
        </inertia>
      </inertial>
      <collision name='l_finger_1_link_0_collision'>
        <pose>0 0 0 -3.14159 5.35898e-08 1.5708</pose>
        <geometry>
          <mesh>
            <scale>1 1 1</scale>
            <uri>model://robotiq_s_model_visualization/meshes/s-model_articulated/collision/link_0.STL</uri>
          </mesh>
        </geometry>
        <surface>
          <contact>
            <ode/>
          </contact>
          <friction>
            <ode>
              <mu>1.1</mu>
              <mu2>1.1</mu2>
            </ode>
          </friction>
        </surface>
      </collision>
      <visual name='l_finger_1_link_0_visual'>
        <pose>0.02 0 0 0 -0 0</pose>
        <geometry>
          <mesh>
            <scale>1 1 1</scale>
            <uri>model://robotiq_s_model_visualization/meshes/s-model_articulated/visual/link_0.STL</uri>
          </mesh>
        </geometry>
      </visual>
      <gravity>1</gravity>
      <velocity_decay/>
      <self_collide>0</self_collide>
    </link>
    <joint name='l_palm_finger_1_joint' type='revolute'>
      <child>l_finger_1_link_0</child>
      <parent>lwr_7_link</parent>
      <axis>
        <xyz>1 2.13376e-11 0.000796327</xyz>
        <limit>
          <lower>-0.2967</lower>
          <upper>0.2967</upper>
          <effort>60</effort>
          <velocity>-1</velocity>
        </limit>
        <dynamics>
          <damping>1</damping>
          <friction>0</friction>
          <spring_reference>0</spring_reference>
          <spring_stiffness>0</spring_stiffness>
        </dynamics>
        <use_parent_model_frame>1</use_parent_model_frame>
      </axis>
      <physics>
        <ode>
          <implicit_spring_damper>1</implicit_spring_damper>
          <cfm_damping>1</cfm_damping>
          <limit>
            <cfm>0</cfm>
            <erp>0.2</erp>
          </limit>
        </ode>
      </physics>
    </joint>
    <link name='l_finger_1_link_1'>
      <pose>-0.0455 -0.036 1.2444 1.57079 0.5206 3.14159</pose>
      <inertial>
        <pose>0.00053 0.03218 0 0 -0 1.5708</pose>
        <mass>0.047</mass>
        <inertia>
          <ixx>4.99332e-06</ixx>
          <ixy>9.1312e-07</ixy>
          <ixz>-1.2e-09</ixz>
          <iyy>6.43453e-05</iyy>
          <iyz>-7e-11</iyz>
          <izz>6.06192e-05</izz>
        </inertia>
      </inertial>
      <collision name='l_finger_1_link_1_collision'>
        <pose>0 0.05717 0 0 -0 1.5708</pose>
        <geometry>
          <mesh>
            <scale>1 1 1</scale>
            <uri>model://robotiq_s_model_visualization/meshes/s-model_articulated/collision/link_1.STL</uri>
          </mesh>
        </geometry>
        <surface>
          <contact>
            <ode/>
          </contact>
          <friction>
            <ode>
              <mu>1.1</mu>
              <mu2>1.1</mu2>
            </ode>
          </friction>
        </surface>
      </collision>
      <visual name='l_finger_1_link_1_visual'>
        <pose>0 0.05717 0 0 -0 1.5708</pose>
        <geometry>
          <mesh>
            <scale>1 1 1</scale>
            <uri>model://robotiq_s_model_visualization/meshes/s-model_articulated/visual/link_1.STL</uri>
          </mesh>
        </geometry>
      </visual>
      <gravity>1</gravity>
      <velocity_decay/>
      <self_collide>0</self_collide>
    </link>
    <joint name='l_finger_1_joint_1' type='revolute'>
      <child>l_finger_1_link_1</child>
      <parent>l_finger_1_link_0</parent>
      <axis>
        <xyz>-5.85014e-09 1 7.31961e-06</xyz>
        <limit>
          <lower>0</lower>
          <upper>1.2217</upper>
          <effort>60</effort>
          <velocity>-1</velocity>
        </limit>
        <dynamics>
          <damping>1</damping>
          <friction>0</friction>
          <spring_reference>0</spring_reference>
          <spring_stiffness>0</spring_stiffness>
        </dynamics>
        <use_parent_model_frame>1</use_parent_model_frame>
      </axis>
      <physics>
        <ode>
          <implicit_spring_damper>1</implicit_spring_damper>
          <cfm_damping>1</cfm_damping>
          <limit>
            <cfm>0</cfm>
            <erp>0.2</erp>
          </limit>
        </ode>
      </physics>
    </joint>
    <link name='l_finger_1_link_2'>
      <pose>-0.0739265 -0.0360004 1.29398 1.57079 0.5206 3.14159</pose>
      <inertial>
        <pose>0.00048 0.02167 0.00018 0 -0 1.5708</pose>
        <mass>0.03284</mass>
        <inertia>
          <ixx>3.48008e-06</ixx>
          <ixy>3.194e-07</ixy>
          <ixz>1.3041e-07</ixz>
          <iyy>2.24812e-05</iyy>
          <iyz>2.91e-09</iyz>
          <izz>1.98635e-05</izz>
        </inertia>
      </inertial>
      <collision name='l_finger_1_link_2_collision'>
        <pose>0 0.0381 0.0075 0 -0 1.5708</pose>
        <geometry>
          <mesh>
            <scale>1 1 1</scale>
            <uri>model://robotiq_s_model_visualization/meshes/s-model_articulated/collision/link_2.STL</uri>
          </mesh>
        </geometry>
        <surface>
          <contact>
            <ode/>
          </contact>
          <friction>
            <ode>
              <mu>1.1</mu>
              <mu2>1.1</mu2>
            </ode>
          </friction>
        </surface>
      </collision>
      <visual name='l_finger_1_link_2_visual'>
        <pose>0 0.0381 0.0075 0 -0 1.5708</pose>
        <geometry>
          <mesh>
            <scale>1 1 1</scale>
            <uri>model://robotiq_s_model_visualization/meshes/s-model_articulated/visual/link_2.STL</uri>
          </mesh>
        </geometry>
      </visual>
      <gravity>1</gravity>
      <velocity_decay/>
      <self_collide>0</self_collide>
    </link>
    <joint name='l_finger_1_joint_2' type='revolute'>
      <child>l_finger_1_link_2</child>
      <parent>l_finger_1_link_1</parent>
      <axis>
        <xyz>-5.85014e-09 1 7.31961e-06</xyz>
        <limit>
          <lower>0</lower>
          <upper>1.5708</upper>
          <effort>60</effort>
          <velocity>-1</velocity>
        </limit>
        <dynamics>
          <damping>1</damping>
          <friction>0</friction>
          <spring_reference>0</spring_reference>
          <spring_stiffness>0</spring_stiffness>
        </dynamics>
        <use_parent_model_frame>1</use_parent_model_frame>
      </axis>
      <physics>
        <ode>
          <implicit_spring_damper>1</implicit_spring_damper>
          <cfm_damping>1</cfm_damping>
          <limit>
            <cfm>0</cfm>
            <erp>0.2</erp>
          </limit>
        </ode>
      </physics>
    </joint>
    <link name='l_finger_1_link_3'>
      <pose>-0.0933251 -0.0360006 1.32781 1.5616 -1.57 -3.1324</pose>
      <inertial>
        <pose>0.01626 0.00049 0.0002 0 -0 0</pose>
        <mass>0.03354</mass>
        <inertia>
          <ixx>3.05151e-06</ixx>
          <ixy>8.9792e-07</ixy>
          <ixz>2.49e-09</ixz>
          <iyy>1.42798e-05</iyy>
          <iyz>-1.191e-08</iyz>
          <izz>1.26413e-05</izz>
        </inertia>
      </inertial>
      <collision name='l_finger_1_link_3_collision'>
        <pose>0 0 0 0 -0 0</pose>
        <geometry>
          <mesh>
            <scale>1 1 1</scale>
            <uri>model://robotiq_s_model_visualization/meshes/s-model_articulated/collision/link_3.STL</uri>
          </mesh>
        </geometry>
        <surface>
          <contact>
            <ode>
              <kp>10000</kp>
              <kd>1</kd>
            </ode>
          </contact>
          <friction>
            <ode>
              <mu>1000</mu>
              <mu2>1000</mu2>
            </ode>
          </friction>
        </surface>
      </collision>
      <visual name='l_finger_1_link_3_visual'>
        <pose>0 0 0 0 -0 0</pose>
        <geometry>
          <mesh>
            <scale>1 1 1</scale>
            <uri>model://robotiq_s_model_visualization/meshes/s-model_articulated/visual/link_3.STL</uri>
          </mesh>
        </geometry>
      </visual>
      <gravity>1</gravity>
      <velocity_decay/>
      <self_collide>0</self_collide>
    </link>
    <joint name='l_finger_1_joint_3' type='revolute'>
      <child>l_finger_1_link_3</child>
      <parent>l_finger_1_link_2</parent>
      <axis>
        <xyz>-5.85014e-09 1 7.31961e-06</xyz>
        <limit>
          <lower>-0.6632</lower>
          <upper>1.0471</upper>
          <effort>60</effort>
          <velocity>-1</velocity>
        </limit>
        <dynamics>
          <damping>1</damping>
          <friction>0</friction>
          <spring_reference>0</spring_reference>
          <spring_stiffness>0</spring_stiffness>
        </dynamics>
        <use_parent_model_frame>1</use_parent_model_frame>
      </axis>
      <physics>
        <ode>
          <implicit_spring_damper>1</implicit_spring_damper>
          <cfm_damping>1</cfm_damping>
          <limit>
            <cfm>0</cfm>
            <erp>0.2</erp>
          </limit>
        </ode>
      </physics>
    </joint>
    <link name='l_finger_1_link_paradistal_hinge'>
      <pose>-0.0933251 -0.0460006 1.32781 1.57079 0.5206 3.14159</pose>
      <inertial>
        <pose>0.00548 0 0 0 -0 0</pose>
        <mass>0.00158</mass>
        <inertia>
          <ixx>1.907e-08</ixx>
          <ixy>0</ixy>
          <ixz>0</ixz>
          <iyy>1.097e-07</iyy>
          <iyz>0</iyz>
          <izz>1.261e-07</izz>
        </inertia>
      </inertial>
      <collision name='l_finger_1_link_paradistal_hinge_collision'>
        <pose>0 0 0 0 -0 0</pose>
        <geometry>
          <box>
            <size>0.02 0.02 0.002</size>
          </box>
        </geometry>
        <surface>
          <contact>
            <ode/>
          </contact>
          <friction>
            <ode>
              <mu>1.1</mu>
              <mu2>1.1</mu2>
            </ode>
          </friction>
        </surface>
      </collision>
      <visual name='l_finger_1_link_paradistal_hinge_visual'>
        <pose>0 0 0 0 -0 0</pose>
        <geometry>
          <box>
            <size>0.02 0.02 0.002</size>
          </box>
        </geometry>
      </visual>
      <gravity>1</gravity>
      <velocity_decay/>
      <self_collide>0</self_collide>
    </link>
    <joint name='l_finger_1_joint_paradistal_hinge' type='revolute'>
      <child>l_finger_1_link_paradistal_hinge</child>
      <parent>l_finger_1_link_2</parent>
      <axis>
        <xyz>-5.85014e-09 1 7.31961e-06</xyz>
        <limit>
          <lower>-3.1416</lower>
          <upper>3.1416</upper>
          <effort>100</effort>
          <velocity>100</velocity>
        </limit>
        <dynamics>
          <spring_reference>0</spring_reference>
          <spring_stiffness>0</spring_stiffness>
        </dynamics>
        <use_parent_model_frame>1</use_parent_model_frame>
      </axis>
      <physics>
        <ode>
          <implicit_spring_damper>1</implicit_spring_damper>
          <cfm_damping>1</cfm_damping>
          <limit>
            <cfm>0</cfm>
            <erp>0.2</erp>
          </limit>
        </ode>
      </physics>
    </joint>
    <link name='l_finger_1_link_median_actuating_hinge'>
      <pose>-0.0739265 -0.0260004 1.29398 1.57078 0.8906 3.14158</pose>
      <inertial>
        <pose>0.0092 0.00514 0 0 -0 0</pose>
        <mass>0.00359</mass>
        <inertia>
          <ixx>2.4735e-07</ixx>
          <ixy>2.3619e-07</ixy>
          <ixz>0</ixz>
          <iyy>4.7681e-07</iyy>
          <iyz>0</iyz>
          <izz>7.1813e-07</izz>
        </inertia>
      </inertial>
      <collision name='l_finger_1_link_median_actuating_hinge_collision'>
        <pose>0 0 0 0 -0 0</pose>
        <geometry>
          <box>
            <size>0.02 0.02 0.002</size>
          </box>
        </geometry>
        <surface>
          <contact>
            <ode/>
          </contact>
          <friction>
            <ode>
              <mu>1.1</mu>
              <mu2>1.1</mu2>
            </ode>
          </friction>
        </surface>
      </collision>
      <visual name='l_finger_1_link_median_actuating_hinge_visual'>
        <pose>0 0 0 0 -0 0</pose>
        <geometry>
          <box>
            <size>0.02 0.02 0.002</size>
          </box>
        </geometry>
      </visual>
      <gravity>1</gravity>
      <velocity_decay/>
      <self_collide>0</self_collide>
    </link>
    <joint name='l_finger_1_joint_median_actuating_hinge' type='revolute'>
      <child>l_finger_1_link_median_actuating_hinge</child>
      <parent>l_finger_1_link_1</parent>
      <axis>
        <xyz>-5.85014e-09 1 7.31961e-06</xyz>
        <limit>
          <lower>-3.1416</lower>
          <upper>3.1416</upper>
          <effort>100</effort>
          <velocity>100</velocity>
        </limit>
        <dynamics>
          <spring_reference>0</spring_reference>
          <spring_stiffness>0</spring_stiffness>
        </dynamics>
        <use_parent_model_frame>1</use_parent_model_frame>
      </axis>
      <physics>
        <ode>
          <implicit_spring_damper>1</implicit_spring_damper>
          <cfm_damping>1</cfm_damping>
          <limit>
            <cfm>0</cfm>
            <erp>0.2</erp>
          </limit>
        </ode>
      </physics>
    </joint>
    <link name='l_finger_1_link_median_bar'>
      <pose>-0.095933 -0.0260003 1.29088 1.57074 -1.4309 -3.14154</pose>
      <inertial>
        <pose>0.01905 -0.00107 0 0 -0 0</pose>
        <mass>0.00538</mass>
        <inertia>
          <ixx>6.639e-08</ixx>
          <ixy>-1.0996e-07</ixy>
          <ixz>9.4e-10</ixz>
          <iyy>3.05318e-06</iyy>
          <iyz>0</iyz>
          <izz>3.04657e-06</izz>
        </inertia>
      </inertial>
      <collision name='l_finger_1_link_median_bar_collision'>
        <pose>0.01905 0 0 0 -0 0</pose>
        <geometry>
          <box>
            <size>0.0381 0.0075 0.002</size>
          </box>
        </geometry>
        <surface>
          <contact>
            <ode/>
          </contact>
          <friction>
            <ode>
              <mu>1.1</mu>
              <mu2>1.1</mu2>
            </ode>
          </friction>
        </surface>
      </collision>
      <visual name='l_finger_1_link_median_bar_visual'>
        <pose>0.01905 0 0 0 -0 0</pose>
        <geometry>
          <box>
            <size>0.0381 0.0075 0.002</size>
          </box>
        </geometry>
      </visual>
      <gravity>1</gravity>
      <velocity_decay/>
      <self_collide>0</self_collide>
    </link>
    <joint name='l_finger_1_joint_median_actuating_hinge_median_bar' type='revolute'>
      <child>l_finger_1_link_median_bar</child>
      <parent>l_finger_1_link_median_actuating_hinge</parent>
      <axis>
        <xyz>-5.85014e-09 1 7.31961e-06</xyz>
        <limit>
          <lower>-3.1416</lower>
          <upper>3.1416</upper>
          <effort>100</effort>
          <velocity>100</velocity>
        </limit>
        <dynamics>
          <spring_reference>0</spring_reference>
          <spring_stiffness>0</spring_stiffness>
        </dynamics>
        <use_parent_model_frame>1</use_parent_model_frame>
      </axis>
      <physics>
        <ode>
          <implicit_spring_damper>1</implicit_spring_damper>
          <cfm_damping>1</cfm_damping>
          <limit>
            <cfm>0</cfm>
            <erp>0.2</erp>
          </limit>
        </ode>
      </physics>
    </joint>
    <link name='l_finger_1_link_paramedian_hinge'>
      <pose>-0.0739265 -0.0460004 1.29398 1.57079 0.5206 3.14159</pose>
      <inertial>
        <pose>-0.01025 0.00046 0 0 -0 0</pose>
        <mass>0.00276</mass>
        <inertia>
          <ixx>4.213e-08</ixx>
          <ixy>-1.491e-08</ixy>
          <ixz>0</ixz>
          <iyy>5.0258e-07</iyy>
          <iyz>0</iyz>
          <izz>5.4007e-07</izz>
        </inertia>
      </inertial>
      <collision name='l_finger_1_link_paramedian_hinge_collision'>
        <pose>0 0 0 0 -0 0</pose>
        <geometry>
          <box>
            <size>0.02 0.02 0.002</size>
          </box>
        </geometry>
        <surface>
          <contact>
            <ode/>
          </contact>
          <friction>
            <ode>
              <mu>1.1</mu>
              <mu2>1.1</mu2>
            </ode>
          </friction>
        </surface>
      </collision>
      <visual name='l_finger_1_link_paramedian_hinge_visual'>
        <pose>0 0 0 0 -0 0</pose>
        <geometry>
          <box>
            <size>0.02 0.02 0.002</size>
          </box>
        </geometry>
      </visual>
      <gravity>1</gravity>
      <velocity_decay/>
      <self_collide>0</self_collide>
    </link>
    <joint name='l_finger_1_joint_paramedian_hinge' type='revolute'>
      <child>l_finger_1_link_paramedian_hinge</child>
      <parent>l_finger_1_link_1</parent>
      <axis>
        <xyz>-5.85014e-09 1 7.31961e-06</xyz>
        <limit>
          <lower>-3.1416</lower>
          <upper>3.1416</upper>
          <effort>100</effort>
          <velocity>100</velocity>
        </limit>
        <dynamics>
          <spring_reference>0</spring_reference>
          <spring_stiffness>0</spring_stiffness>
        </dynamics>
        <use_parent_model_frame>1</use_parent_model_frame>
      </axis>
      <physics>
        <ode>
          <implicit_spring_damper>1</implicit_spring_damper>
          <cfm_damping>1</cfm_damping>
          <limit>
            <cfm>0</cfm>
            <erp>0.2</erp>
          </limit>
        </ode>
      </physics>
    </joint>
    <link name='l_finger_1_link_median_bar_underactuated'>
      <pose>-0.0862074 -0.0460003 1.29073 1.57078 -1.0502 -3.14158</pose>
      <inertial>
        <pose>0.01905 -0.00107 0 0 -0 0</pose>
        <mass>0.00538</mass>
        <inertia>
          <ixx>6.639e-08</ixx>
          <ixy>-1.0996e-07</ixy>
          <ixz>-9.4e-10</ixz>
          <iyy>3.05318e-06</iyy>
          <iyz>0</iyz>
          <izz>3.04657e-06</izz>
        </inertia>
      </inertial>
      <collision name='l_finger_1_link_median_bar_underactuated_collision'>
        <pose>0.01905 0 0 0 -0 0</pose>
        <geometry>
          <box>
            <size>0.0381 0.0075 0.002</size>
          </box>
        </geometry>
        <surface>
          <contact>
            <ode/>
          </contact>
          <friction>
            <ode>
              <mu>1.1</mu>
              <mu2>1.1</mu2>
            </ode>
          </friction>
        </surface>
      </collision>
      <visual name='l_finger_1_link_median_bar_underactuated_visual'>
        <pose>0.01905 0 0 0 -0 0</pose>
        <geometry>
          <box>
            <size>0.0381 0.0075 0.002</size>
          </box>
        </geometry>
      </visual>
      <gravity>1</gravity>
      <velocity_decay/>
      <self_collide>0</self_collide>
    </link>
    <joint name='l_finger_1_joint_paramedian_hinge_median_bar_underactuated' type='revolute'>
      <child>l_finger_1_link_median_bar_underactuated</child>
      <parent>l_finger_1_link_paramedian_hinge</parent>
      <axis>
        <xyz>-5.85014e-09 1 7.31961e-06</xyz>
        <limit>
          <lower>-3.1416</lower>
          <upper>3.1416</upper>
          <effort>100</effort>
          <velocity>100</velocity>
        </limit>
        <dynamics>
          <spring_reference>0</spring_reference>
          <spring_stiffness>0</spring_stiffness>
        </dynamics>
        <use_parent_model_frame>1</use_parent_model_frame>
      </axis>
      <physics>
        <ode>
          <implicit_spring_damper>1</implicit_spring_damper>
          <cfm_damping>1</cfm_damping>
          <limit>
            <cfm>0</cfm>
            <erp>0.2</erp>
          </limit>
        </ode>
      </physics>
    </joint>
    <link name='l_finger_1_link_paraproximal_actuating_hinge'>
      <pose>-0.0455 -0.046 1.2444 1.57079 0.5206 3.14159</pose>
      <inertial>
        <pose>0.0064 0 0 0 -0 0</pose>
        <mass>0.00362</mass>
        <inertia>
          <ixx>1.2043e-07</ixx>
          <ixy>0</ixy>
          <ixz>0</ixz>
          <iyy>5.3588e-07</iyy>
          <iyz>0</iyz>
          <izz>6.5322e-07</izz>
        </inertia>
      </inertial>
      <collision name='l_finger_1_link_paraproximal_actuating_hinge_collision'>
        <pose>0.01143 0 0 0 -0 0</pose>
        <geometry>
          <box>
            <size>0.02286 0.0075 0.002</size>
          </box>
        </geometry>
        <surface>
          <contact>
            <ode/>
          </contact>
          <friction>
            <ode>
              <mu>1.1</mu>
              <mu2>1.1</mu2>
            </ode>
          </friction>
        </surface>
      </collision>
      <visual name='l_finger_1_link_paraproximal_actuating_hinge_visual'>
        <pose>0.01143 0 0 0 -0 0</pose>
        <geometry>
          <box>
            <size>0.02286 0.0075 0.002</size>
          </box>
        </geometry>
      </visual>
      <gravity>1</gravity>
      <velocity_decay/>
      <self_collide>0</self_collide>
    </link>
    <joint name='l_finger_1_joint_paraproximal_actuating_hinge' type='revolute'>
      <child>l_finger_1_link_paraproximal_actuating_hinge</child>
      <parent>l_finger_1_link_0</parent>
      <axis>
        <xyz>-5.85014e-09 1 7.31961e-06</xyz>
        <limit>
          <lower>-3.1416</lower>
          <upper>3.1416</upper>
          <effort>100</effort>
          <velocity>100</velocity>
        </limit>
        <dynamics>
          <spring_reference>0</spring_reference>
          <spring_stiffness>0</spring_stiffness>
        </dynamics>
        <use_parent_model_frame>1</use_parent_model_frame>
      </axis>
      <physics>
        <ode>
          <implicit_spring_damper>1</implicit_spring_damper>
          <cfm_damping>1</cfm_damping>
          <limit>
            <cfm>0</cfm>
            <erp>0.2</erp>
          </limit>
        </ode>
      </physics>
    </joint>
    <link name='l_finger_1_link_paraproximal_bar'>
      <pose>-0.0653315 -0.0459999 1.23303 1.57078 -1.0494 -3.14158</pose>
      <inertial>
        <pose>0.02858 -0.00129 0 0 -0 0</pose>
        <mass>0.00732</mass>
        <inertia>
          <ixx>9.065e-08</ixx>
          <ixy>-2.7047e-07</ixy>
          <ixz>1.42e-09</ixz>
          <iyy>8.78034e-06</iyy>
          <iyz>0</iyz>
          <izz>8.77558e-06</izz>
        </inertia>
      </inertial>
      <collision name='l_finger_1_link_paraproximal_bar_collision'>
        <pose>0.02885 0 0 0 -0 0</pose>
        <geometry>
          <box>
            <size>0.0577 0.0075 0.002</size>
          </box>
        </geometry>
        <surface>
          <contact>
            <ode/>
          </contact>
          <friction>
            <ode>
              <mu>1.1</mu>
              <mu2>1.1</mu2>
            </ode>
          </friction>
        </surface>
      </collision>
      <visual name='l_finger_1_link_paraproximal_bar_visual'>
        <pose>0.02885 0 0 0 -0 0</pose>
        <geometry>
          <box>
            <size>0.0577 0.0075 0.002</size>
          </box>
        </geometry>
      </visual>
      <gravity>1</gravity>
      <velocity_decay/>
      <self_collide>0</self_collide>
    </link>
    <joint name='l_finger_1_joint_paraproximal_bar' type='revolute'>
      <child>l_finger_1_link_paraproximal_bar</child>
      <parent>l_finger_1_link_paraproximal_actuating_hinge</parent>
      <axis>
        <xyz>-5.85014e-09 1 7.31961e-06</xyz>
        <limit>
          <lower>-3.1416</lower>
          <upper>3.1416</upper>
          <effort>100</effort>
          <velocity>100</velocity>
        </limit>
        <dynamics>
          <spring_reference>0</spring_reference>
          <spring_stiffness>0</spring_stiffness>
        </dynamics>
        <use_parent_model_frame>1</use_parent_model_frame>
      </axis>
      <physics>
        <ode>
          <implicit_spring_damper>1</implicit_spring_damper>
          <cfm_damping>1</cfm_damping>
          <limit>
            <cfm>0</cfm>
            <erp>0.2</erp>
          </limit>
        </ode>
      </physics>
    </joint>
    <link name='l_finger_1_link_proximal_actuating_hinge'>
      <pose>-0.0455 -0.026 1.2444 1.57079 0.5206 3.14159</pose>
      <inertial>
        <pose>0.0012 -0.00162 -0.00161 0 -0 0</pose>
        <mass>0.02647</mass>
        <inertia>
          <ixx>1.56447e-06</ixx>
          <ixy>2.36226e-07</ixy>
          <ixz>-1.4862e-07</ixz>
          <iyy>2.21068e-06</iyy>
          <iyz>-1.4369e-07</iyz>
          <izz>3.23175e-06</izz>
        </inertia>
      </inertial>
      <collision name='l_finger_1_link_proximal_actuating_hinge_collision'>
        <pose>0.01429 0 0 0 -0 0</pose>
        <geometry>
          <box>
            <size>0.02858 0.0075 0.002</size>
          </box>
        </geometry>
        <surface>
          <contact>
            <ode/>
          </contact>
          <friction>
            <ode>
              <mu>1.1</mu>
              <mu2>1.1</mu2>
            </ode>
          </friction>
        </surface>
      </collision>
      <visual name='l_finger_1_link_proximal_actuating_hinge_visual'>
        <pose>0.01429 0 0 0 -0 0</pose>
        <geometry>
          <box>
            <size>0.02858 0.0075 0.002</size>
          </box>
        </geometry>
      </visual>
      <gravity>1</gravity>
      <velocity_decay/>
      <self_collide>0</self_collide>
    </link>
    <joint name='l_finger_1_joint_proximal_actuating_hinge' type='revolute'>
      <child>l_finger_1_link_proximal_actuating_hinge</child>
      <parent>l_finger_1_link_0</parent>
      <axis>
        <xyz>-5.85014e-09 1 7.31961e-06</xyz>
        <limit>
          <lower>-3.1416</lower>
          <upper>3.1416</upper>
          <effort>100</effort>
          <velocity>100</velocity>
        </limit>
        <dynamics>
          <spring_reference>0</spring_reference>
          <spring_stiffness>0</spring_stiffness>
        </dynamics>
        <use_parent_model_frame>1</use_parent_model_frame>
      </axis>
      <physics>
        <ode>
          <implicit_spring_damper>1</implicit_spring_damper>
          <cfm_damping>1</cfm_damping>
          <limit>
            <cfm>0</cfm>
            <erp>0.2</erp>
          </limit>
        </ode>
      </physics>
    </joint>
    <link name='l_finger_1_link_proximal_actuating_bar'>
      <pose>-0.0702937 -0.0259999 1.23018 1.57076 -1.341 -3.14156</pose>
      <inertial>
        <pose>0.02699 -0.00122 0 0 -0 0</pose>
        <mass>0.00659</mass>
        <inertia>
          <ixx>8.348e-08</ixx>
          <ixy>-2.179e-07</ixy>
          <ixz>1.34e-09</ixz>
          <iyy>7.19076e-06</iyy>
          <iyz>0</iyz>
          <izz>7.18272e-06</izz>
        </inertia>
      </inertial>
      <collision name='l_finger_1_link_proximal_actuating_bar_collision'>
        <pose>0.026789 0 0 0 -0 0</pose>
        <geometry>
          <box>
            <size>0.05398 0.0075 0.002</size>
          </box>
        </geometry>
        <surface>
          <contact>
            <ode/>
          </contact>
          <friction>
            <ode>
              <mu>1.1</mu>
              <mu2>1.1</mu2>
            </ode>
          </friction>
        </surface>
      </collision>
      <visual name='l_finger_1_link_proximal_actuating_bar_visual'>
        <pose>0.026789 0 0 0 -0 0</pose>
        <geometry>
          <box>
            <size>0.05398 0.0075 0.002</size>
          </box>
        </geometry>
      </visual>
      <gravity>1</gravity>
      <velocity_decay/>
      <self_collide>0</self_collide>
    </link>
    <joint name='l_finger_1_joint_proximal_actuating_bar' type='revolute'>
      <child>l_finger_1_link_proximal_actuating_bar</child>
      <parent>l_finger_1_link_proximal_actuating_hinge</parent>
      <axis>
        <xyz>-5.85014e-09 1 7.31961e-06</xyz>
        <limit>
          <lower>-3.1416</lower>
          <upper>3.1416</upper>
          <effort>100</effort>
          <velocity>100</velocity>
        </limit>
        <dynamics>
          <spring_reference>0</spring_reference>
          <spring_stiffness>0</spring_stiffness>
        </dynamics>
        <use_parent_model_frame>1</use_parent_model_frame>
      </axis>
      <physics>
        <ode>
          <implicit_spring_damper>1</implicit_spring_damper>
          <cfm_damping>1</cfm_damping>
          <limit>
            <cfm>0</cfm>
            <erp>0.2</erp>
          </limit>
        </ode>
      </physics>
    </joint>
    <link name='l_finger_2_link_0'>
      <pose>-0.0455 0.036 1.2444 1.5616 -1.57 -3.1324</pose>
      <inertial>
        <pose>-0.01 0 0 0 -0 0</pose>
        <mass>0.1</mass>
        <inertia>
          <ixx>1.8e-05</ixx>
          <ixy>0</ixy>
          <ixz>0</ixz>
          <iyy>2.5e-05</iyy>
          <iyz>0</iyz>
          <izz>2.5e-05</izz>
        </inertia>
      </inertial>
      <collision name='l_finger_2_link_0_collision'>
        <pose>0 0 0 -3.14159 5.35898e-08 1.5708</pose>
        <geometry>
          <mesh>
            <scale>1 1 1</scale>
            <uri>model://robotiq_s_model_visualization/meshes/s-model_articulated/collision/link_0.STL</uri>
          </mesh>
        </geometry>
        <surface>
          <contact>
            <ode/>
          </contact>
          <friction>
            <ode>
              <mu>1.1</mu>
              <mu2>1.1</mu2>
            </ode>
          </friction>
        </surface>
      </collision>
      <visual name='l_finger_2_link_0_visual'>
        <pose>0.02 0 0 0 -0 0</pose>
        <geometry>
          <mesh>
            <scale>1 1 1</scale>
            <uri>model://robotiq_s_model_visualization/meshes/s-model_articulated/visual/link_0.STL</uri>
          </mesh>
        </geometry>
      </visual>
      <gravity>1</gravity>
      <velocity_decay/>
      <self_collide>0</self_collide>
    </link>
    <joint name='l_palm_finger_2_joint' type='revolute'>
      <child>l_finger_2_link_0</child>
      <parent>lwr_7_link</parent>
      <axis>
        <xyz>1 2.13376e-11 0.000796327</xyz>
        <limit>
          <lower>-0.2967</lower>
          <upper>0.2967</upper>
          <effort>60</effort>
          <velocity>-1</velocity>
        </limit>
        <dynamics>
          <damping>1</damping>
          <friction>0</friction>
          <spring_reference>0</spring_reference>
          <spring_stiffness>0</spring_stiffness>
        </dynamics>
        <use_parent_model_frame>1</use_parent_model_frame>
      </axis>
      <physics>
        <ode>
          <implicit_spring_damper>1</implicit_spring_damper>
          <cfm_damping>1</cfm_damping>
          <limit>
            <cfm>0</cfm>
            <erp>0.2</erp>
          </limit>
        </ode>
      </physics>
    </joint>
    <link name='l_finger_2_link_1'>
      <pose>-0.0455 0.036 1.2444 1.57079 0.5206 3.14159</pose>
      <inertial>
        <pose>0.00053 0.03218 0 0 -0 1.5708</pose>
        <mass>0.047</mass>
        <inertia>
          <ixx>4.99332e-06</ixx>
          <ixy>9.1312e-07</ixy>
          <ixz>-1.2e-09</ixz>
          <iyy>6.43453e-05</iyy>
          <iyz>-7e-11</iyz>
          <izz>6.06192e-05</izz>
        </inertia>
      </inertial>
      <collision name='l_finger_2_link_1_collision'>
        <pose>0 0.05717 0 0 -0 1.5708</pose>
        <geometry>
          <mesh>
            <scale>1 1 1</scale>
            <uri>model://robotiq_s_model_visualization/meshes/s-model_articulated/collision/link_1.STL</uri>
          </mesh>
        </geometry>
        <surface>
          <contact>
            <ode/>
          </contact>
          <friction>
            <ode>
              <mu>1.1</mu>
              <mu2>1.1</mu2>
            </ode>
          </friction>
        </surface>
      </collision>
      <visual name='l_finger_2_link_1_visual'>
        <pose>0 0.05717 0 0 -0 1.5708</pose>
        <geometry>
          <mesh>
            <scale>1 1 1</scale>
            <uri>model://robotiq_s_model_visualization/meshes/s-model_articulated/visual/link_1.STL</uri>
          </mesh>
        </geometry>
      </visual>
      <gravity>1</gravity>
      <velocity_decay/>
      <self_collide>0</self_collide>
    </link>
    <joint name='l_finger_2_joint_1' type='revolute'>
      <child>l_finger_2_link_1</child>
      <parent>l_finger_2_link_0</parent>
      <axis>
        <xyz>-5.85014e-09 1 7.31961e-06</xyz>
        <limit>
          <lower>0</lower>
          <upper>1.2217</upper>
          <effort>60</effort>
          <velocity>-1</velocity>
        </limit>
        <dynamics>
          <damping>1</damping>
          <friction>0</friction>
          <spring_reference>0</spring_reference>
          <spring_stiffness>0</spring_stiffness>
        </dynamics>
        <use_parent_model_frame>1</use_parent_model_frame>
      </axis>
      <physics>
        <ode>
          <implicit_spring_damper>1</implicit_spring_damper>
          <cfm_damping>1</cfm_damping>
          <limit>
            <cfm>0</cfm>
            <erp>0.2</erp>
          </limit>
        </ode>
      </physics>
    </joint>
    <link name='l_finger_2_link_2'>
      <pose>-0.0739265 0.0359996 1.29398 1.57079 0.5206 3.14159</pose>
      <inertial>
        <pose>0.00048 0.02167 0.00018 0 -0 1.5708</pose>
        <mass>0.03284</mass>
        <inertia>
          <ixx>3.48008e-06</ixx>
          <ixy>3.194e-07</ixy>
          <ixz>1.3041e-07</ixz>
          <iyy>2.24812e-05</iyy>
          <iyz>2.91e-09</iyz>
          <izz>1.98635e-05</izz>
        </inertia>
      </inertial>
      <collision name='l_finger_2_link_2_collision'>
        <pose>0 0.0381 0.0075 0 -0 1.5708</pose>
        <geometry>
          <mesh>
            <scale>1 1 1</scale>
            <uri>model://robotiq_s_model_visualization/meshes/s-model_articulated/collision/link_2.STL</uri>
          </mesh>
        </geometry>
        <surface>
          <contact>
            <ode/>
          </contact>
          <friction>
            <ode>
              <mu>1.1</mu>
              <mu2>1.1</mu2>
            </ode>
          </friction>
        </surface>
      </collision>
      <visual name='l_finger_2_link_2_visual'>
        <pose>0 0.0381 0.0075 0 -0 1.5708</pose>
        <geometry>
          <mesh>
            <scale>1 1 1</scale>
            <uri>model://robotiq_s_model_visualization/meshes/s-model_articulated/visual/link_2.STL</uri>
          </mesh>
        </geometry>
      </visual>
      <gravity>1</gravity>
      <velocity_decay/>
      <self_collide>0</self_collide>
    </link>
    <joint name='l_finger_2_joint_2' type='revolute'>
      <child>l_finger_2_link_2</child>
      <parent>l_finger_2_link_1</parent>
      <axis>
        <xyz>-5.85014e-09 1 7.31961e-06</xyz>
        <limit>
          <lower>0</lower>
          <upper>1.5708</upper>
          <effort>60</effort>
          <velocity>-1</velocity>
        </limit>
        <dynamics>
          <damping>1</damping>
          <friction>0</friction>
          <spring_reference>0</spring_reference>
          <spring_stiffness>0</spring_stiffness>
        </dynamics>
        <use_parent_model_frame>1</use_parent_model_frame>
      </axis>
      <physics>
        <ode>
          <implicit_spring_damper>1</implicit_spring_damper>
          <cfm_damping>1</cfm_damping>
          <limit>
            <cfm>0</cfm>
            <erp>0.2</erp>
          </limit>
        </ode>
      </physics>
    </joint>
    <link name='l_finger_2_link_3'>
      <pose>-0.0933251 0.0359994 1.32781 1.5616 -1.57 -3.1324</pose>
      <inertial>
        <pose>0.01626 0.00049 0.0002 0 -0 0</pose>
        <mass>0.03354</mass>
        <inertia>
          <ixx>3.05151e-06</ixx>
          <ixy>8.9792e-07</ixy>
          <ixz>2.49e-09</ixz>
          <iyy>1.42798e-05</iyy>
          <iyz>-1.191e-08</iyz>
          <izz>1.26413e-05</izz>
        </inertia>
      </inertial>
      <collision name='l_finger_2_link_3_collision'>
        <pose>0 0 0 0 -0 0</pose>
        <geometry>
          <mesh>
            <scale>1 1 1</scale>
            <uri>model://robotiq_s_model_visualization/meshes/s-model_articulated/collision/link_3.STL</uri>
          </mesh>
        </geometry>
        <surface>
          <contact>
            <ode>
              <kp>10000</kp>
              <kd>1</kd>
            </ode>
          </contact>
          <friction>
            <ode>
              <mu>1000</mu>
              <mu2>1000</mu2>
            </ode>
          </friction>
        </surface>
      </collision>
      <visual name='l_finger_2_link_3_visual'>
        <pose>0 0 0 0 -0 0</pose>
        <geometry>
          <mesh>
            <scale>1 1 1</scale>
            <uri>model://robotiq_s_model_visualization/meshes/s-model_articulated/visual/link_3.STL</uri>
          </mesh>
        </geometry>
      </visual>
      <gravity>1</gravity>
      <velocity_decay/>
      <self_collide>0</self_collide>
    </link>
    <joint name='l_finger_2_joint_3' type='revolute'>
      <child>l_finger_2_link_3</child>
      <parent>l_finger_2_link_2</parent>
      <axis>
        <xyz>-5.85014e-09 1 7.31961e-06</xyz>
        <limit>
          <lower>-0.6632</lower>
          <upper>1.0471</upper>
          <effort>60</effort>
          <velocity>-1</velocity>
        </limit>
        <dynamics>
          <damping>1</damping>
          <friction>0</friction>
          <spring_reference>0</spring_reference>
          <spring_stiffness>0</spring_stiffness>
        </dynamics>
        <use_parent_model_frame>1</use_parent_model_frame>
      </axis>
      <physics>
        <ode>
          <implicit_spring_damper>1</implicit_spring_damper>
          <cfm_damping>1</cfm_damping>
          <limit>
            <cfm>0</cfm>
            <erp>0.2</erp>
          </limit>
        </ode>
      </physics>
    </joint>
    <link name='l_finger_2_link_paradistal_hinge'>
      <pose>-0.0933251 0.0259994 1.32781 1.57079 0.5206 3.14159</pose>
      <inertial>
        <pose>0.00548 0 0 0 -0 0</pose>
        <mass>0.00158</mass>
        <inertia>
          <ixx>1.907e-08</ixx>
          <ixy>0</ixy>
          <ixz>0</ixz>
          <iyy>1.097e-07</iyy>
          <iyz>0</iyz>
          <izz>1.261e-07</izz>
        </inertia>
      </inertial>
      <collision name='l_finger_2_link_paradistal_hinge_collision'>
        <pose>0 0 0 0 -0 0</pose>
        <geometry>
          <box>
            <size>0.02 0.02 0.002</size>
          </box>
        </geometry>
        <surface>
          <contact>
            <ode/>
          </contact>
          <friction>
            <ode>
              <mu>1.1</mu>
              <mu2>1.1</mu2>
            </ode>
          </friction>
        </surface>
      </collision>
      <visual name='l_finger_2_link_paradistal_hinge_visual'>
        <pose>0 0 0 0 -0 0</pose>
        <geometry>
          <box>
            <size>0.02 0.02 0.002</size>
          </box>
        </geometry>
      </visual>
      <gravity>1</gravity>
      <velocity_decay/>
      <self_collide>0</self_collide>
    </link>
    <joint name='l_finger_2_joint_paradistal_hinge' type='revolute'>
      <child>l_finger_2_link_paradistal_hinge</child>
      <parent>l_finger_2_link_2</parent>
      <axis>
        <xyz>-5.85014e-09 1 7.31961e-06</xyz>
        <limit>
          <lower>-3.1416</lower>
          <upper>3.1416</upper>
          <effort>100</effort>
          <velocity>100</velocity>
        </limit>
        <dynamics>
          <spring_reference>0</spring_reference>
          <spring_stiffness>0</spring_stiffness>
        </dynamics>
        <use_parent_model_frame>1</use_parent_model_frame>
      </axis>
      <physics>
        <ode>
          <implicit_spring_damper>1</implicit_spring_damper>
          <cfm_damping>1</cfm_damping>
          <limit>
            <cfm>0</cfm>
            <erp>0.2</erp>
          </limit>
        </ode>
      </physics>
    </joint>
    <link name='l_finger_2_link_median_actuating_hinge'>
      <pose>-0.0739265 0.0459996 1.29398 1.57078 0.8906 3.14158</pose>
      <inertial>
        <pose>0.0092 0.00514 0 0 -0 0</pose>
        <mass>0.00359</mass>
        <inertia>
          <ixx>2.4735e-07</ixx>
          <ixy>2.3619e-07</ixy>
          <ixz>0</ixz>
          <iyy>4.7681e-07</iyy>
          <iyz>0</iyz>
          <izz>7.1813e-07</izz>
        </inertia>
      </inertial>
      <collision name='l_finger_2_link_median_actuating_hinge_collision'>
        <pose>0 0 0 0 -0 0</pose>
        <geometry>
          <box>
            <size>0.02 0.02 0.002</size>
          </box>
        </geometry>
        <surface>
          <contact>
            <ode/>
          </contact>
          <friction>
            <ode>
              <mu>1.1</mu>
              <mu2>1.1</mu2>
            </ode>
          </friction>
        </surface>
      </collision>
      <visual name='l_finger_2_link_median_actuating_hinge_visual'>
        <pose>0 0 0 0 -0 0</pose>
        <geometry>
          <box>
            <size>0.02 0.02 0.002</size>
          </box>
        </geometry>
      </visual>
      <gravity>1</gravity>
      <velocity_decay/>
      <self_collide>0</self_collide>
    </link>
    <joint name='l_finger_2_joint_median_actuating_hinge' type='revolute'>
      <child>l_finger_2_link_median_actuating_hinge</child>
      <parent>l_finger_2_link_1</parent>
      <axis>
        <xyz>-5.85014e-09 1 7.31961e-06</xyz>
        <limit>
          <lower>-3.1416</lower>
          <upper>3.1416</upper>
          <effort>100</effort>
          <velocity>100</velocity>
        </limit>
        <dynamics>
          <spring_reference>0</spring_reference>
          <spring_stiffness>0</spring_stiffness>
        </dynamics>
        <use_parent_model_frame>1</use_parent_model_frame>
      </axis>
      <physics>
        <ode>
          <implicit_spring_damper>1</implicit_spring_damper>
          <cfm_damping>1</cfm_damping>
          <limit>
            <cfm>0</cfm>
            <erp>0.2</erp>
          </limit>
        </ode>
      </physics>
    </joint>
    <link name='l_finger_2_link_median_bar'>
      <pose>-0.095933 0.0459997 1.29088 1.57074 -1.4309 -3.14154</pose>
      <inertial>
        <pose>0.01905 -0.00107 0 0 -0 0</pose>
        <mass>0.00538</mass>
        <inertia>
          <ixx>6.639e-08</ixx>
          <ixy>-1.0996e-07</ixy>
          <ixz>9.4e-10</ixz>
          <iyy>3.05318e-06</iyy>
          <iyz>0</iyz>
          <izz>3.04657e-06</izz>
        </inertia>
      </inertial>
      <collision name='l_finger_2_link_median_bar_collision'>
        <pose>0.01905 0 0 0 -0 0</pose>
        <geometry>
          <box>
            <size>0.0381 0.0075 0.002</size>
          </box>
        </geometry>
        <surface>
          <contact>
            <ode/>
          </contact>
          <friction>
            <ode>
              <mu>1.1</mu>
              <mu2>1.1</mu2>
            </ode>
          </friction>
        </surface>
      </collision>
      <visual name='l_finger_2_link_median_bar_visual'>
        <pose>0.01905 0 0 0 -0 0</pose>
        <geometry>
          <box>
            <size>0.0381 0.0075 0.002</size>
          </box>
        </geometry>
      </visual>
      <gravity>1</gravity>
      <velocity_decay/>
      <self_collide>0</self_collide>
    </link>
    <joint name='l_finger_2_joint_median_actuating_hinge_median_bar' type='revolute'>
      <child>l_finger_2_link_median_bar</child>
      <parent>l_finger_2_link_median_actuating_hinge</parent>
      <axis>
        <xyz>-5.85014e-09 1 7.31961e-06</xyz>
        <limit>
          <lower>-3.1416</lower>
          <upper>3.1416</upper>
          <effort>100</effort>
          <velocity>100</velocity>
        </limit>
        <dynamics>
          <spring_reference>0</spring_reference>
          <spring_stiffness>0</spring_stiffness>
        </dynamics>
        <use_parent_model_frame>1</use_parent_model_frame>
      </axis>
      <physics>
        <ode>
          <implicit_spring_damper>1</implicit_spring_damper>
          <cfm_damping>1</cfm_damping>
          <limit>
            <cfm>0</cfm>
            <erp>0.2</erp>
          </limit>
        </ode>
      </physics>
    </joint>
    <link name='l_finger_2_link_paramedian_hinge'>
      <pose>-0.0739265 0.0259996 1.29398 1.57079 0.5206 3.14159</pose>
      <inertial>
        <pose>-0.01025 0.00046 0 0 -0 0</pose>
        <mass>0.00276</mass>
        <inertia>
          <ixx>4.213e-08</ixx>
          <ixy>-1.491e-08</ixy>
          <ixz>0</ixz>
          <iyy>5.0258e-07</iyy>
          <iyz>0</iyz>
          <izz>5.4007e-07</izz>
        </inertia>
      </inertial>
      <collision name='l_finger_2_link_paramedian_hinge_collision'>
        <pose>0 0 0 0 -0 0</pose>
        <geometry>
          <box>
            <size>0.02 0.02 0.002</size>
          </box>
        </geometry>
        <surface>
          <contact>
            <ode/>
          </contact>
          <friction>
            <ode>
              <mu>1.1</mu>
              <mu2>1.1</mu2>
            </ode>
          </friction>
        </surface>
      </collision>
      <visual name='l_finger_2_link_paramedian_hinge_visual'>
        <pose>0 0 0 0 -0 0</pose>
        <geometry>
          <box>
            <size>0.02 0.02 0.002</size>
          </box>
        </geometry>
      </visual>
      <gravity>1</gravity>
      <velocity_decay/>
      <self_collide>0</self_collide>
    </link>
    <joint name='l_finger_2_joint_paramedian_hinge' type='revolute'>
      <child>l_finger_2_link_paramedian_hinge</child>
      <parent>l_finger_2_link_1</parent>
      <axis>
        <xyz>-5.85014e-09 1 7.31961e-06</xyz>
        <limit>
          <lower>-3.1416</lower>
          <upper>3.1416</upper>
          <effort>100</effort>
          <velocity>100</velocity>
        </limit>
        <dynamics>
          <spring_reference>0</spring_reference>
          <spring_stiffness>0</spring_stiffness>
        </dynamics>
        <use_parent_model_frame>1</use_parent_model_frame>
      </axis>
      <physics>
        <ode>
          <implicit_spring_damper>1</implicit_spring_damper>
          <cfm_damping>1</cfm_damping>
          <limit>
            <cfm>0</cfm>
            <erp>0.2</erp>
          </limit>
        </ode>
      </physics>
    </joint>
    <link name='l_finger_2_link_median_bar_underactuated'>
      <pose>-0.0862074 0.0259997 1.29073 1.57078 -1.0502 -3.14158</pose>
      <inertial>
        <pose>0.01905 -0.00107 0 0 -0 0</pose>
        <mass>0.00538</mass>
        <inertia>
          <ixx>6.639e-08</ixx>
          <ixy>-1.0996e-07</ixy>
          <ixz>-9.4e-10</ixz>
          <iyy>3.05318e-06</iyy>
          <iyz>0</iyz>
          <izz>3.04657e-06</izz>
        </inertia>
      </inertial>
      <collision name='l_finger_2_link_median_bar_underactuated_collision'>
        <pose>0.01905 0 0 0 -0 0</pose>
        <geometry>
          <box>
            <size>0.0381 0.0075 0.002</size>
          </box>
        </geometry>
        <surface>
          <contact>
            <ode/>
          </contact>
          <friction>
            <ode>
              <mu>1.1</mu>
              <mu2>1.1</mu2>
            </ode>
          </friction>
        </surface>
      </collision>
      <visual name='l_finger_2_link_median_bar_underactuated_visual'>
        <pose>0.01905 0 0 0 -0 0</pose>
        <geometry>
          <box>
            <size>0.0381 0.0075 0.002</size>
          </box>
        </geometry>
      </visual>
      <gravity>1</gravity>
      <velocity_decay/>
      <self_collide>0</self_collide>
    </link>
    <joint name='l_finger_2_joint_paramedian_hinge_median_bar_underactuated' type='revolute'>
      <child>l_finger_2_link_median_bar_underactuated</child>
      <parent>l_finger_2_link_paramedian_hinge</parent>
      <axis>
        <xyz>-5.85014e-09 1 7.31961e-06</xyz>
        <limit>
          <lower>-3.1416</lower>
          <upper>3.1416</upper>
          <effort>100</effort>
          <velocity>100</velocity>
        </limit>
        <dynamics>
          <spring_reference>0</spring_reference>
          <spring_stiffness>0</spring_stiffness>
        </dynamics>
        <use_parent_model_frame>1</use_parent_model_frame>
      </axis>
      <physics>
        <ode>
          <implicit_spring_damper>1</implicit_spring_damper>
          <cfm_damping>1</cfm_damping>
          <limit>
            <cfm>0</cfm>
            <erp>0.2</erp>
          </limit>
        </ode>
      </physics>
    </joint>
    <link name='l_finger_2_link_paraproximal_actuating_hinge'>
      <pose>-0.0455 0.026 1.2444 1.57079 0.5206 3.14159</pose>
      <inertial>
        <pose>0.0064 0 0 0 -0 0</pose>
        <mass>0.00362</mass>
        <inertia>
          <ixx>1.2043e-07</ixx>
          <ixy>0</ixy>
          <ixz>0</ixz>
          <iyy>5.3588e-07</iyy>
          <iyz>0</iyz>
          <izz>6.5322e-07</izz>
        </inertia>
      </inertial>
      <collision name='l_finger_2_link_paraproximal_actuating_hinge_collision'>
        <pose>0.01143 0 0 0 -0 0</pose>
        <geometry>
          <box>
            <size>0.02286 0.0075 0.002</size>
          </box>
        </geometry>
        <surface>
          <contact>
            <ode/>
          </contact>
          <friction>
            <ode>
              <mu>1.1</mu>
              <mu2>1.1</mu2>
            </ode>
          </friction>
        </surface>
      </collision>
      <visual name='l_finger_2_link_paraproximal_actuating_hinge_visual'>
        <pose>0.01143 0 0 0 -0 0</pose>
        <geometry>
          <box>
            <size>0.02286 0.0075 0.002</size>
          </box>
        </geometry>
      </visual>
      <gravity>1</gravity>
      <velocity_decay/>
      <self_collide>0</self_collide>
    </link>
    <joint name='l_finger_2_joint_paraproximal_actuating_hinge' type='revolute'>
      <child>l_finger_2_link_paraproximal_actuating_hinge</child>
      <parent>l_finger_2_link_0</parent>
      <axis>
        <xyz>-5.85014e-09 1 7.31961e-06</xyz>
        <limit>
          <lower>-3.1416</lower>
          <upper>3.1416</upper>
          <effort>100</effort>
          <velocity>100</velocity>
        </limit>
        <dynamics>
          <spring_reference>0</spring_reference>
          <spring_stiffness>0</spring_stiffness>
        </dynamics>
        <use_parent_model_frame>1</use_parent_model_frame>
      </axis>
      <physics>
        <ode>
          <implicit_spring_damper>1</implicit_spring_damper>
          <cfm_damping>1</cfm_damping>
          <limit>
            <cfm>0</cfm>
            <erp>0.2</erp>
          </limit>
        </ode>
      </physics>
    </joint>
    <link name='l_finger_2_link_paraproximal_bar'>
      <pose>-0.0653315 0.0260001 1.23303 1.57078 -1.0494 -3.14158</pose>
      <inertial>
        <pose>0.02858 -0.00129 0 0 -0 0</pose>
        <mass>0.00732</mass>
        <inertia>
          <ixx>9.065e-08</ixx>
          <ixy>-2.7047e-07</ixy>
          <ixz>1.42e-09</ixz>
          <iyy>8.78034e-06</iyy>
          <iyz>0</iyz>
          <izz>8.77558e-06</izz>
        </inertia>
      </inertial>
      <collision name='l_finger_2_link_paraproximal_bar_collision'>
        <pose>0.02885 0 0 0 -0 0</pose>
        <geometry>
          <box>
            <size>0.0577 0.0075 0.002</size>
          </box>
        </geometry>
        <surface>
          <contact>
            <ode/>
          </contact>
          <friction>
            <ode>
              <mu>1.1</mu>
              <mu2>1.1</mu2>
            </ode>
          </friction>
        </surface>
      </collision>
      <visual name='l_finger_2_link_paraproximal_bar_visual'>
        <pose>0.02885 0 0 0 -0 0</pose>
        <geometry>
          <box>
            <size>0.0577 0.0075 0.002</size>
          </box>
        </geometry>
      </visual>
      <gravity>1</gravity>
      <velocity_decay/>
      <self_collide>0</self_collide>
    </link>
    <joint name='l_finger_2_joint_paraproximal_bar' type='revolute'>
      <child>l_finger_2_link_paraproximal_bar</child>
      <parent>l_finger_2_link_paraproximal_actuating_hinge</parent>
      <axis>
        <xyz>-5.85014e-09 1 7.31961e-06</xyz>
        <limit>
          <lower>-3.1416</lower>
          <upper>3.1416</upper>
          <effort>100</effort>
          <velocity>100</velocity>
        </limit>
        <dynamics>
          <spring_reference>0</spring_reference>
          <spring_stiffness>0</spring_stiffness>
        </dynamics>
        <use_parent_model_frame>1</use_parent_model_frame>
      </axis>
      <physics>
        <ode>
          <implicit_spring_damper>1</implicit_spring_damper>
          <cfm_damping>1</cfm_damping>
          <limit>
            <cfm>0</cfm>
            <erp>0.2</erp>
          </limit>
        </ode>
      </physics>
    </joint>
    <link name='l_finger_2_link_proximal_actuating_hinge'>
      <pose>-0.0455 0.046 1.2444 1.57079 0.5206 3.14159</pose>
      <inertial>
        <pose>0.0012 -0.00162 -0.00161 0 -0 0</pose>
        <mass>0.02647</mass>
        <inertia>
          <ixx>1.56447e-06</ixx>
          <ixy>2.36226e-07</ixy>
          <ixz>-1.4862e-07</ixz>
          <iyy>2.21068e-06</iyy>
          <iyz>-1.4369e-07</iyz>
          <izz>3.23175e-06</izz>
        </inertia>
      </inertial>
      <collision name='l_finger_2_link_proximal_actuating_hinge_collision'>
        <pose>0.01429 0 0 0 -0 0</pose>
        <geometry>
          <box>
            <size>0.02858 0.0075 0.002</size>
          </box>
        </geometry>
        <surface>
          <contact>
            <ode/>
          </contact>
          <friction>
            <ode>
              <mu>1.1</mu>
              <mu2>1.1</mu2>
            </ode>
          </friction>
        </surface>
      </collision>
      <visual name='l_finger_2_link_proximal_actuating_hinge_visual'>
        <pose>0.01429 0 0 0 -0 0</pose>
        <geometry>
          <box>
            <size>0.02858 0.0075 0.002</size>
          </box>
        </geometry>
      </visual>
      <gravity>1</gravity>
      <velocity_decay/>
      <self_collide>0</self_collide>
    </link>
    <joint name='l_finger_2_joint_proximal_actuating_hinge' type='revolute'>
      <child>l_finger_2_link_proximal_actuating_hinge</child>
      <parent>l_finger_2_link_0</parent>
      <axis>
        <xyz>-5.85014e-09 1 7.31961e-06</xyz>
        <limit>
          <lower>-3.1416</lower>
          <upper>3.1416</upper>
          <effort>100</effort>
          <velocity>100</velocity>
        </limit>
        <dynamics>
          <spring_reference>0</spring_reference>
          <spring_stiffness>0</spring_stiffness>
        </dynamics>
        <use_parent_model_frame>1</use_parent_model_frame>
      </axis>
      <physics>
        <ode>
          <implicit_spring_damper>1</implicit_spring_damper>
          <cfm_damping>1</cfm_damping>
          <limit>
            <cfm>0</cfm>
            <erp>0.2</erp>
          </limit>
        </ode>
      </physics>
    </joint>
    <link name='l_finger_2_link_proximal_actuating_bar'>
      <pose>-0.0702937 0.0460001 1.23018 1.57076 -1.341 -3.14156</pose>
      <inertial>
        <pose>0.02699 -0.00122 0 0 -0 0</pose>
        <mass>0.00659</mass>
        <inertia>
          <ixx>8.348e-08</ixx>
          <ixy>-2.179e-07</ixy>
          <ixz>1.34e-09</ixz>
          <iyy>7.19076e-06</iyy>
          <iyz>0</iyz>
          <izz>7.18272e-06</izz>
        </inertia>
      </inertial>
      <collision name='l_finger_2_link_proximal_actuating_bar_collision'>
        <pose>0.026789 0 0 0 -0 0</pose>
        <geometry>
          <box>
            <size>0.05398 0.0075 0.002</size>
          </box>
        </geometry>
        <surface>
          <contact>
            <ode/>
          </contact>
          <friction>
            <ode>
              <mu>1.1</mu>
              <mu2>1.1</mu2>
            </ode>
          </friction>
        </surface>
      </collision>
      <visual name='l_finger_2_link_proximal_actuating_bar_visual'>
        <pose>0.026789 0 0 0 -0 0</pose>
        <geometry>
          <box>
            <size>0.05398 0.0075 0.002</size>
          </box>
        </geometry>
      </visual>
      <gravity>1</gravity>
      <velocity_decay/>
      <self_collide>0</self_collide>
    </link>
    <joint name='l_finger_2_joint_proximal_actuating_bar' type='revolute'>
      <child>l_finger_2_link_proximal_actuating_bar</child>
      <parent>l_finger_2_link_proximal_actuating_hinge</parent>
      <axis>
        <xyz>-5.85014e-09 1 7.31961e-06</xyz>
        <limit>
          <lower>-3.1416</lower>
          <upper>3.1416</upper>
          <effort>100</effort>
          <velocity>100</velocity>
        </limit>
        <dynamics>
          <spring_reference>0</spring_reference>
          <spring_stiffness>0</spring_stiffness>
        </dynamics>
        <use_parent_model_frame>1</use_parent_model_frame>
      </axis>
      <physics>
        <ode>
          <implicit_spring_damper>1</implicit_spring_damper>
          <cfm_damping>1</cfm_damping>
          <limit>
            <cfm>0</cfm>
            <erp>0.2</erp>
          </limit>
        </ode>
      </physics>
    </joint>
    <link name='l_finger_middle_link_0'>
      <pose>0.0455 5.73411e-10 1.2444 1.57076 -1.57 3.36481e-05</pose>
      <inertial>
        <pose>-0.01 0 0 0 -0 0</pose>
        <mass>0.1</mass>
        <inertia>
          <ixx>1.8e-05</ixx>
          <ixy>0</ixy>
          <ixz>0</ixz>
          <iyy>2.5e-05</iyy>
          <iyz>0</iyz>
          <izz>2.5e-05</izz>
        </inertia>
      </inertial>
      <collision name='l_finger_middle_link_0_collision'>
        <pose>0 0 0 -3.14159 5.35898e-08 1.5708</pose>
        <geometry>
          <mesh>
            <scale>1 1 1</scale>
            <uri>model://robotiq_s_model_visualization/meshes/s-model_articulated/collision/link_0.STL</uri>
          </mesh>
        </geometry>
        <surface>
          <contact>
            <ode/>
          </contact>
          <friction>
            <ode>
              <mu>1.1</mu>
              <mu2>1.1</mu2>
            </ode>
          </friction>
        </surface>
      </collision>
      <visual name='l_finger_middle_link_0_visual'>
        <pose>0.02 0 0 0 -0 0</pose>
        <geometry>
          <mesh>
            <scale>1 1 1</scale>
            <uri>model://robotiq_s_model_visualization/meshes/s-model_articulated/visual/link_0.STL</uri>
          </mesh>
        </geometry>
      </visual>
      <gravity>1</gravity>
      <velocity_decay/>
      <self_collide>0</self_collide>
    </link>
    <joint name='l_palm_finger_middle_joint' type='revolute'>
      <child>l_finger_middle_link_0</child>
      <parent>lwr_7_link</parent>
      <axis>
        <xyz>-1 2.13375e-11 0.000796327</xyz>
        <limit>
          <lower>0</lower>
          <upper>0</upper>
          <effort>60</effort>
          <velocity>-1</velocity>
        </limit>
        <dynamics>
          <damping>1</damping>
          <friction>0</friction>
          <spring_reference>0</spring_reference>
          <spring_stiffness>0</spring_stiffness>
        </dynamics>
        <use_parent_model_frame>1</use_parent_model_frame>
      </axis>
      <physics>
        <ode>
          <implicit_spring_damper>1</implicit_spring_damper>
          <cfm_damping>1</cfm_damping>
          <limit>
            <cfm>0</cfm>
            <erp>0.2</erp>
          </limit>
        </ode>
      </physics>
    </joint>
    <link name='l_finger_middle_link_1'>
      <pose>0.0455 5.73411e-10 1.2444 1.5708 0.5206 -1.53631e-08</pose>
      <inertial>
        <pose>0.00053 0.03218 0 0 -0 1.5708</pose>
        <mass>0.047</mass>
        <inertia>
          <ixx>4.99332e-06</ixx>
          <ixy>9.1312e-07</ixy>
          <ixz>-1.2e-09</ixz>
          <iyy>6.43453e-05</iyy>
          <iyz>-7e-11</iyz>
          <izz>6.06192e-05</izz>
        </inertia>
      </inertial>
      <collision name='l_finger_middle_link_1_collision'>
        <pose>0 0.05717 0 0 -0 1.5708</pose>
        <geometry>
          <mesh>
            <scale>1 1 1</scale>
            <uri>model://robotiq_s_model_visualization/meshes/s-model_articulated/collision/link_1.STL</uri>
          </mesh>
        </geometry>
        <surface>
          <contact>
            <ode/>
          </contact>
          <friction>
            <ode>
              <mu>1.1</mu>
              <mu2>1.1</mu2>
            </ode>
          </friction>
        </surface>
      </collision>
      <visual name='l_finger_middle_link_1_visual'>
        <pose>0 0.05717 0 0 -0 1.5708</pose>
        <geometry>
          <mesh>
            <scale>1 1 1</scale>
            <uri>model://robotiq_s_model_visualization/meshes/s-model_articulated/visual/link_1.STL</uri>
          </mesh>
        </geometry>
      </visual>
      <gravity>1</gravity>
      <velocity_decay/>
      <self_collide>0</self_collide>
    </link>
    <joint name='l_finger_middle_joint_1' type='revolute'>
      <child>l_finger_middle_link_1</child>
      <parent>l_finger_middle_link_0</parent>
      <axis>
        <xyz>1.38778e-17 -1 2.67949e-08</xyz>
        <limit>
          <lower>0</lower>
          <upper>1.2217</upper>
          <effort>60</effort>
          <velocity>-1</velocity>
        </limit>
        <dynamics>
          <damping>1</damping>
          <friction>0</friction>
          <spring_reference>0</spring_reference>
          <spring_stiffness>0</spring_stiffness>
        </dynamics>
        <use_parent_model_frame>1</use_parent_model_frame>
      </axis>
      <physics>
        <ode>
          <implicit_spring_damper>1</implicit_spring_damper>
          <cfm_damping>1</cfm_damping>
          <limit>
            <cfm>0</cfm>
            <erp>0.2</erp>
          </limit>
        </ode>
      </physics>
    </joint>
    <link name='l_finger_middle_link_2'>
      <pose>0.0739265 1.90187e-09 1.29398 1.5708 0.5206 -1.53631e-08</pose>
      <inertial>
        <pose>0.00048 0.02167 0.00018 0 -0 1.5708</pose>
        <mass>0.03284</mass>
        <inertia>
          <ixx>3.48008e-06</ixx>
          <ixy>3.194e-07</ixy>
          <ixz>1.3041e-07</ixz>
          <iyy>2.24812e-05</iyy>
          <iyz>2.91e-09</iyz>
          <izz>1.98635e-05</izz>
        </inertia>
      </inertial>
      <collision name='l_finger_middle_link_2_collision'>
        <pose>0 0.0381 0.0075 0 -0 1.5708</pose>
        <geometry>
          <mesh>
            <scale>1 1 1</scale>
            <uri>model://robotiq_s_model_visualization/meshes/s-model_articulated/collision/link_2.STL</uri>
          </mesh>
        </geometry>
        <surface>
          <contact>
            <ode/>
          </contact>
          <friction>
            <ode>
              <mu>1.1</mu>
              <mu2>1.1</mu2>
            </ode>
          </friction>
        </surface>
      </collision>
      <visual name='l_finger_middle_link_2_visual'>
        <pose>0 0.0381 0.0075 0 -0 1.5708</pose>
        <geometry>
          <mesh>
            <scale>1 1 1</scale>
            <uri>model://robotiq_s_model_visualization/meshes/s-model_articulated/visual/link_2.STL</uri>
          </mesh>
        </geometry>
      </visual>
      <gravity>1</gravity>
      <velocity_decay/>
      <self_collide>0</self_collide>
    </link>
    <joint name='l_finger_middle_joint_2' type='revolute'>
      <child>l_finger_middle_link_2</child>
      <parent>l_finger_middle_link_1</parent>
      <axis>
        <xyz>1.38778e-17 -1 2.67949e-08</xyz>
        <limit>
          <lower>0</lower>
          <upper>1.5708</upper>
          <effort>60</effort>
          <velocity>-1</velocity>
        </limit>
        <dynamics>
          <damping>1</damping>
          <friction>0</friction>
          <spring_reference>0</spring_reference>
          <spring_stiffness>0</spring_stiffness>
        </dynamics>
        <use_parent_model_frame>1</use_parent_model_frame>
      </axis>
      <physics>
        <ode>
          <implicit_spring_damper>1</implicit_spring_damper>
          <cfm_damping>1</cfm_damping>
          <limit>
            <cfm>0</cfm>
            <erp>0.2</erp>
          </limit>
        </ode>
      </physics>
    </joint>
    <link name='l_finger_middle_link_3'>
      <pose>0.0933251 2.80843e-09 1.32781 1.57076 -1.57 3.36481e-05</pose>
      <inertial>
        <pose>0.01626 0.00049 0.0002 0 -0 0</pose>
        <mass>0.03354</mass>
        <inertia>
          <ixx>3.05151e-06</ixx>
          <ixy>8.9792e-07</ixy>
          <ixz>2.49e-09</ixz>
          <iyy>1.42798e-05</iyy>
          <iyz>-1.191e-08</iyz>
          <izz>1.26413e-05</izz>
        </inertia>
      </inertial>
      <collision name='l_finger_middle_link_3_collision'>
        <pose>0 0 0 0 -0 0</pose>
        <geometry>
          <mesh>
            <scale>1 1 1</scale>
            <uri>model://robotiq_s_model_visualization/meshes/s-model_articulated/collision/link_3.STL</uri>
          </mesh>
        </geometry>
        <surface>
          <contact>
            <ode>
              <kp>10000</kp>
              <kd>1</kd>
            </ode>
          </contact>
          <friction>
            <ode>
              <mu>1000</mu>
              <mu2>1000</mu2>
            </ode>
          </friction>
        </surface>
      </collision>
      <visual name='l_finger_middle_link_3_visual'>
        <pose>0 0 0 0 -0 0</pose>
        <geometry>
          <mesh>
            <scale>1 1 1</scale>
            <uri>model://robotiq_s_model_visualization/meshes/s-model_articulated/visual/link_3.STL</uri>
          </mesh>
        </geometry>
      </visual>
      <gravity>1</gravity>
      <velocity_decay/>
      <self_collide>0</self_collide>
    </link>
    <joint name='l_finger_middle_joint_3' type='revolute'>
      <child>l_finger_middle_link_3</child>
      <parent>l_finger_middle_link_2</parent>
      <axis>
        <xyz>1.66533e-16 -1 2.67949e-08</xyz>
        <limit>
          <lower>-0.6632</lower>
          <upper>1.0471</upper>
          <effort>60</effort>
          <velocity>-1</velocity>
        </limit>
        <dynamics>
          <damping>1</damping>
          <friction>0</friction>
          <spring_reference>0</spring_reference>
          <spring_stiffness>0</spring_stiffness>
        </dynamics>
        <use_parent_model_frame>1</use_parent_model_frame>
      </axis>
      <physics>
        <ode>
          <implicit_spring_damper>1</implicit_spring_damper>
          <cfm_damping>1</cfm_damping>
          <limit>
            <cfm>0</cfm>
            <erp>0.2</erp>
          </limit>
        </ode>
      </physics>
    </joint>
    <link name='l_finger_middle_link_paradistal_hinge'>
      <pose>0.0933251 0.01 1.32781 1.5708 0.5206 -1.53631e-08</pose>
      <inertial>
        <pose>0.00548 0 0 0 -0 0</pose>
        <mass>0.00158</mass>
        <inertia>
          <ixx>1.907e-08</ixx>
          <ixy>0</ixy>
          <ixz>0</ixz>
          <iyy>1.097e-07</iyy>
          <iyz>0</iyz>
          <izz>1.261e-07</izz>
        </inertia>
      </inertial>
      <collision name='l_finger_middle_link_paradistal_hinge_collision'>
        <pose>0 0 0 0 -0 0</pose>
        <geometry>
          <box>
            <size>0.02 0.02 0.002</size>
          </box>
        </geometry>
        <surface>
          <contact>
            <ode/>
          </contact>
          <friction>
            <ode>
              <mu>1.1</mu>
              <mu2>1.1</mu2>
            </ode>
          </friction>
        </surface>
      </collision>
      <visual name='l_finger_middle_link_paradistal_hinge_visual'>
        <pose>0 0 0 0 -0 0</pose>
        <geometry>
          <box>
            <size>0.02 0.02 0.002</size>
          </box>
        </geometry>
      </visual>
      <gravity>1</gravity>
      <velocity_decay/>
      <self_collide>0</self_collide>
    </link>
    <joint name='l_finger_middle_joint_paradistal_hinge' type='revolute'>
      <child>l_finger_middle_link_paradistal_hinge</child>
      <parent>l_finger_middle_link_2</parent>
      <axis>
        <xyz>1.38778e-17 -1 2.67949e-08</xyz>
        <limit>
          <lower>-3.1416</lower>
          <upper>3.1416</upper>
          <effort>100</effort>
          <velocity>100</velocity>
        </limit>
        <dynamics>
          <spring_reference>0</spring_reference>
          <spring_stiffness>0</spring_stiffness>
        </dynamics>
        <use_parent_model_frame>1</use_parent_model_frame>
      </axis>
      <physics>
        <ode>
          <implicit_spring_damper>1</implicit_spring_damper>
          <cfm_damping>1</cfm_damping>
          <limit>
            <cfm>0</cfm>
            <erp>0.2</erp>
          </limit>
        </ode>
      </physics>
    </joint>
    <link name='l_finger_middle_link_median_actuating_hinge'>
      <pose>0.0739265 -0.01 1.29398 1.5708 0.8906 -3.31216e-08</pose>
      <inertial>
        <pose>0.0092 0.00514 0 0 -0 0</pose>
        <mass>0.00359</mass>
        <inertia>
          <ixx>2.4735e-07</ixx>
          <ixy>2.3619e-07</ixy>
          <ixz>0</ixz>
          <iyy>4.7681e-07</iyy>
          <iyz>0</iyz>
          <izz>7.1813e-07</izz>
        </inertia>
      </inertial>
      <collision name='l_finger_middle_link_median_actuating_hinge_collision'>
        <pose>0 0 0 0 -0 0</pose>
        <geometry>
          <box>
            <size>0.02 0.02 0.002</size>
          </box>
        </geometry>
        <surface>
          <contact>
            <ode/>
          </contact>
          <friction>
            <ode>
              <mu>1.1</mu>
              <mu2>1.1</mu2>
            </ode>
          </friction>
        </surface>
      </collision>
      <visual name='l_finger_middle_link_median_actuating_hinge_visual'>
        <pose>0 0 0 0 -0 0</pose>
        <geometry>
          <box>
            <size>0.02 0.02 0.002</size>
          </box>
        </geometry>
      </visual>
      <gravity>1</gravity>
      <velocity_decay/>
      <self_collide>0</self_collide>
    </link>
    <joint name='l_finger_middle_joint_median_actuating_hinge' type='revolute'>
      <child>l_finger_middle_link_median_actuating_hinge</child>
      <parent>l_finger_middle_link_1</parent>
      <axis>
        <xyz>8.32667e-17 -1 2.67949e-08</xyz>
        <limit>
          <lower>-3.1416</lower>
          <upper>3.1416</upper>
          <effort>100</effort>
          <velocity>100</velocity>
        </limit>
        <dynamics>
          <spring_reference>0</spring_reference>
          <spring_stiffness>0</spring_stiffness>
        </dynamics>
        <use_parent_model_frame>1</use_parent_model_frame>
      </axis>
      <physics>
        <ode>
          <implicit_spring_damper>1</implicit_spring_damper>
          <cfm_damping>1</cfm_damping>
          <limit>
            <cfm>0</cfm>
            <erp>0.2</erp>
          </limit>
        </ode>
      </physics>
    </joint>
    <link name='l_finger_middle_link_median_bar'>
      <pose>0.095933 -0.01 1.29088 1.5708 -1.4309 1.90283e-07</pose>
      <inertial>
        <pose>0.01905 -0.00107 0 0 -0 0</pose>
        <mass>0.00538</mass>
        <inertia>
          <ixx>6.639e-08</ixx>
          <ixy>-1.0996e-07</ixy>
          <ixz>9.4e-10</ixz>
          <iyy>3.05318e-06</iyy>
          <iyz>0</iyz>
          <izz>3.04657e-06</izz>
        </inertia>
      </inertial>
      <collision name='l_finger_middle_link_median_bar_collision'>
        <pose>0.01905 0 0 0 -0 0</pose>
        <geometry>
          <box>
            <size>0.0381 0.0075 0.002</size>
          </box>
        </geometry>
        <surface>
          <contact>
            <ode/>
          </contact>
          <friction>
            <ode>
              <mu>1.1</mu>
              <mu2>1.1</mu2>
            </ode>
          </friction>
        </surface>
      </collision>
      <visual name='l_finger_middle_link_median_bar_visual'>
        <pose>0.01905 0 0 0 -0 0</pose>
        <geometry>
          <box>
            <size>0.0381 0.0075 0.002</size>
          </box>
        </geometry>
      </visual>
      <gravity>1</gravity>
      <velocity_decay/>
      <self_collide>0</self_collide>
    </link>
    <joint name='l_finger_middle_joint_median_actuating_hinge_median_bar' type='revolute'>
      <child>l_finger_middle_link_median_bar</child>
      <parent>l_finger_middle_link_median_actuating_hinge</parent>
      <axis>
        <xyz>8.32667e-17 -1 2.67949e-08</xyz>
        <limit>
          <lower>-3.1416</lower>
          <upper>3.1416</upper>
          <effort>100</effort>
          <velocity>100</velocity>
        </limit>
        <dynamics>
          <spring_reference>0</spring_reference>
          <spring_stiffness>0</spring_stiffness>
        </dynamics>
        <use_parent_model_frame>1</use_parent_model_frame>
      </axis>
      <physics>
        <ode>
          <implicit_spring_damper>1</implicit_spring_damper>
          <cfm_damping>1</cfm_damping>
          <limit>
            <cfm>0</cfm>
            <erp>0.2</erp>
          </limit>
        </ode>
      </physics>
    </joint>
    <link name='l_finger_middle_link_paramedian_hinge'>
      <pose>0.0739265 0.01 1.29398 1.5708 0.5206 -1.53631e-08</pose>
      <inertial>
        <pose>-0.01025 0.00046 0 0 -0 0</pose>
        <mass>0.00276</mass>
        <inertia>
          <ixx>4.213e-08</ixx>
          <ixy>-1.491e-08</ixy>
          <ixz>0</ixz>
          <iyy>5.0258e-07</iyy>
          <iyz>0</iyz>
          <izz>5.4007e-07</izz>
        </inertia>
      </inertial>
      <collision name='l_finger_middle_link_paramedian_hinge_collision'>
        <pose>0 0 0 0 -0 0</pose>
        <geometry>
          <box>
            <size>0.02 0.02 0.002</size>
          </box>
        </geometry>
        <surface>
          <contact>
            <ode/>
          </contact>
          <friction>
            <ode>
              <mu>1.1</mu>
              <mu2>1.1</mu2>
            </ode>
          </friction>
        </surface>
      </collision>
      <visual name='l_finger_middle_link_paramedian_hinge_visual'>
        <pose>0 0 0 0 -0 0</pose>
        <geometry>
          <box>
            <size>0.02 0.02 0.002</size>
          </box>
        </geometry>
      </visual>
      <gravity>1</gravity>
      <velocity_decay/>
      <self_collide>0</self_collide>
    </link>
    <joint name='l_finger_middle_joint_paramedian_hinge' type='revolute'>
      <child>l_finger_middle_link_paramedian_hinge</child>
      <parent>l_finger_middle_link_1</parent>
      <axis>
        <xyz>1.38778e-17 -1 2.67949e-08</xyz>
        <limit>
          <lower>-3.1416</lower>
          <upper>3.1416</upper>
          <effort>100</effort>
          <velocity>100</velocity>
        </limit>
        <dynamics>
          <spring_reference>0</spring_reference>
          <spring_stiffness>0</spring_stiffness>
        </dynamics>
        <use_parent_model_frame>1</use_parent_model_frame>
      </axis>
      <physics>
        <ode>
          <implicit_spring_damper>1</implicit_spring_damper>
          <cfm_damping>1</cfm_damping>
          <limit>
            <cfm>0</cfm>
            <erp>0.2</erp>
          </limit>
        </ode>
      </physics>
    </joint>
    <link name='l_finger_middle_link_median_bar_underactuated'>
      <pose>0.0862074 0.01 1.29073 1.5708 -1.0502 4.67336e-08</pose>
      <inertial>
        <pose>0.01905 -0.00107 0 0 -0 0</pose>
        <mass>0.00538</mass>
        <inertia>
          <ixx>6.639e-08</ixx>
          <ixy>-1.0996e-07</ixy>
          <ixz>-9.4e-10</ixz>
          <iyy>3.05318e-06</iyy>
          <iyz>0</iyz>
          <izz>3.04657e-06</izz>
        </inertia>
      </inertial>
      <collision name='l_finger_middle_link_median_bar_underactuated_collision'>
        <pose>0.01905 0 0 0 -0 0</pose>
        <geometry>
          <box>
            <size>0.0381 0.0075 0.002</size>
          </box>
        </geometry>
        <surface>
          <contact>
            <ode/>
          </contact>
          <friction>
            <ode>
              <mu>1.1</mu>
              <mu2>1.1</mu2>
            </ode>
          </friction>
        </surface>
      </collision>
      <visual name='l_finger_middle_link_median_bar_underactuated_visual'>
        <pose>0.01905 0 0 0 -0 0</pose>
        <geometry>
          <box>
            <size>0.0381 0.0075 0.002</size>
          </box>
        </geometry>
      </visual>
      <gravity>1</gravity>
      <velocity_decay/>
      <self_collide>0</self_collide>
    </link>
    <joint name='l_finger_middle_joint_paramedian_hinge_median_bar_underactuated' type='revolute'>
      <child>l_finger_middle_link_median_bar_underactuated</child>
      <parent>l_finger_middle_link_paramedian_hinge</parent>
      <axis>
        <xyz>0 -1 2.67949e-08</xyz>
        <limit>
          <lower>-3.1416</lower>
          <upper>3.1416</upper>
          <effort>100</effort>
          <velocity>100</velocity>
        </limit>
        <dynamics>
          <spring_reference>0</spring_reference>
          <spring_stiffness>0</spring_stiffness>
        </dynamics>
        <use_parent_model_frame>1</use_parent_model_frame>
      </axis>
      <physics>
        <ode>
          <implicit_spring_damper>1</implicit_spring_damper>
          <cfm_damping>1</cfm_damping>
          <limit>
            <cfm>0</cfm>
            <erp>0.2</erp>
          </limit>
        </ode>
      </physics>
    </joint>
    <link name='l_finger_middle_link_paraproximal_actuating_hinge'>
      <pose>0.0455 0.01 1.2444 1.5708 0.5206 -1.53631e-08</pose>
      <inertial>
        <pose>0.0064 0 0 0 -0 0</pose>
        <mass>0.00362</mass>
        <inertia>
          <ixx>1.2043e-07</ixx>
          <ixy>0</ixy>
          <ixz>0</ixz>
          <iyy>5.3588e-07</iyy>
          <iyz>0</iyz>
          <izz>6.5322e-07</izz>
        </inertia>
      </inertial>
      <collision name='l_finger_middle_link_paraproximal_actuating_hinge_collision'>
        <pose>0.01143 0 0 0 -0 0</pose>
        <geometry>
          <box>
            <size>0.02286 0.0075 0.002</size>
          </box>
        </geometry>
        <surface>
          <contact>
            <ode/>
          </contact>
          <friction>
            <ode>
              <mu>1.1</mu>
              <mu2>1.1</mu2>
            </ode>
          </friction>
        </surface>
      </collision>
      <visual name='l_finger_middle_link_paraproximal_actuating_hinge_visual'>
        <pose>0.01143 0 0 0 -0 0</pose>
        <geometry>
          <box>
            <size>0.02286 0.0075 0.002</size>
          </box>
        </geometry>
      </visual>
      <gravity>1</gravity>
      <velocity_decay/>
      <self_collide>0</self_collide>
    </link>
    <joint name='l_finger_middle_joint_paraproximal_actuating_hinge' type='revolute'>
      <child>l_finger_middle_link_paraproximal_actuating_hinge</child>
      <parent>l_finger_middle_link_0</parent>
      <axis>
        <xyz>1.38778e-17 -1 2.67949e-08</xyz>
        <limit>
          <lower>-3.1416</lower>
          <upper>3.1416</upper>
          <effort>100</effort>
          <velocity>100</velocity>
        </limit>
        <dynamics>
          <spring_reference>0</spring_reference>
          <spring_stiffness>0</spring_stiffness>
        </dynamics>
        <use_parent_model_frame>1</use_parent_model_frame>
      </axis>
      <physics>
        <ode>
          <implicit_spring_damper>1</implicit_spring_damper>
          <cfm_damping>1</cfm_damping>
          <limit>
            <cfm>0</cfm>
            <erp>0.2</erp>
          </limit>
        </ode>
      </physics>
    </joint>
    <link name='l_finger_middle_link_paraproximal_bar'>
      <pose>0.0653315 0.01 1.23303 1.5708 -1.0494 4.66471e-08</pose>
      <inertial>
        <pose>0.02858 -0.00129 0 0 -0 0</pose>
        <mass>0.00732</mass>
        <inertia>
          <ixx>9.065e-08</ixx>
          <ixy>-2.7047e-07</ixy>
          <ixz>1.42e-09</ixz>
          <iyy>8.78034e-06</iyy>
          <iyz>0</iyz>
          <izz>8.77558e-06</izz>
        </inertia>
      </inertial>
      <collision name='l_finger_middle_link_paraproximal_bar_collision'>
        <pose>0.02885 0 0 0 -0 0</pose>
        <geometry>
          <box>
            <size>0.0577 0.0075 0.002</size>
          </box>
        </geometry>
        <surface>
          <contact>
            <ode/>
          </contact>
          <friction>
            <ode>
              <mu>1.1</mu>
              <mu2>1.1</mu2>
            </ode>
          </friction>
        </surface>
      </collision>
      <visual name='l_finger_middle_link_paraproximal_bar_visual'>
        <pose>0.02885 0 0 0 -0 0</pose>
        <geometry>
          <box>
            <size>0.0577 0.0075 0.002</size>
          </box>
        </geometry>
      </visual>
      <gravity>1</gravity>
      <velocity_decay/>
      <self_collide>0</self_collide>
    </link>
    <joint name='l_finger_middle_joint_paraproximal_bar' type='revolute'>
      <child>l_finger_middle_link_paraproximal_bar</child>
      <parent>l_finger_middle_link_paraproximal_actuating_hinge</parent>
      <axis>
        <xyz>0 -1 2.67949e-08</xyz>
        <limit>
          <lower>-3.1416</lower>
          <upper>3.1416</upper>
          <effort>100</effort>
          <velocity>100</velocity>
        </limit>
        <dynamics>
          <spring_reference>0</spring_reference>
          <spring_stiffness>0</spring_stiffness>
        </dynamics>
        <use_parent_model_frame>1</use_parent_model_frame>
      </axis>
      <physics>
        <ode>
          <implicit_spring_damper>1</implicit_spring_damper>
          <cfm_damping>1</cfm_damping>
          <limit>
            <cfm>0</cfm>
            <erp>0.2</erp>
          </limit>
        </ode>
      </physics>
    </joint>
    <link name='l_finger_middle_link_proximal_actuating_hinge'>
      <pose>0.0455 -0.01 1.2444 1.5708 0.5206 -1.53631e-08</pose>
      <inertial>
        <pose>0.0012 -0.00162 -0.00161 0 -0 0</pose>
        <mass>0.02647</mass>
        <inertia>
          <ixx>1.56447e-06</ixx>
          <ixy>2.36226e-07</ixy>
          <ixz>-1.4862e-07</ixz>
          <iyy>2.21068e-06</iyy>
          <iyz>-1.4369e-07</iyz>
          <izz>3.23175e-06</izz>
        </inertia>
      </inertial>
      <collision name='l_finger_middle_link_proximal_actuating_hinge_collision'>
        <pose>0.01429 0 0 0 -0 0</pose>
        <geometry>
          <box>
            <size>0.02858 0.0075 0.002</size>
          </box>
        </geometry>
        <surface>
          <contact>
            <ode/>
          </contact>
          <friction>
            <ode>
              <mu>1.1</mu>
              <mu2>1.1</mu2>
            </ode>
          </friction>
        </surface>
      </collision>
      <visual name='l_finger_middle_link_proximal_actuating_hinge_visual'>
        <pose>0.01429 0 0 0 -0 0</pose>
        <geometry>
          <box>
            <size>0.02858 0.0075 0.002</size>
          </box>
        </geometry>
      </visual>
      <gravity>1</gravity>
      <velocity_decay/>
      <self_collide>0</self_collide>
    </link>
    <joint name='l_finger_middle_joint_proximal_actuating_hinge' type='revolute'>
      <child>l_finger_middle_link_proximal_actuating_hinge</child>
      <parent>l_finger_middle_link_0</parent>
      <axis>
        <xyz>1.38778e-17 -1 2.67949e-08</xyz>
        <limit>
          <lower>-3.1416</lower>
          <upper>3.1416</upper>
          <effort>100</effort>
          <velocity>100</velocity>
        </limit>
        <dynamics>
          <spring_reference>0</spring_reference>
          <spring_stiffness>0</spring_stiffness>
        </dynamics>
        <use_parent_model_frame>1</use_parent_model_frame>
      </axis>
      <physics>
        <ode>
          <implicit_spring_damper>1</implicit_spring_damper>
          <cfm_damping>1</cfm_damping>
          <limit>
            <cfm>0</cfm>
            <erp>0.2</erp>
          </limit>
        </ode>
      </physics>
    </joint>
    <link name='l_finger_middle_link_proximal_actuating_bar'>
      <pose>0.0702937 -0.01 1.23018 1.5708 -1.341 1.14543e-07</pose>
      <inertial>
        <pose>0.02699 -0.00122 0 0 -0 0</pose>
        <mass>0.00659</mass>
        <inertia>
          <ixx>8.348e-08</ixx>
          <ixy>-2.179e-07</ixy>
          <ixz>1.34e-09</ixz>
          <iyy>7.19076e-06</iyy>
          <iyz>0</iyz>
          <izz>7.18272e-06</izz>
        </inertia>
      </inertial>
      <collision name='l_finger_middle_link_proximal_actuating_bar_collision'>
        <pose>0.026789 0 0 0 -0 0</pose>
        <geometry>
          <box>
            <size>0.05398 0.0075 0.002</size>
          </box>
        </geometry>
        <surface>
          <contact>
            <ode/>
          </contact>
          <friction>
            <ode>
              <mu>1.1</mu>
              <mu2>1.1</mu2>
            </ode>
          </friction>
        </surface>
      </collision>
      <visual name='l_finger_middle_link_proximal_actuating_bar_visual'>
        <pose>0.026789 0 0 0 -0 0</pose>
        <geometry>
          <box>
            <size>0.05398 0.0075 0.002</size>
          </box>
        </geometry>
      </visual>
      <gravity>1</gravity>
      <velocity_decay/>
      <self_collide>0</self_collide>
    </link>
    <joint name='l_finger_middle_joint_proximal_actuating_bar' type='revolute'>
      <child>l_finger_middle_link_proximal_actuating_bar</child>
      <parent>l_finger_middle_link_proximal_actuating_hinge</parent>
      <axis>
        <xyz>1.11022e-16 -1 2.67949e-08</xyz>
        <limit>
          <lower>-3.1416</lower>
          <upper>3.1416</upper>
          <effort>100</effort>
          <velocity>100</velocity>
        </limit>
        <dynamics>
          <spring_reference>0</spring_reference>
          <spring_stiffness>0</spring_stiffness>
        </dynamics>
        <use_parent_model_frame>1</use_parent_model_frame>
      </axis>
      <physics>
        <ode>
          <implicit_spring_damper>1</implicit_spring_damper>
          <cfm_damping>1</cfm_damping>
          <limit>
            <cfm>0</cfm>
            <erp>0.2</erp>
          </limit>
        </ode>
      </physics>
    </joint>
    <plugin name='lwr_hw' filename='liblwr_hw_sim_plugin.so'>
      <robotNamespace>lwr</robotNamespace>
      <robotSimType>lwr_hw/DefaultLWRHWsim</robotSimType>
    </plugin>
    <joint name='l_finger_1_link_proximal_actuating_bar_median_actuating_hinge_couple' type='revolute'>
      <parent>l_finger_1_link_median_actuating_hinge</parent>
      <child>l_finger_1_link_proximal_actuating_bar</child>
      <pose>0.05398 0 0 0 -0 0</pose>
      <axis>
        <dynamics>
          <damping>0</damping>
          <friction>0</friction>
          <spring_reference>0</spring_reference>
          <spring_stiffness>0</spring_stiffness>
        </dynamics>
        <xyz>0 0 1</xyz>
        <use_parent_model_frame>1</use_parent_model_frame>
        <limit>
          <lower>-1e+16</lower>
          <upper>1e+16</upper>
        </limit>
      </axis>
    </joint>
    <joint name='l_finger_1_link_median_bar_link_3_couple' type='revolute'>
      <parent>l_finger_1_link_3</parent>
      <child>l_finger_1_link_median_bar</child>
      <pose>0.0381 0 0 0 -0 0</pose>
      <axis>
        <dynamics>
          <damping>0</damping>
          <friction>0</friction>
          <spring_reference>0</spring_reference>
          <spring_stiffness>0</spring_stiffness>
        </dynamics>
        <xyz>0 0 1</xyz>
        <use_parent_model_frame>1</use_parent_model_frame>
        <limit>
          <lower>-1e+16</lower>
          <upper>1e+16</upper>
        </limit>
      </axis>
    </joint>
    <joint name='l_finger_1_link_paramedian_bar_paradistal_hinge_couple' type='revolute'>
      <parent>l_finger_1_link_paradistal_hinge</parent>
      <child>l_finger_1_link_median_bar_underactuated</child>
      <pose>0.0381 0 0 0 -0 0</pose>
      <axis>
        <dynamics>
          <damping>0</damping>
          <friction>0</friction>
          <spring_reference>0</spring_reference>
          <spring_stiffness>0</spring_stiffness>
        </dynamics>
        <xyz>0 0 1</xyz>
        <use_parent_model_frame>1</use_parent_model_frame>
        <limit>
          <lower>-1e+16</lower>
          <upper>1e+16</upper>
        </limit>
      </axis>
    </joint>
    <joint name='l_finger_1_link_paradistal_hinge_link_3_couple' type='revolute'>
      <parent>l_finger_1_link_paradistal_hinge</parent>
      <child>l_finger_1_link_3</child>
      <pose>0.0381 0 0 0 -0 0</pose>
      <axis>
        <dynamics>
          <damping>0</damping>
          <friction>0</friction>
          <spring_reference>0</spring_reference>
          <spring_stiffness>0</spring_stiffness>
        </dynamics>
        <xyz>0 0 1</xyz>
        <use_parent_model_frame>1</use_parent_model_frame>
        <limit>
          <lower>-1e+16</lower>
          <upper>1e+16</upper>
        </limit>
      </axis>
    </joint>
    <joint name='l_finger_1_link_paraproximal_bar_paramedian_hinge_couple' type='revolute'>
      <parent>l_finger_1_link_paramedian_hinge</parent>
      <child>l_finger_1_link_paraproximal_bar</child>
      <pose>0.0577 0 0 0 -0 0</pose>
      <axis>
        <dynamics>
          <damping>0</damping>
          <friction>0</friction>
          <spring_reference>0</spring_reference>
          <spring_stiffness>0</spring_stiffness>
        </dynamics>
        <xyz>0 0 1</xyz>
        <use_parent_model_frame>1</use_parent_model_frame>
        <limit>
          <lower>-1e+16</lower>
          <upper>1e+16</upper>
        </limit>
      </axis>
    </joint>
    <joint name='l_finger_2_link_proximal_actuating_bar_median_actuating_hinge_couple' type='revolute'>
      <parent>l_finger_2_link_median_actuating_hinge</parent>
      <child>l_finger_2_link_proximal_actuating_bar</child>
      <pose>0.05398 0 0 0 -0 0</pose>
      <axis>
        <dynamics>
          <damping>0</damping>
          <friction>0</friction>
          <spring_reference>0</spring_reference>
          <spring_stiffness>0</spring_stiffness>
        </dynamics>
        <xyz>0 0 1</xyz>
        <use_parent_model_frame>1</use_parent_model_frame>
        <limit>
          <lower>-1e+16</lower>
          <upper>1e+16</upper>
        </limit>
      </axis>
    </joint>
    <joint name='l_finger_2_link_median_bar_link_3_couple' type='revolute'>
      <parent>l_finger_2_link_3</parent>
      <child>l_finger_2_link_median_bar</child>
      <pose>0.0381 0 0 0 -0 0</pose>
      <axis>
        <dynamics>
          <damping>0</damping>
          <friction>0</friction>
          <spring_reference>0</spring_reference>
          <spring_stiffness>0</spring_stiffness>
        </dynamics>
        <xyz>0 0 1</xyz>
        <use_parent_model_frame>1</use_parent_model_frame>
        <limit>
          <lower>-1e+16</lower>
          <upper>1e+16</upper>
        </limit>
      </axis>
    </joint>
    <joint name='l_finger_2_link_paramedian_bar_paradistal_hinge_couple' type='revolute'>
      <parent>l_finger_2_link_paradistal_hinge</parent>
      <child>l_finger_2_link_median_bar_underactuated</child>
      <pose>0.0381 0 0 0 -0 0</pose>
      <axis>
        <dynamics>
          <damping>0</damping>
          <friction>0</friction>
          <spring_reference>0</spring_reference>
          <spring_stiffness>0</spring_stiffness>
        </dynamics>
        <xyz>0 0 1</xyz>
        <use_parent_model_frame>1</use_parent_model_frame>
        <limit>
          <lower>-1e+16</lower>
          <upper>1e+16</upper>
        </limit>
      </axis>
    </joint>
    <joint name='l_finger_2_link_paradistal_hinge_link_3_couple' type='revolute'>
      <parent>l_finger_2_link_paradistal_hinge</parent>
      <child>l_finger_2_link_3</child>
      <pose>0.0381 0 0 0 -0 0</pose>
      <axis>
        <dynamics>
          <damping>0</damping>
          <friction>0</friction>
          <spring_reference>0</spring_reference>
          <spring_stiffness>0</spring_stiffness>
        </dynamics>
        <xyz>0 0 1</xyz>
        <use_parent_model_frame>1</use_parent_model_frame>
        <limit>
          <lower>-1e+16</lower>
          <upper>1e+16</upper>
        </limit>
      </axis>
    </joint>
    <joint name='l_finger_2_link_paraproximal_bar_paramedian_hinge_couple' type='revolute'>
      <parent>l_finger_2_link_paramedian_hinge</parent>
      <child>l_finger_2_link_paraproximal_bar</child>
      <pose>0.0577 0 0 0 -0 0</pose>
      <axis>
        <dynamics>
          <damping>0</damping>
          <friction>0</friction>
          <spring_reference>0</spring_reference>
          <spring_stiffness>0</spring_stiffness>
        </dynamics>
        <xyz>0 0 1</xyz>
        <use_parent_model_frame>1</use_parent_model_frame>
        <limit>
          <lower>-1e+16</lower>
          <upper>1e+16</upper>
        </limit>
      </axis>
    </joint>
    <joint name='l_finger_middle_link_proximal_actuating_bar_median_actuating_hinge_couple' type='revolute'>
      <parent>l_finger_middle_link_median_actuating_hinge</parent>
      <child>l_finger_middle_link_proximal_actuating_bar</child>
      <pose>0.05398 0 0 0 -0 0</pose>
      <axis>
        <dynamics>
          <damping>0</damping>
          <friction>0</friction>
          <spring_reference>0</spring_reference>
          <spring_stiffness>0</spring_stiffness>
        </dynamics>
        <xyz>0 0 1</xyz>
        <use_parent_model_frame>1</use_parent_model_frame>
        <limit>
          <lower>-1e+16</lower>
          <upper>1e+16</upper>
        </limit>
      </axis>
    </joint>
    <joint name='l_finger_middle_link_median_bar_link_3_couple' type='revolute'>
      <parent>l_finger_middle_link_3</parent>
      <child>l_finger_middle_link_median_bar</child>
      <pose>0.0381 0 0 0 -0 0</pose>
      <axis>
        <dynamics>
          <damping>0</damping>
          <friction>0</friction>
          <spring_reference>0</spring_reference>
          <spring_stiffness>0</spring_stiffness>
        </dynamics>
        <xyz>0 0 1</xyz>
        <use_parent_model_frame>1</use_parent_model_frame>
        <limit>
          <lower>-1e+16</lower>
          <upper>1e+16</upper>
        </limit>
      </axis>
    </joint>
    <joint name='l_finger_middle_link_paramedian_bar_paradistal_hinge_couple' type='revolute'>
      <parent>l_finger_middle_link_paradistal_hinge</parent>
      <child>l_finger_middle_link_median_bar_underactuated</child>
      <pose>0.0381 0 0 0 -0 0</pose>
      <axis>
        <dynamics>
          <damping>0</damping>
          <friction>0</friction>
          <spring_reference>0</spring_reference>
          <spring_stiffness>0</spring_stiffness>
        </dynamics>
        <xyz>0 0 1</xyz>
        <use_parent_model_frame>1</use_parent_model_frame>
        <limit>
          <lower>-1e+16</lower>
          <upper>1e+16</upper>
        </limit>
      </axis>
    </joint>
    <joint name='l_finger_middle_link_paradistal_hinge_link_3_couple' type='revolute'>
      <parent>l_finger_middle_link_paradistal_hinge</parent>
      <child>l_finger_middle_link_3</child>
      <pose>0.0381 0 0 0 -0 0</pose>
      <axis>
        <dynamics>
          <damping>0</damping>
          <friction>0</friction>
          <spring_reference>0</spring_reference>
          <spring_stiffness>0</spring_stiffness>
        </dynamics>
        <xyz>0 0 1</xyz>
        <use_parent_model_frame>1</use_parent_model_frame>
        <limit>
          <lower>-1e+16</lower>
          <upper>1e+16</upper>
        </limit>
      </axis>
    </joint>
    <joint name='l_finger_middle_link_paraproximal_bar_paramedian_hinge_couple' type='revolute'>
      <parent>l_finger_middle_link_paramedian_hinge</parent>
      <child>l_finger_middle_link_paraproximal_bar</child>
      <pose>0.0577 0 0 0 -0 0</pose>
      <axis>
        <dynamics>
          <damping>0</damping>
          <friction>0</friction>
          <spring_reference>0</spring_reference>
          <spring_stiffness>0</spring_stiffness>
        </dynamics>
        <xyz>0 0 1</xyz>
        <use_parent_model_frame>1</use_parent_model_frame>
        <limit>
          <lower>-1e+16</lower>
          <upper>1e+16</upper>
        </limit>
      </axis>
    </joint>
    <static>0</static>
    <plugin name='robotiq_controller' filename='libRobotiqHandPlugin.so'>
      <side>left</side>
      <kp_position>8</kp_position>
      <robotName>full_lwr</robotName>
    </plugin>
  </model>
</sdf>
